Workbook
Name __dol1: #REF!
Name __END1: #REF!
Name __kurs_dol__: #REF!
Name __stroka__: #REF!
Name _dol1: #REF!
Name _END1: #REF!
Name aned110: #REF!
Name aned111: #REF!
Name aned112: #REF!
Name aned113: #REF!
Name aned146: #REF!
Name aned158: #REF!
Name aned161: #REF!
Name aned162: #REF!
Name aned170: #REF!
Name aned184: #REF!
Name aned191: #REF!
Name aned194: #REF!
Name aned213: #REF!
Name aned224: #REF!
Name aned239: #REF!
Name aned34: #REF!
Name aned50: #REF!
Name aned60: #REF!
Name aned61: #REF!
Name aned62: #REF!
Name aned620: #REF!
Name aned624: #REF!
Name aned628: #REF!
Name aned629: #REF!
Name aned63: #REF!
Name aned632: #REF!
Name aned636: #REF!
Name aned637: #REF!
Name aned639: #REF!
Name aned64: #REF!
Name aned647: #REF!
Name aned65: #REF!
Name aned657: #REF!
Name aned662: #REF!
Name aned668: #REF!
Name aned680: #REF!
Name aned681: #REF!
Name aned682: #REF!
Name aned683: #REF!
Name aned716: #REF!
Name aned718: #REF!
Name aned719: #REF!
Name aned72: #REF!
Name aned728: #REF!
Name aned729: #REF!
Name aned731: #REF!
Name aned76: #REF!
Name aned77: #REF!
Name aned79: #REF!
Name aned812: #REF!
Name aned86: #REF!
Name aned87: #REF!
Name aned882: #REF!
Name aned900: #REF!

Sheet 0
A1: BaaS - параметры модели
D4: 46023 | E4: 46054 | F4: 46082 | G4: 46113 | H4: 46143 | I4: 46174 | J4: 46204 | K4: 46235 | L4: 46266 | M4: 46296 | N4: 46327 | O4: 46357 | P4: 46388 | Q4: 46419 | R4: 46447 | S4: 46478 | T4: 46508 | U4: 46539 | V4: 46569 | W4: 46600 | X4: 46631 | Y4: 46661 | Z4: 46692 | AA4: 46722 | AB4: 46753 | AC4: 46784 | AD4: 46813 | AE4: 46844 | AF4: 46874 | AG4: 46905 | AH4: 46935 | AI4: 46966 | AJ4: 46997 | AK4: 47027 | AL4: 47058 | AM4: 47088 | AO4: =YEAR(O4) -> 2026 | AP4: =YEAR(AA4) -> 2027 | AQ4: =YEAR(AM4) -> 2028
D5: m1 | E5: m2 | F5: m3 | G5: m4 | H5: m5 | I5: m6 | J5: m7 | K5: m8 | L5: m9 | M5: m10 | N5: m11 | O5: m12 | P5: m13 | Q5: m14 | R5: m15 | S5: m16 | T5: m17 | U5: m18 | V5: m19 | W5: m20 | X5: m21 | Y5: m22 | Z5: m23 | AA5: m24 | AB5: m25 | AC5: m26 | AD5: m27 | AE5: m28 | AF5: m29 | AG5: m30 | AH5: m31 | AI5: m32 | AJ5: m33 | AK5: m34 | AL5: m35 | AM5: m36 | AO5: Y1 | AP5: Y2 | AQ5: Y3
D6: 1 | E6: =D6+1 -> 2 | F6: =E6+1 -> 3 | G6: =F6+1 -> 4 | H6: =G6+1 -> 5 | I6: =H6+1 -> 6 | J6: =I6+1 -> 7 | K6: =J6+1 -> 8 | L6: =K6+1 -> 9 | ... AM6: =AL6+1 -> 36
A8: Показатель | B8: ЕИ | C8: Отв.исп.
A9: общее количество партнеров, в т.ч.: | D9: 15 | E9: =D9+1 -> 16 | F9: =E9+1 -> 17 | G9: =F9+1 -> 18 | H9: =G9+1 -> 19 | I9: =H9+1 -> 20 | J9: 20 | K9: =J9+2 -> 22 | L9: =K9+2 -> 24 | M9: =L9+2 -> 26 | N9: =M9+2 -> 28 | O9: 30 | P9: =O9 -> 30 | Q9: =P9 -> 30 | R9: =Q9 -> 30 | S9: =R9 -> 30 | T9: =S9 -> 30 | U9: =T9 -> 30 | V9: =U9 -> 30 | W9: =V9 -> 30 | ... AM9: =AL9 -> 30 | AO9: =O9 -> 30 | AP9: =AA9 -> 30 | AQ9: =AM9 -> 30
A10: кредитование (свои кредиты) | B10: шт | D10: 15 | E10: =D10+1 -> 16 | F10: =E10+1 -> 17 | G10: =F10+1 -> 18 | H10: =G10+1 -> 19 | I10: =H10+1 -> 20 | J10: 20 | K10: =J10+2 -> 22 | L10: =K10+2 -> 24 | M10: =L10+2 -> 26 | N10: =M10+2 -> 28 | O10: 30 | P10: =O10 -> 30 | Q10: =P10 -> 30 | R10: =Q10 -> 30 | S10: =R10 -> 30 | T10: =S10 -> 30 | U10: =T10 -> 30 | V10: =U10 -> 30 | W10: =V10 -> 30 | ... AM10: =AL10 -> 30 | AO10: =O10 -> 30 | AP10: =AA10 -> 30 | AQ10: =AM10 -> 30
A11: кредитование (чужие кредиты) | B11: шт | D11: 2 | E11: =D11+1 -> 3 | F11: =E11+1 -> 4 | G11: =F11+1 -> 5 | H11: =G11+1 -> 6 | I11: =H11+1 -> 7 | J11: =I11+1 -> 8 | K11: =J11+1 -> 9 | L11: =K11+1 -> 10 | ... AM11: =AL11+1 -> 37 | AO11: =O11 -> 13 | AP11: =AA11 -> 25 | AQ11: =AM11 -> 37
A12: депозиты | B12: шт | D12: 15 | E12: =D12+1 -> 16 | F12: =E12+1 -> 17 | G12: =F12+1 -> 18 | H12: =G12+1 -> 19 | I12: =H12+1 -> 20 | J12: 20 | K12: =J12+2 -> 22 | L12: =K12+2 -> 24 | M12: =L12+2 -> 26 | N12: =M12+2 -> 28 | O12: 30 | P12: =O12 -> 30 | Q12: =P12 -> 30 | R12: =Q12 -> 30 | S12: =R12 -> 30 | T12: =S12 -> 30 | U12: =T12 -> 30 | V12: =U12 -> 30 | W12: =V12 -> 30 | ... AM12: =AL12 -> 30 | AO12: =O12 -> 30 | AP12: =AA12 -> 30 | AQ12: =AM12 -> 30
A13: DCB ID / DCB BIO | B13: шт | D13: 15 | E13: =D13+1 -> 16 | F13: =E13+1 -> 17 | G13: =F13+1 -> 18 | H13: =G13+1 -> 19 | I13: =H13+1 -> 20 | J13: 20 | K13: =J13+2 -> 22 | L13: =K13+2 -> 24 | M13: =L13+2 -> 26 | N13: =M13+2 -> 28 | O13: 30 | P13: =O13 -> 30 | Q13: =P13 -> 30 | R13: =Q13 -> 30 | S13: =R13 -> 30 | T13: =S13 -> 30 | U13: =T13 -> 30 | V13: =U13 -> 30 | W13: =V13 -> 30 | ... AM13: =AL13 -> 30 | AO13: =O13 -> 30 | AP13: =AA13 -> 30 | AQ13: =AM13 -> 30
A14: QR прием | B14: шт | D14: 7 | E14: 7 | F14: 8 | G14: 8 | H14: 8 | I14: 9 | J14: 9 | K14: 9 | L14: 10 | M14: 10 | N14: 12 | O14: 14 | P14: 14 | Q14: 14 | R14: 14 | S14: 14 | T14: 14 | U14: 14 | V14: 14 | W14: 14 | X14: 14 | Y14: 14 | Z14: 14 | AA14: 14 | AB14: 14 | AC14: 14 | AD14: 14 | AE14: 14 | AF14: 14 | AG14: 14 | AH14: 14 | AI14: 14 | AJ14: 14 | AK14: 14 | AL14: 14 | AM14: 14 | AO14: =O14 -> 14 | AP14: =AA14 -> 14 | AQ14: =AM14 -> 14
A15: QR оплата | B15: шт | D15: 5 | E15: 5 | F15: 5 | G15: 6 | H15: 6 | I15: 6 | J15: 7 | K15: 7 | L15: 7 | M15: 8 | N15: 8 | O15: 9 | P15: 9 | Q15: 9 | R15: 9 | S15: 9 | T15: 9 | U15: 9 | V15: 9 | W15: 9 | X15: 9 | Y15: 9 | Z15: 9 | AA15: 9 | AB15: 9 | AC15: 9 | AD15: 9 | AE15: 9 | AF15: 9 | AG15: 9 | AH15: 9 | AI15: 9 | AJ15: 9 | AK15: 9 | AL15: 9 | AM15: 9 | AO15: =O15 -> 9 | AP15: =AA15 -> 9 | AQ15: =AM15 -> 9
A16: кошелек | B16: шт | D16: 2 | E16: 2 | F16: 2 | G16: 3 | H16: 3 | I16: 4 | J16: 4 | K16: 4 | L16: 5 | M16: 5 | N16: 5 | O16: 6 | P16: =O16 -> 6 | Q16: =P16 -> 6 | R16: =Q16 -> 6 | S16: =R16 -> 6 | T16: =S16 -> 6 | U16: =T16 -> 6 | V16: =U16 -> 6 | W16: =V16 -> 6 | ... AM16: =AL16 -> 6 | AO16: =O16 -> 6 | AP16: =AA16 -> 6 | AQ16: =AM16 -> 6
A17: расчетный счет | B17: шт | D17: 1 | E17: 1 | F17: 2 | G17: 2 | H17: 3 | I17: 3 | J17: 4 | K17: 5 | L17: 6 | M17: 7 | N17: 8 | O17: 8 | P17: =O17 -> 8 | Q17: =P17 -> 8 | R17: =Q17 -> 8 | S17: =R17 -> 8 | T17: =S17 -> 8 | U17: =T17 -> 8 | V17: =U17 -> 8 | W17: =V17 -> 8 | ... AM17: =AL17 -> 8 | AO17: =O17 -> 8 | AP17: =AA17 -> 8 | AQ17: =AM17 -> 8
A18: карта | B18: шт | D18: 1 | E18: =D18+1 -> 2 | F18: 2 | G18: 2 | H18: 2 | I18: 3 | J18: 3 | K18: 3 | L18: 3 | M18: 3 | N18: 4 | O18: 4 | P18: =O18 -> 4 | Q18: =P18 -> 4 | R18: =Q18 -> 4 | S18: =R18 -> 4 | T18: =S18 -> 4 | U18: =T18 -> 4 | V18: =U18 -> 4 | W18: =V18 -> 4 | ... AM18: =AL18 -> 4 | AO18: =O18 -> 4 | AP18: =AA18 -> 4 | AQ18: =AM18 -> 4
A19: онлайн конвертация | B19: шт | D19: 1 | E19: 1 | F19: 1 | G19: 2 | H19: 2 | I19: 2 | J19: 3 | K19: 3 | L19: 4 | M19: 5 | N19: 5 | O19: 6 | P19: =O19 -> 6 | Q19: =P19 -> 6 | R19: =Q19 -> 6 | S19: =R19 -> 6 | T19: =S19 -> 6 | U19: =T19 -> 6 | V19: =U19 -> 6 | W19: =V19 -> 6 | ... AM19: =AL19 -> 6 | AO19: =O19 -> 6 | AP19: =AA19 -> 6 | AQ19: =AM19 -> 6
A20: онлайн переводы | B20: шт | D20: 23 | E20: 23 | F20: =E20+1 -> 24 | G20: 24 | H20: =G20+1 -> 25 | I20: 25 | J20: 27 | K20: 28 | L20: 28 | M20: 29 | N20: 29 | O20: 30 | P20: =O20 -> 30 | Q20: =P20 -> 30 | R20: =Q20 -> 30 | S20: =R20 -> 30 | T20: =S20 -> 30 | U20: =T20 -> 30 | V20: =U20 -> 30 | W20: =V20 -> 30 | ... AM20: =AL20 -> 30 | AO20: =O20 -> 30 | AP20: =AA20 -> 30 | AQ20: =AM20 -> 30
A21: (ИЭ) Привязка карты и списания с карты | B21: шт | D21: 15 | E21: =D21+1 -> 16 | F21: =E21+1 -> 17 | G21: =F21+1 -> 18 | H21: =G21+1 -> 19 | I21: =H21+1 -> 20 | J21: 20 | K21: =J21+2 -> 22 | L21: =K21+2 -> 24 | M21: =L21+2 -> 26 | N21: =M21+2 -> 28 | O21: 30 | P21: =O21 -> 30 | Q21: =P21 -> 30 | R21: =Q21 -> 30 | S21: =R21 -> 30 | T21: =S21 -> 30 | U21: =T21 -> 30 | V21: =U21 -> 30 | W21: =V21 -> 30 | ... AM21: =AL21 -> 30 | AO21: =O21 -> 30 | AP21: =AA21 -> 30 | AQ21: =AM21 -> 30
A22: (ИЭ) QR-генерация | B22: шт | D22: 15 | E22: =D22+1 -> 16 | F22: =E22+1 -> 17 | G22: =F22+1 -> 18 | H22: =G22+1 -> 19 | I22: =H22+1 -> 20 | J22: 20 | K22: =J22+2 -> 22 | L22: =K22+2 -> 24 | M22: =L22+2 -> 26 | N22: =M22+2 -> 28 | O22: 30 | P22: =O22 -> 30 | Q22: =P22 -> 30 | R22: =Q22 -> 30 | S22: =R22 -> 30 | T22: =S22 -> 30 | U22: =T22 -> 30 | V22: =U22 -> 30 | W22: =V22 -> 30 | ... AM22: =AL22 -> 30 | AO22: =O22 -> 30 | AP22: =AA22 -> 30 | AQ22: =AM22 -> 30
A23: (ИЭ) Переход в МП DCB + платежи из него | B23: шт | D23: 15 | E23: =D23+1 -> 16 | F23: =E23+1 -> 17 | G23: =F23+1 -> 18 | H23: =G23+1 -> 19 | I23: =H23+1 -> 20 | J23: 20 | K23: =J23+2 -> 22 | L23: =K23+2 -> 24 | M23: =L23+2 -> 26 | N23: =M23+2 -> 28 | O23: 30 | P23: =O23 -> 30 | Q23: =P23 -> 30 | R23: =Q23 -> 30 | S23: =R23 -> 30 | T23: =S23 -> 30 | U23: =T23 -> 30 | V23: =U23 -> 30 | W23: =V23 -> 30 | ... AM23: =AL23 -> 30 | AO23: =O23 -> 30 | AP23: =AA23 -> 30 | AQ23: =AM23 -> 30
A24: продажа страховых полисов | B24: шт | D24: 2 | E24: 2 | F24: 3 | G24: 3 | H24: 3 | I24: 3 | J24: 4 | K24: 4 | L24: 5 | M24: 5 | N24: 5 | O24: 6 | P24: =O24 -> 6 | Q24: =P24 -> 6 | R24: =Q24 -> 6 | S24: =R24 -> 6 | T24: =S24 -> 6 | U24: =T24 -> 6 | V24: =U24 -> 6 | W24: =V24 -> 6 | ... AM24: =AL24 -> 6 | AO24: =O24 -> 6 | AP24: =AA24 -> 6 | AQ24: =AM24 -> 6
A25: курсы валют
A26: RUB | D26: 1.01 | E26: 1.01 | F26: 1.01 | G26: 1.01 | H26: 1.01 | I26: 1 | J26: 1 | K26: 1 | L26: 1 | M26: 1 | N26: 1 | O26: 1 | P26: 1 | Q26: 1 | R26: 0.97 | S26: 0.97 | T26: 0.97 | U26: 0.97 | V26: 0.97 | W26: 0.97 | X26: 0.97 | Y26: 0.97 | Z26: 0.97 | AA26: 0.97 | AB26: 0.97 | AC26: 0.97 | AD26: 0.97 | AE26: 0.97 | AF26: 0.97 | AG26: 0.97 | AH26: 0.97 | AI26: 0.97 | AJ26: 0.97 | AK26: 0.97 | AL26: 0.97 | AM26: 0.97
A27: USD | D27: 85 | E27: 85 | F27: 85 | G27: 85 | H27: 85 | I27: 85 | J27: 85 | K27: 85 | L27: 85 | M27: 85 | N27: 85 | O27: 85 | P27: 85 | Q27: 85 | R27: 85 | S27: 85 | T27: 85 | U27: 85 | V27: 85 | W27: 85 | X27: 85 | Y27: 85 | Z27: 85 | AA27: 85 | AB27: 85 | AC27: 85 | AD27: 85 | AE27: 85 | AF27: 85 | AG27: 85 | AH27: 85 | AI27: 85 | AJ27: 85 | AK27: 85 | AL27: 85 | AM27: 85

Sheet BaaS.1
A1: BaaS - Онлайн кредитование
D3: 46023 | E3: 46054 | F3: 46082 | G3: 46113 | H3: 46143 | I3: 46174 | J3: 46204 | K3: 46235 | L3: 46266 | M3: 46296 | N3: 46327 | O3: 46357 | P3: 46388 | Q3: 46419 | R3: 46447 | S3: 46478 | T3: 46508 | U3: 46539 | V3: 46569 | W3: 46600 | X3: 46631 | Y3: 46661 | Z3: 46692 | AA3: 46722 | AB3: 46753 | AC3: 46784 | AD3: 46813 | AE3: 46844 | AF3: 46874 | AG3: 46905 | AH3: 46935 | AI3: 46966 | AJ3: 46997 | AK3: 47027 | AL3: 47058 | AM3: 47088 | AO3: =YEAR(O3) -> 2026 | AP3: =YEAR(AA3) -> 2027 | AQ3: =YEAR(AM3) -> 2028
D4: m1 | E4: m2 | F4: m3 | G4: m4 | H4: m5 | I4: m6 | J4: m7 | K4: m8 | L4: m9 | M4: m10 | N4: m11 | O4: m12 | P4: m13 | Q4: m14 | R4: m15 | S4: m16 | T4: m17 | U4: m18 | V4: m19 | W4: m20 | X4: m21 | Y4: m22 | Z4: m23 | AA4: m24 | AB4: m25 | AC4: m26 | AD4: m27 | AE4: m28 | AF4: m29 | AG4: m30 | AH4: m31 | AI4: m32 | AJ4: m33 | AK4: m34 | AL4: m35 | AM4: m36 | AO4: Y1 | AP4: Y2 | AQ4: Y3
D5: 1 | E5: =D5+1 -> 2 | F5: =E5+1 -> 3 | G5: =F5+1 -> 4 | H5: =G5+1 -> 5 | I5: =H5+1 -> 6 | J5: =I5+1 -> 7 | K5: =J5+1 -> 8 | L5: =K5+1 -> 9 | ... AM5: =AL5+1 -> 36
A7: Итого | B7: ЕИ | C7: Отв.исп.
A8: чистый операционный доход | B8: тыс сом | D8: =D32+D54+D76+D102+D118+D129 -> -524.4951 | E8: =E32+E54+E76+E102+E118+E129 -> -252.67733 | F8: =F32+F54+F76+F102+F118+F129 -> -17.422927 | G8: =G32+G54+G76+G102+G118+G129 -> 202.48295 | H8: =H32+H54+H76+H102+H118+H129 -> 411.91642 | I8: =I32+I54+I76+I102+I118+I129 -> 614.18897 | J8: =J32+J54+J76+J102+J118+J129 -> 846.66095 | K8: =K32+K54+K76+K102+K118+K129 -> 985.20545 | ... AM8: =AM32+AM54+AM76+AM102+AM118+AM129 -> 5129.3657 | AO8: =SUM(D8:O8) -> 7974.2142 | AP8: =SUM(P8:AA8) -> 37528.639 | AQ8: =SUM(AB8:AM8) -> 55973.163
A9: операционные расходы | B9: тыс сом | D9: =D33+D55+D77+D103+D119+D130 -> -62.717173 | E9: =E33+E55+E77+E103+E119+E130 -> -52.432524 | F9: =F33+F55+F77+F103+F119+F130 -> -65.156034 | G9: =G33+G55+G77+G103+G119+G130 -> -77.338018 | H9: =H33+H55+H77+H103+H119+H130 -> -89.143119 | I9: =I33+I55+I77+I103+I119+I130 -> -100.67754 | J9: =J33+J55+J77+J103+J119+J130 -> -111.37862 | K9: =K33+K55+K77+K103+K119+K130 -> -122.37435 | ... AM9: =AM33+AM55+AM77+AM103+AM119+AM130 -> -315.89162 | AO9: =SUM(D9:O9) -> -1295.5684 | AP9: =SUM(P9:AA9) -> -2837.7126 | AQ9: =SUM(AB9:AM9) -> -3597.163
A10: прибыль | B10: тыс сом | D10: =D34+D56+D78+D104+D120+D131 -> -587.21227 | E10: =E34+E56+E78+E104+E120+E131 -> -305.10985 | F10: =F34+F56+F78+F104+F120+F131 -> -82.578961 | G10: =G34+G56+G78+G104+G120+G131 -> 125.14493 | H10: =H34+H56+H78+H104+H120+H131 -> 322.7733 | I10: =I34+I56+I78+I104+I120+I131 -> 513.51143 | J10: =J34+J56+J78+J104+J120+J131 -> 735.28233 | K10: =K34+K56+K78+K104+K120+K131 -> 862.8311 | ... AM10: =AM34+AM56+AM78+AM104+AM120+AM131 -> 4813.4741 | AO10: =SUM(D10:O10) -> 6678.6457 | AP10: =SUM(P10:AA10) -> 34690.927 | AQ10: =SUM(AB10:AM10) -> 52376
A12: Потребительский кредит | B12: ЕИ | C12: Отв.исп.
A13: количество партнеров | B13: шт | D13: ='0'!D10 -> 15 | E13: ='0'!E10 -> 16 | F13: ='0'!F10 -> 17 | G13: ='0'!G10 -> 18 | H13: ='0'!H10 -> 19 | I13: ='0'!I10 -> 20 | J13: ='0'!J10 -> 20 | K13: ='0'!K10 -> 22 | ... AM13: ='0'!AM10 -> 30 | AO13: =O13 -> 30 | AP13: =AA13 -> 30 | AQ13: =AM13 -> 30
A14: среднее количество выдач на 1 партнера | B14: шт | D14: 30 | E14: 30 | F14: 30 | G14: 30 | H14: 30 | I14: 30 | J14: 30 | K14: 30 | L14: 30 | M14: 30 | N14: 30 | O14: 30 | P14: 30 | Q14: 30 | R14: 30 | S14: 30 | T14: 30 | U14: 30 | V14: 30 | W14: 30 | X14: 30 | Y14: 30 | Z14: 30 | AA14: 30 | AB14: 30 | AC14: 30 | AD14: 30 | AE14: 30 | AF14: 30 | AG14: 30 | AH14: 30 | AI14: 30 | AJ14: 30 | AK14: 30 | AL14: 30 | AM14: 30 | AO14: =AVERAGE(D14:O14) -> 30 | AP14: =AVERAGE(P14:AA14) -> 30 | AQ14: =AVERAGE(AB14:AM14) -> 30
A15: количество выдач | B15: шт | D15: =D13*D14 -> 450 | E15: =E13*E14 -> 480 | F15: =F13*F14 -> 510 | G15: =G13*G14 -> 540 | H15: =H13*H14 -> 570 | I15: =I13*I14 -> 600 | J15: =J13*J14 -> 600 | K15: =K13*K14 -> 660 | ... AM15: =AM13*AM14 -> 900 | AO15: =SUM(D15:O15) -> 7650 | AP15: =SUM(P15:AA15) -> 10800 | AQ15: =SUM(AB15:AM15) -> 10800
A16: ср. сумма выдачи | B16: тыс сом | D16: 50 | E16: 50 | F16: 50 | G16: 50 | H16: 50 | I16: 50 | J16: 50 | K16: 50 | L16: 50 | M16: 50 | N16: 50 | O16: 50 | P16: 50 | Q16: 50 | R16: 50 | S16: 50 | T16: 50 | U16: 50 | V16: 50 | W16: 50 | X16: 50 | Y16: 50 | Z16: 50 | AA16: 50 | AB16: 50 | AC16: 50 | AD16: 50 | AE16: 50 | AF16: 50 | AG16: 50 | AH16: 50 | AI16: 50 | AJ16: 50 | AK16: 50 | AL16: 50 | AM16: 50 | AO16: =AVERAGE(D16:O16) -> 50 | AP16: =AVERAGE(P16:AA16) -> 50 | AQ16: =AVERAGE(AB16:AM16) -> 50
A17: выдачи | B17: тыс сом | D17: =D15*D16 -> 22500 | E17: =E15*E16 -> 24000 | F17: =F15*F16 -> 25500 | G17: =G15*G16 -> 27000 | H17: =H15*H16 -> 28500 | I17: =I15*I16 -> 30000 | J17: =J15*J16 -> 30000 | K17: =K15*K16 -> 33000 | ... AM17: =AM15*AM16 -> 45000 | AO17: =SUM(D17:O17) -> 382500 | AP17: =SUM(P17:AA17) -> 540000 | AQ17: =SUM(AB17:AM17) -> 540000
A18: cр. срок портфеля | B18: мес | D18: 12 | E18: 12 | F18: 12 | G18: 12 | H18: 12 | I18: 12 | J18: 12 | K18: 12 | L18: 12 | M18: 12 | N18: 12 | O18: 12 | P18: 12 | Q18: 12 | R18: 12 | S18: 12 | T18: 12 | U18: 12 | V18: 12 | W18: 12 | X18: 12 | Y18: 12 | Z18: 12 | AA18: 12 | AB18: 12 | AC18: 12 | AD18: 12 | AE18: 12 | AF18: 12 | AG18: 12 | AH18: 12 | AI18: 12 | AJ18: 12 | AK18: 12 | AL18: 12 | AM18: 12 | AO18: =AVERAGE(D18:O18) -> 12 | AP18: =AVERAGE(P18:AA18) -> 12 | AQ18: =AVERAGE(AB18:AM18) -> 12
A19: погашения | B19: тыс сом | D19: 0 | E19: =D20/E18 -> 1875 | F19: =E20/F18 -> 3718.75 | G19: =F20/G18 -> 5533.8542 | H19: =G20/H18 -> 7322.6997 | I19: =H20/I18 -> 9087.4747 | J19: =I20/J18 -> 10830.185 | K19: =J20/K18 -> 12427.67 | L19: =K20/L18 -> 14142.031 | ... AM19: =AL20/AM18 -> 41889.215 | AO19: =SUM(D19:O19) -> 118677.39 | AP19: =SUM(P19:AA19) -> 361035.84 | AQ19: =SUM(AB19:AM19) -> 477005.4
A20: кредитный портфель | B20: тыс сом | D20: =D17-D19 -> 22500 | E20: =D20+E17-E19 -> 44625 | F20: =E20+F17-F19 -> 66406.25 | G20: =F20+G17-G19 -> 87872.396 | H20: =G20+H17-H19 -> 109049.7 | I20: =H20+I17-I19 -> 129962.22 | J20: =I20+J17-J19 -> 149132.04 | K20: =J20+K17-K19 -> 169704.37 | L20: =K20+L17-L19 -> 191562.34 | ... AM20: =AL20+AM17-AM19 -> 505781.37 | AO20: =O20 -> 263822.61 | AP20: =AA20 -> 442786.77 | AQ20: =AM20 -> 505781.37
A21: доля просроченной задолженности, % | B21: % | D21: 0.04 | E21: 0.04 | F21: 0.04 | G21: 0.04 | H21: 0.04 | I21: 0.04 | J21: 0.04 | K21: 0.04 | L21: 0.04 | M21: 0.04 | N21: 0.04 | O21: 0.04 | P21: 0.04 | Q21: 0.04 | R21: 0.04 | S21: 0.04 | T21: 0.04 | U21: 0.04 | V21: 0.04 | W21: 0.04 | X21: 0.04 | Y21: 0.04 | Z21: 0.04 | AA21: 0.04 | AB21: 0.04 | AC21: 0.04 | AD21: 0.04 | AE21: 0.04 | AF21: 0.04 | AG21: 0.04 | AH21: 0.04 | AI21: 0.04 | AJ21: 0.04 | AK21: 0.04 | AL21: 0.04 | AM21: 0.04 | AO21: =O21 -> 0.04 | AP21: =AA21 -> 0.04 | AQ21: =AM21 -> 0.04
A22: просроченная задолженность | B22: тыс сом | D22: =D20*D21 -> 900 | E22: =E20*E21 -> 1785 | F22: =F20*F21 -> 2656.25 | G22: =G20*G21 -> 3514.8958 | H22: =H20*H21 -> 4361.9878 | I22: =I20*I21 -> 5198.4889 | J22: =J20*J21 -> 5965.2815 | K22: =K20*K21 -> 6788.1747 | ... AM22: =AM20*AM21 -> 20231.255 | AO22: =SUM(D22:O22) -> 67518.052 | AP22: =SUM(P22:AA22) -> 180455.77 | AQ22: =SUM(AB22:AM22) -> 231482.38
A23: комиссия партнеру | B23: % | D23: 0 | E23: 0 | F23: 0 | G23: 0 | H23: 0 | I23: 0 | J23: 0 | K23: 0 | L23: 0 | M23: 0 | N23: 0 | O23: 0 | P23: 0 | Q23: 0 | R23: 0 | S23: 0 | T23: 0 | U23: 0 | V23: 0 | W23: 0 | X23: 0 | Y23: 0 | Z23: 0 | AA23: 0 | AB23: 0 | AC23: 0 | AD23: 0 | AE23: 0 | AF23: 0 | AG23: 0 | AH23: 0 | AI23: 0 | AJ23: 0 | AK23: 0 | AL23: 0 | AM23: 0 | AO23: =AVERAGE(D23:O23) -> 0 | AP23: =AVERAGE(P23:AA23) -> 0 | AQ23: =AVERAGE(AB23:AM23) -> 0
A24: ср. % ставка портфеля | B24: % | D24: 0.24 | E24: 0.24 | F24: 0.24 | G24: 0.24 | H24: 0.24 | I24: 0.24 | J24: 0.24 | K24: 0.24 | L24: 0.24 | M24: 0.24 | N24: 0.24 | O24: 0.24 | P24: 0.24 | Q24: 0.24 | R24: 0.24 | S24: 0.24 | T24: 0.24 | U24: 0.24 | V24: 0.24 | W24: 0.24 | X24: 0.24 | Y24: 0.24 | Z24: 0.24 | AA24: 0.24 | AB24: 0.24 | AC24: 0.24 | AD24: 0.24 | AE24: 0.24 | AF24: 0.24 | AG24: 0.24 | AH24: 0.24 | AI24: 0.24 | AJ24: 0.24 | AK24: 0.24 | AL24: 0.24 | AM24: 0.24 | AO24: =AVERAGE(D24:O24) -> 0.24 | AP24: =AVERAGE(P24:AA24) -> 0.24 | AQ24: =AVERAGE(AB24:AM24) -> 0.24
A25: ср. % ставка фондирования | B25: % | D25: 0.15 | E25: 0.15 | F25: 0.15 | G25: 0.15 | H25: 0.15 | I25: 0.15 | J25: 0.15 | K25: 0.15 | L25: 0.15 | M25: 0.15 | N25: 0.15 | O25: 0.15 | P25: 0.15 | Q25: 0.15 | R25: 0.15 | S25: 0.15 | T25: 0.15 | U25: 0.15 | V25: 0.15 | W25: 0.15 | X25: 0.15 | Y25: 0.15 | Z25: 0.15 | AA25: 0.15 | AB25: 0.15 | AC25: 0.15 | AD25: 0.15 | AE25: 0.15 | AF25: 0.15 | AG25: 0.15 | AH25: 0.15 | AI25: 0.15 | AJ25: 0.15 | AK25: 0.15 | AL25: 0.15 | AM25: 0.15 | AO25: =AVERAGE(D25:O25) -> 0.15 | AP25: =AVERAGE(P25:AA25) -> 0.15 | AQ25: =AVERAGE(AB25:AM25) -> 0.15
A26: ср. % резервирования | B26: % | D26: 0.02 | E26: 0.02 | F26: 0.02 | G26: 0.02 | H26: 0.02 | I26: 0.02 | J26: 0.02 | K26: 0.02 | L26: 0.02 | M26: 0.02 | N26: 0.02 | O26: 0.02 | P26: 0.02 | Q26: 0.02 | R26: 0.02 | S26: 0.02 | T26: 0.02 | U26: 0.02 | V26: 0.02 | W26: 0.02 | X26: 0.02 | Y26: 0.02 | Z26: 0.02 | AA26: 0.02 | AB26: 0.02 | AC26: 0.02 | AD26: 0.02 | AE26: 0.02 | AF26: 0.02 | AG26: 0.02 | AH26: 0.02 | AI26: 0.02 | AJ26: 0.02 | AK26: 0.02 | AL26: 0.02 | AM26: 0.02 | AO26: =AVERAGE(D26:O26) -> 0.02 | AP26: =AVERAGE(P26:AA26) -> 0.02 | AQ26: =AVERAGE(AB26:AM26) -> 0.02
A27: РППУ на конец месяца | B27: тыс сом | D27: =-D20*D26 -> -450 | E27: =-E20*E26 -> -892.5 | F27: =-F20*F26 -> -1328.125 | G27: =-G20*G26 -> -1757.4479 | H27: =-H20*H26 -> -2180.9939 | I27: =-I20*I26 -> -2599.2444 | J27: =-J20*J26 -> -2982.6407 | K27: =-K20*K26 -> -3394.0873 | ... AM27: =-AM20*AM26 -> -10115.627 | AO27: =O27 -> -5276.4522 | AP27: =AA27 -> -8855.7353 | AQ27: =AM27 -> -10115.627
A28: % доход | B28: тыс сом | D28: =(C20+D20)/2*D24/12*(1-2/102) -> 220.58824 | E28: =(D20+E20)/2*E24/12*(1-2/102) -> 658.08824 | F28: =(E20+F20)/2*F24/12*(1-2/102) -> 1088.5417 | G28: =(F20+G20)/2*G24/12*(1-2/102) -> 1512.5357 | H28: =(G20+H20)/2*H24/12*(1-2/102) -> 1930.6087 | I28: =(H20+I20)/2*I24/12*(1-2/102) -> 2343.2541 | J28: =(I20+J20)/2*J24/12*(1-2/102) -> 2736.2182 | K28: =(J20+K20)/2*K24/12*(1-2/102) -> 3125.8471 | ... AM28: =(AL20+AM20)/2*AM24/12*(1-2/102) -> 9886.7838 | AO28: =SUM(D28:O28) -> 30510.588 | AP28: =SUM(P28:AA28) -> 86704.161 | AQ28: =SUM(AB28:AM28) -> 112854.16
A29: трансфертный расход | B29: тыс сом | D29: =-(C20+D20)/2*D25/12 -> -140.625 | E29: =-(D20+E20)/2*E25/12 -> -419.53125 | F29: =-(E20+F20)/2*F25/12 -> -693.94531 | G29: =-(F20+G20)/2*G25/12 -> -964.24154 | H29: =-(G20+H20)/2*H25/12 -> -1230.7631 | I29: =-(H20+I20)/2*I25/12 -> -1493.8245 | J29: =-(I20+J20)/2*J25/12 -> -1744.3391 | K29: =-(J20+K20)/2*K25/12 -> -1992.7275 | ... AM29: =-(AL20+AM20)/2*AM25/12 -> -6302.8247 | AO29: =SUM(D29:O29) -> -19450.5 | AP29: =SUM(P29:AA29) -> -55273.903 | AQ29: =SUM(AB29:AM29) -> -71944.526
A30: комиссия партнеру | B30: тыс сом | D30: =-D23*D17 -> 0 | E30: =-E23*E17 -> 0 | F30: =-F23*F17 -> 0 | G30: =-G23*G17 -> 0 | H30: =-H23*H17 -> 0 | I30: =-I23*I17 -> 0 | J30: =-J23*J17 -> 0 | K30: =-K23*K17 -> 0 | ... AM30: =-AM23*AM17 -> 0 | AO30: =SUM(D30:O30) -> 0 | AP30: =SUM(P30:AA30) -> 0 | AQ30: =SUM(AB30:AM30) -> 0
A31: расходы на провизии | B31: тыс сом | D31: =(D27-C27) -> -450 | E31: =(E27-D27) -> -442.5 | F31: =(F27-E27) -> -435.625 | G31: =(G27-F27) -> -429.32292 | H31: =(H27-G27) -> -423.54601 | I31: =(I27-H27) -> -418.25051 | J31: =(J27-I27) -> -383.3963 | K31: =(K27-J27) -> -411.44661 | ... AM31: =(AM27-AL27) -> -62.215697 | AO31: =SUM(D31:O31) -> -5276.4522 | AP31: =SUM(P31:AA31) -> -3579.2831 | AQ31: =SUM(AB31:AM31) -> -1259.892
A32: чистый операционный доход | B32: тыс сом | D32: =SUM(D28:D31) -> -370.03676 | E32: =SUM(E28:E31) -> -203.94301 | F32: =SUM(F28:F31) -> -41.028646 | G32: =SUM(G28:G31) -> 118.97129 | H32: =SUM(H28:H31) -> 276.29966 | I32: =SUM(I28:I31) -> 431.1791 | J32: =SUM(J28:J31) -> 608.48281 | K32: =SUM(K28:K31) -> 721.67296 | ... AM32: =SUM(AM28:AM31) -> 3521.7434 | AO32: =SUM(D32:O32) -> 5783.636 | AP32: =SUM(P32:AA32) -> 27850.975 | AQ32: =SUM(AB32:AM32) -> 39649.741
A33: операционные расходы | B33: тыс сом | D33: =-'OPEX+CAPEX'!E19 -> -11.41875 | E33: =-'OPEX+CAPEX'!F19 -> -22.647188 | F33: =-'OPEX+CAPEX'!G19 -> -33.701172 | G33: =-'OPEX+CAPEX'!H19 -> -44.595241 | H33: =-'OPEX+CAPEX'!I19 -> -55.342721 | I33: =-'OPEX+CAPEX'!J19 -> -65.955827 | J33: =-'OPEX+CAPEX'!K19 -> -75.684508 | K33: =-'OPEX+CAPEX'!L19 -> -86.124966 | ... AM33: =-'OPEX+CAPEX'!AN19 -> -256.68404 | AO33: =SUM(D33:O33) -> -856.63528 | AP33: =SUM(P33:AA33) -> -2289.5326 | AQ33: =SUM(AB33:AM33) -> -2936.9326
A34: прибыль | B34: тыс сом | D34: =D32+D33 -> -381.45551 | E34: =E32+E33 -> -226.5902 | F34: =F32+F33 -> -74.729818 | G34: =G32+G33 -> 74.376049 | H34: =H32+H33 -> 220.95694 | I34: =I32+I33 -> 365.22328 | J34: =J32+J33 -> 532.7983 | K34: =K32+K33 -> 635.548 | ... AM34: =AM32+AM33 -> 3265.0594 | AO34: =SUM(D34:O34) -> 4927.0007 | AP34: =SUM(P34:AA34) -> 25561.443 | AQ34: =SUM(AB34:AM34) -> 36712.808
A36: Рассрочка (BNPL) | B36: ЕИ | C36: Отв.исп.
A37: количество партнеров | B37: шт | D37: ='0'!D10 -> 15 | E37: ='0'!E10 -> 16 | F37: ='0'!F10 -> 17 | G37: ='0'!G10 -> 18 | H37: ='0'!H10 -> 19 | I37: ='0'!I10 -> 20 | J37: ='0'!J10 -> 20 | K37: ='0'!K10 -> 22 | ... AM37: ='0'!AM10 -> 30 | AO37: =O37 -> 30 | AP37: =AA37 -> 30 | AQ37: =AM37 -> 30
A38: среднее количество выдач на 1 партнера | B38: шт | D38: 1 | E38: 1 | F38: 1 | G38: 1 | H38: 1 | I38: 1 | J38: 1 | K38: 1 | L38: 1 | M38: 1 | N38: 1 | O38: 1 | P38: 1 | Q38: 1 | R38: 1 | S38: 1 | T38: 1 | U38: 1 | V38: 1 | W38: 1 | X38: 1 | Y38: 1 | Z38: 1 | AA38: 1 | AB38: 1 | AC38: 1 | AD38: 1 | AE38: 1 | AF38: 1 | AG38: 1 | AH38: 1 | AI38: 1 | AJ38: 1 | AK38: 1 | AL38: 1 | AM38: 1 | AO38: =AVERAGE(D38:O38) -> 1 | AP38: =AVERAGE(P38:AA38) -> 1 | AQ38: =AVERAGE(AB38:AM38) -> 1
A39: количество выдач | B39: шт | D39: =D37*D38 -> 15 | E39: =E37*E38 -> 16 | F39: =F37*F38 -> 17 | G39: =G37*G38 -> 18 | H39: =H37*H38 -> 19 | I39: =I37*I38 -> 20 | J39: =J37*J38 -> 20 | K39: =K37*K38 -> 22 | ... AM39: =AM37*AM38 -> 30 | AO39: =SUM(D39:O39) -> 255 | AP39: =SUM(P39:AA39) -> 360 | AQ39: =SUM(AB39:AM39) -> 360
A40: ср. сумма выдачи | B40: тыс сом | D40: 100 | E40: 100 | F40: 100 | G40: 100 | H40: 100 | I40: 100 | J40: 100 | K40: 100 | L40: 100 | M40: 100 | N40: 100 | O40: 100 | P40: 100 | Q40: 100 | R40: 100 | S40: 100 | T40: 100 | U40: 100 | V40: 100 | W40: 100 | X40: 100 | Y40: 100 | Z40: 100 | AA40: 100 | AB40: 100 | AC40: 100 | AD40: 100 | AE40: 100 | AF40: 100 | AG40: 100 | AH40: 100 | AI40: 100 | AJ40: 100 | AK40: 100 | AL40: 100 | AM40: 100 | AO40: =AVERAGE(D40:O40) -> 100 | AP40: =AVERAGE(P40:AA40) -> 100 | AQ40: =AVERAGE(AB40:AM40) -> 100
A41: выдачи | B41: тыс сом | D41: =D39*D40 -> 1500 | E41: =E39*E40 -> 1600 | F41: =F39*F40 -> 1700 | G41: =G39*G40 -> 1800 | H41: =H39*H40 -> 1900 | I41: =I39*I40 -> 2000 | J41: =J39*J40 -> 2000 | K41: =K39*K40 -> 2200 | ... AM41: =AM39*AM40 -> 3000 | AO41: =SUM(D41:O41) -> 25500 | AP41: =SUM(P41:AA41) -> 36000 | AQ41: =SUM(AB41:AM41) -> 36000
A42: cр. срок портфеля | B42: мес | D42: 3 | E42: 3 | F42: 3 | G42: 3 | H42: 3 | I42: 3 | J42: 3 | K42: 3 | L42: 3 | M42: 3 | N42: 3 | O42: 3 | P42: 3 | Q42: 3 | R42: 3 | S42: 3 | T42: 3 | U42: 3 | V42: 3 | W42: 3 | X42: 3 | Y42: 3 | Z42: 3 | AA42: 3 | AB42: 3 | AC42: 3 | AD42: 3 | AE42: 3 | AF42: 3 | AG42: 3 | AH42: 3 | AI42: 3 | AJ42: 3 | AK42: 3 | AL42: 3 | AM42: 3 | AO42: =AVERAGE(D42:O42) -> 3 | AP42: =AVERAGE(P42:AA42) -> 3 | AQ42: =AVERAGE(AB42:AM42) -> 3
A43: погашения | B43: тыс сом | D43: 0 | E43: =D44/E42 -> 500 | F43: =E44/F42 -> 866.66667 | G43: =F44/G42 -> 1144.4444 | H43: =G44/H42 -> 1362.963 | I43: =H44/I42 -> 1541.9753 | J43: =I44/J42 -> 1694.6502 | K43: =J44/K42 -> 1796.4335 | L43: =K44/L42 -> 1930.9556 | ... AM43: =AL44/AM42 -> 2999.9667 | AO43: =SUM(D43:O43) -> 17622.397 | AP43: =SUM(P43:AA43) -> 34886.254 | AQ43: =SUM(AB43:AM43) -> 35991.416
A44: кредитный портфель | B44: тыс сом | D44: =D41-D43 -> 1500 | E44: =D44+E41-E43 -> 2600 | F44: =E44+F41-F43 -> 3433.3333 | G44: =F44+G41-G43 -> 4088.8889 | H44: =G44+H41-H43 -> 4625.9259 | I44: =H44+I41-I43 -> 5083.9506 | J44: =I44+J41-J43 -> 5389.3004 | K44: =J44+K41-K43 -> 5792.8669 | L44: =K44+L41-L43 -> 6261.9113 | ... AM44: =AL44+AM41-AM43 -> 8999.9333 | AO44: =O44 -> 7877.6033 | AP44: =AA44 -> 8991.3493 | AQ44: =AM44 -> 8999.9333
...

Sheet BaaS.2
A1: BaaS - Онлайн депозит
D3: 46023 | E3: 46054 | F3: 46082 | G3: 46113 | H3: 46143 | I3: 46174 | J3: 46204 | K3: 46235 | L3: 46266 | M3: 46296 | N3: 46327 | O3: 46357 | P3: 46388 | Q3: 46419 | R3: 46447 | S3: 46478 | T3: 46508 | U3: 46539 | V3: 46569 | W3: 46600 | X3: 46631 | Y3: 46661 | Z3: 46692 | AA3: 46722 | AB3: 46753 | AC3: 46784 | AD3: 46813 | AE3: 46844 | AF3: 46874 | AG3: 46905 | AH3: 46935 | AI3: 46966 | AJ3: 46997 | AK3: 47027 | AL3: 47058 | AM3: 47088 | AO3: =YEAR(O3) -> 2026 | AP3: =YEAR(AA3) -> 2027 | AQ3: =YEAR(AM3) -> 2028
D4: m1 | E4: m2 | F4: m3 | G4: m4 | H4: m5 | I4: m6 | J4: m7 | K4: m8 | L4: m9 | M4: m10 | N4: m11 | O4: m12 | P4: m13 | Q4: m14 | R4: m15 | S4: m16 | T4: m17 | U4: m18 | V4: m19 | W4: m20 | X4: m21 | Y4: m22 | Z4: m23 | AA4: m24 | AB4: m25 | AC4: m26 | AD4: m27 | AE4: m28 | AF4: m29 | AG4: m30 | AH4: m31 | AI4: m32 | AJ4: m33 | AK4: m34 | AL4: m35 | AM4: m36 | AO4: Y1 | AP4: Y2 | AQ4: Y3
D5: 1 | E5: =D5+1 -> 2 | F5: =E5+1 -> 3 | G5: =F5+1 -> 4 | H5: =G5+1 -> 5 | I5: =H5+1 -> 6 | J5: =I5+1 -> 7 | K5: =J5+1 -> 8 | L5: =K5+1 -> 9 | ... AM5: =AL5+1 -> 36
A7: Итого | B7: ЕИ | C7: Отв.исп.
A8: количество депозитов | B8: шт | D8: =D27/D22+D45/D40+D70/D65 -> 1350 | E8: =E27/E22+E45/E40+E70/E65 -> 2681.4375 | F8: =F27/F22+F45/F40+F70/F65 -> 3999.7427 | G8: =G27/G22+G45/G40+G70/G65 -> 5305.9176 | H8: =H27/H22+H45/H40+H70/H65 -> 6600.8993 | I8: =I27/I22+I45/I40+I70/I65 -> 7885.5526 | J8: =J27/J22+J45/J40+J70/J65 -> 9070.6754 | K8: =K27/K22+K45/K40+K70/K65 -> 10344.241 | ... AM8: =AM27/AM22+AM45/AM40+AM70/AM65 -> 32130.82 | AO8: =O8 -> 16188.695 | AP8: =AA8 -> 27732.221 | AQ8: =AM8 -> 32130.82
A9: портфель | B9: тыс сом | D9: =D27+D55+D80 -> 64350 | E9: =E27+E55+E80 -> 127815.19 | F9: =F27+F55+F80 -> 190654.4 | G9: =G27+G55+G80 -> 252915.41 | H9: =H27+H55+H80 -> 314642.87 | I9: =I27+I55+I80 -> 374563.75 | J9: =J27+J55+J80 -> 430857.08 | K9: =K27+K55+K80 -> 491351.47 | ... AM9: =AM27+AM55+AM80 -> 1510148.5 | AO9: =O9 -> 768963.01 | AP9: =AA9 -> 1303414.4 | AQ9: =AM9 -> 1510148.5
A10: % расход | B10: тыс сом | D10: =D31+D56+D81 -> -375.375 | E10: =E31+E56+E81 -> -1120.9636 | F10: =F31+F56+F81 -> -1857.7393 | G10: =G31+G56+G81 -> -2587.4906 | H10: =H31+H56+H81 -> -3310.7566 | I10: =I31+I56+I81 -> -4013.9544 | J10: =J31+J56+J81 -> -4698.2882 | K10: =K31+K56+K81 -> -5379.5499 | ... AM10: =AM31+AM56+AM81 -> -17556.242 | AO10: =SUM(D10:O10) -> -52559.885 | AP10: =SUM(P10:AA10) -> -150677.19 | AQ10: =SUM(AB10:AM10) -> -199225.02
A11: трансфертный доход | B11: тыс сом | D11: =D32+D57+D82 -> 429 | E11: =E32+E57+E82 -> 1281.1012 | F11: =F32+F57+F82 -> 2123.1306 | G11: =G32+G57+G82 -> 2957.1321 | H11: =H32+H57+H82 -> 3783.7218 | I11: =I32+I57+I82 -> 4587.3764 | J11: =J32+J57+J82 -> 5369.4722 | K11: =K32+K57+K82 -> 6148.057 | ... AM11: =AM32+AM57+AM82 -> 20064.277 | AO11: =SUM(D11:O11) -> 60068.44 | AP11: =SUM(P11:AA11) -> 172202.51 | AQ11: =SUM(AB11:AM11) -> 227685.73
A12: комиссия партнеру | B12: тыс сом | D12: =D33+D58+D83 -> -643.5 | E12: =E33+E58+E83 -> -686.4 | F12: =F33+F58+F83 -> -729.3 | G12: =G33+G58+G83 -> -772.2 | H12: =H33+H58+H83 -> -815.1 | I12: =I33+I58+I83 -> -855 | J12: =J33+J58+J83 -> -855 | K12: =K33+K58+K83 -> -940.5 | ... AM12: =AM33+AM58+AM83 -> -1269 | AO12: =SUM(D12:O12) -> -10914 | AP12: =SUM(P12:AA12) -> -15255 | AQ12: =SUM(AB12:AM12) -> -15228
A13: начисление расходов в ФЗД | B13: тыс сом | E13: =-0.2%*D9/12 -> -10.725 | F13: =-0.2%*(D9+E9)/2/12 -> -16.013766 | G13: =-0.2%*(E9+F9)/2/12 -> -26.539133 | H13: =-0.2%*(F9+G9)/2/12 -> -36.964151 | I13: =-0.2%*(G9+H9)/2/12 -> -47.296523 | J13: =-0.2%*(H9+I9)/2/12 -> -57.433885 | K13: =-0.2%*(I9+J9)/2/12 -> -67.118402 | L13: =-0.2%*(J9+K9)/2/12 -> -76.850712 | M13: =-0.2%*(K9+L9)/2/12 -> -87.253896 | ... AM13: =-0.2%*(AK9+AL9)/2/12 -> -248.95318 | AO13: =SUM(D13:O13) -> -634.33235 | AP13: =SUM(P13:AA13) -> -2060.3932 | AQ13: =SUM(AB13:AM13) -> -2810.1736
A14: чистый операционный доход | B14: тыс сом | D14: =D34+D59+D84+D13 -> -589.875 | E14: =E34+E59+E84+E13 -> -536.98734 | F14: =F34+F59+F84+F13 -> -479.92244 | G14: =G34+G59+G84+G13 -> -429.09762 | H14: =H34+H59+H84+H13 -> -379.09892 | I14: =I34+I59+I84+I13 -> -328.87447 | J14: =J34+J59+J84+J13 -> -241.24986 | K14: =K34+K59+K84+K13 -> -239.11128 | ... AM14: =AM34+AM59+AM84+AM13 -> 990.08139 | AO14: =SUM(D14:O14) -> -4039.7774 | AP14: =SUM(P14:AA14) -> 4209.9201 | AQ14: =SUM(AB14:AM14) -> 10422.543
A15: операционные расходы | B15: тыс сом | D15: =-('OPEX+CAPEX'!E38+'OPEX+CAPEX'!E45+'OPEX+CAPEX'!E46) -> -103.93214 | E15: =-('OPEX+CAPEX'!F38+'OPEX+CAPEX'!F45+'OPEX+CAPEX'!F46) -> -107.81022 | F15: =-('OPEX+CAPEX'!G38+'OPEX+CAPEX'!G45+'OPEX+CAPEX'!G46) -> -111.65004 | G15: =-('OPEX+CAPEX'!H38+'OPEX+CAPEX'!H45+'OPEX+CAPEX'!H46) -> -115.45454 | H15: =-('OPEX+CAPEX'!I38+'OPEX+CAPEX'!I45+'OPEX+CAPEX'!I46) -> -144.0181 | I15: =-('OPEX+CAPEX'!J38+'OPEX+CAPEX'!J45+'OPEX+CAPEX'!J46) -> -147.7599 | J15: =-('OPEX+CAPEX'!K38+'OPEX+CAPEX'!K45+'OPEX+CAPEX'!K46) -> -151.21181 | K15: =-('OPEX+CAPEX'!L38+'OPEX+CAPEX'!L45+'OPEX+CAPEX'!L46) -> -154.92132 | ... AM15: =-('OPEX+CAPEX'!AN38+'OPEX+CAPEX'!AN45+'OPEX+CAPEX'!AN46) -> -232.54572 | AO15: =SUM(D15:O15) -> -1697.9943 | AP15: =SUM(P15:AA15) -> -2455.2712 | AQ15: =SUM(AB15:AM15) -> -2732.1716
A16: прибыль | B16: тыс сом | D16: =D14+D15 -> -693.80714 | E16: =E14+E15 -> -644.79756 | F16: =F14+F15 -> -591.57248 | G16: =G14+G15 -> -544.55216 | H16: =H14+H15 -> -523.11702 | I16: =I14+I15 -> -476.63437 | J16: =J14+J15 -> -392.46167 | K16: =K14+K15 -> -394.0326 | ... AM16: =AM14+AM15 -> 757.53567 | AO16: =SUM(D16:O16) -> -5737.7717 | AP16: =SUM(P16:AA16) -> 1754.6489 | AQ16: =SUM(AB16:AM16) -> 7690.3713
A18: Депозиты KGS | B18: ЕИ | C18: Отв.исп.
A19: количество партнеров | B19: шт | D19: ='0'!D12 -> 15 | E19: ='0'!E12 -> 16 | F19: ='0'!F12 -> 17 | G19: ='0'!G12 -> 18 | H19: ='0'!H12 -> 19 | I19: ='0'!I12 -> 20 | J19: ='0'!J12 -> 20 | K19: ='0'!K12 -> 22 | ... AM19: ='0'!AM12 -> 30 | AO19: =O19 -> 30 | AP19: =AA19 -> 30 | AQ19: =AM19 -> 30
A20: среднее количество депозитов на 1 партнера | B20: шт | D20: 30 | E20: 30 | F20: 30 | G20: 30 | H20: 30 | I20: 30 | J20: 30 | K20: 30 | L20: 30 | M20: 30 | N20: 30 | O20: 30 | P20: 30 | Q20: 30 | R20: 30 | S20: 30 | T20: 30 | U20: 30 | V20: 30 | W20: 30 | X20: 30 | Y20: 30 | Z20: 30 | AA20: 30 | AB20: 30 | AC20: 30 | AD20: 30 | AE20: 30 | AF20: 30 | AG20: 30 | AH20: 30 | AI20: 30 | AJ20: 30 | AK20: 30 | AL20: 30 | AM20: 30 | AO20: =AVERAGE(D20:O20) -> 30 | AP20: =AVERAGE(P20:AA20) -> 30 | AQ20: =AVERAGE(AB20:AM20) -> 30
A21: количество новых депозитов | B21: шт | D21: =D19*D20 -> 450 | E21: =E19*E20 -> 480 | F21: =F19*F20 -> 510 | G21: =G19*G20 -> 540 | H21: =H19*H20 -> 570 | I21: =I19*I20 -> 600 | J21: =J19*J20 -> 600 | K21: =K19*K20 -> 660 | ... AM21: =AM19*AM20 -> 900 | AO21: =SUM(D21:O21) -> 7650 | AP21: =SUM(P21:AA21) -> 10800 | AQ21: =SUM(AB21:AM21) -> 10800
A22: ср. сумма депозита | B22: тыс сом | D22: 50 | E22: 50 | F22: 50 | G22: 50 | H22: 50 | I22: 50 | J22: 50 | K22: 50 | L22: 50 | M22: 50 | N22: 50 | O22: 50 | P22: 50 | Q22: 50 | R22: 50 | S22: 50 | T22: 50 | U22: 50 | V22: 50 | W22: 50 | X22: 50 | Y22: 50 | Z22: 50 | AA22: 50 | AB22: 50 | AC22: 50 | AD22: 50 | AE22: 50 | AF22: 50 | AG22: 50 | AH22: 50 | AI22: 50 | AJ22: 50 | AK22: 50 | AL22: 50 | AM22: 50 | AO22: =AVERAGE(D22:O22) -> 50 | AP22: =AVERAGE(P22:AA22) -> 50 | AQ22: =AVERAGE(AB22:AM22) -> 50
A23: привлечение депозитов | B23: тыс сом | D23: =D21*D22 -> 22500 | E23: =E21*E22 -> 24000 | F23: =F21*F22 -> 25500 | G23: =G21*G22 -> 27000 | H23: =H21*H22 -> 28500 | I23: =I21*I22 -> 30000 | J23: =J21*J22 -> 30000 | K23: =K21*K22 -> 33000 | ... AM23: =AM21*AM22 -> 45000 | AO23: =SUM(D23:O23) -> 382500 | AP23: =SUM(P23:AA23) -> 540000 | AQ23: =SUM(AB23:AM23) -> 540000
A24: капитализация % | B24: тыс сом | E24: =-D31/2 -> 65.625 | F24: =-E31/2 -> 195.97266 | G24: =-F31/2 -> 324.77959 | H24: =-G31/2 -> 452.35849 | I24: =-H31/2 -> 578.8036 | J24: =-I31/2 -> 704.20252 | K24: =-J31/2 -> 824.26108 | L24: =-K31/2 -> 943.78068 | ... AM24: =-AL31/2 -> 3089.8444 | AO24: =SUM(D24:O24) -> 7717.3897 | AP24: =SUM(P24:AA24) -> 25510.106 | AQ24: =SUM(AB24:AM24) -> 34878.041
A25: cр. срок портфеля | B25: мес | D25: 12 | E25: 12 | F25: 12 | G25: 12 | H25: 12 | I25: 12 | J25: 12 | K25: 12 | L25: 12 | M25: 12 | N25: 12 | O25: 12 | P25: 12 | Q25: 12 | R25: 12 | S25: 12 | T25: 12 | U25: 12 | V25: 12 | W25: 12 | X25: 12 | Y25: 12 | Z25: 12 | AA25: 12 | AB25: 12 | AC25: 12 | AD25: 12 | AE25: 12 | AF25: 12 | AG25: 12 | AH25: 12 | AI25: 12 | AJ25: 12 | AK25: 12 | AL25: 12 | AM25: 12 | AO25: =AVERAGE(D25:O25) -> 12 | AP25: =AVERAGE(P25:AA25) -> 12 | AQ25: =AVERAGE(AB25:AM25) -> 12
A26: возвраты | B26: тыс сом | D26: 0 | E26: =D27/E25 -> 1875 | F26: =E27/F25 -> 3724.2188 | G26: =F27/G25 -> 5555.1982 | H26: =G27/H25 -> 7369.33 | I26: =H27/I25 -> 9167.9157 | J26: =I27/J25 -> 10952.156 | K26: =J27/K25 -> 12598.16 | L26: =K27/L25 -> 14367.002 | ... AM26: =AL27/AM25 -> 44311.257 | AO26: =SUM(D26:O26) -> 120405.81 | AP26: =SUM(P26:AA26) -> 373118.01 | AQ26: =SUM(AB26:AM26) -> 501568.05
A27: портфель | B27: тыс сом | D27: =D23-D26 -> 22500 | E27: =D27+E23-E26+E24 -> 44690.625 | F27: =E27+F23-F26+F24 -> 66662.379 | G27: =F27+G23-G26+G24 -> 88431.96 | H27: =G27+H23-H26+H24 -> 110014.99 | I27: =H27+I23-I26+I24 -> 131425.88 | J27: =I27+J23-J26+J24 -> 151177.92 | K27: =J27+K23-K26+K24 -> 172404.02 | L27: =K27+L23-L26+L24 -> 194980.8 | ... AM27: =AL27+AM23-AM26+AM24 -> 535513.67 | AO27: =O27 -> 269811.58 | AP27: =AA27 -> 462203.68 | AQ27: =AM27 -> 535513.67
A28: комиссия партнеру | B28: % | D28: 0.01 | E28: 0.01 | F28: 0.01 | G28: 0.01 | H28: 0.01 | I28: 0.01 | J28: 0.01 | K28: 0.01 | L28: 0.01 | M28: 0.01 | N28: 0.01 | O28: 0.01 | P28: 0.01 | Q28: 0.01 | R28: 0.01 | S28: 0.01 | T28: 0.01 | U28: 0.01 | V28: 0.01 | W28: 0.01 | X28: 0.01 | Y28: 0.01 | Z28: 0.01 | AA28: 0.01 | AB28: 0.01 | AC28: 0.01 | AD28: 0.01 | AE28: 0.01 | AF28: 0.01 | AG28: 0.01 | AH28: 0.01 | AI28: 0.01 | AJ28: 0.01 | AK28: 0.01 | AL28: 0.01 | AM28: 0.01 | AO28: =AVERAGE(D28:O28) -> 0.01 | AP28: =AVERAGE(P28:AA28) -> 0.01 | AQ28: =AVERAGE(AB28:AM28) -> 0.01
A29: ср. % ставка портфеля | B29: % | D29: 0.14 | E29: 0.14 | F29: 0.14 | G29: 0.14 | H29: 0.14 | I29: 0.14 | J29: 0.14 | K29: 0.14 | L29: 0.14 | M29: 0.14 | N29: 0.14 | O29: 0.14 | P29: 0.14 | Q29: 0.14 | R29: 0.14 | S29: 0.14 | T29: 0.14 | U29: 0.14 | V29: 0.14 | W29: 0.14 | X29: 0.14 | Y29: 0.14 | Z29: 0.14 | AA29: 0.14 | AB29: 0.14 | AC29: 0.14 | AD29: 0.14 | AE29: 0.14 | AF29: 0.14 | AG29: 0.14 | AH29: 0.14 | AI29: 0.14 | AJ29: 0.14 | AK29: 0.14 | AL29: 0.14 | AM29: 0.14 | AO29: =AVERAGE(D29:O29) -> 0.14 | AP29: =AVERAGE(P29:AA29) -> 0.14 | AQ29: =AVERAGE(AB29:AM29) -> 0.14
A30: ср. % ставка фондирования | B30: % | D30: 0.16 | E30: 0.16 | F30: 0.16 | G30: 0.16 | H30: 0.16 | I30: 0.16 | J30: 0.16 | K30: 0.16 | L30: 0.16 | M30: 0.16 | N30: 0.16 | O30: 0.16 | P30: 0.16 | Q30: 0.16 | R30: 0.16 | S30: 0.16 | T30: 0.16 | U30: 0.16 | V30: 0.16 | W30: 0.16 | X30: 0.16 | Y30: 0.16 | Z30: 0.16 | AA30: 0.16 | AB30: 0.16 | AC30: 0.16 | AD30: 0.16 | AE30: 0.16 | AF30: 0.16 | AG30: 0.16 | AH30: 0.16 | AI30: 0.16 | AJ30: 0.16 | AK30: 0.16 | AL30: 0.16 | AM30: 0.16 | AO30: =AVERAGE(D30:O30) -> 0.16 | AP30: =AVERAGE(P30:AA30) -> 0.16 | AQ30: =AVERAGE(AB30:AM30) -> 0.16
A31: % расход | B31: тыс сом | D31: =-(C27+D27)/2*D29/12 -> -131.25 | E31: =-(D27+E27)/2*E29/12 -> -391.94531 | F31: =-(E27+F27)/2*F29/12 -> -649.55919 | G31: =-(F27+G27)/2*G29/12 -> -904.71698 | H31: =-(G27+H27)/2*H29/12 -> -1157.6072 | I31: =-(H27+I27)/2*I29/12 -> -1408.405 | J31: =-(I27+J27)/2*J29/12 -> -1648.5222 | K31: =-(J27+K27)/2*K29/12 -> -1887.5614 | ... AM31: =-(AL27+AM27)/2*AM29/12 -> -6225.6177 | AO31: =SUM(D31:O31) -> -18430.714 | AP31: =SUM(P31:AA31) -> -53358.809 | AQ31: =SUM(AB31:AM31) -> -70647.169
A32: трансфертный доход | B32: тыс сом | D32: =(C27+D27)/2*D30/12 -> 150 | E32: =(D27+E27)/2*E30/12 -> 447.9375 | F32: =(E27+F27)/2*F30/12 -> 742.35336 | G32: =(F27+G27)/2*G30/12 -> 1033.9623 | H32: =(G27+H27)/2*H30/12 -> 1322.9797 | I32: =(H27+I27)/2*I30/12 -> 1609.6058 | J32: =(I27+J27)/2*J30/12 -> 1884.0253 | K32: =(J27+K27)/2*K30/12 -> 2157.213 | ... AM32: =(AL27+AM27)/2*AM30/12 -> 7114.9917 | AO32: =SUM(D32:O32) -> 21063.673 | AP32: =SUM(P32:AA32) -> 60981.496 | AQ32: =SUM(AB32:AM32) -> 80739.621
A33: комиссия партнеру | B33: тыс сом | D33: =-D28*D23 -> -225 | E33: =-E28*E23 -> -240 | F33: =-F28*F23 -> -255 | G33: =-G28*G23 -> -270 | H33: =-H28*H23 -> -285 | I33: =-I28*I23 -> -300 | J33: =-J28*J23 -> -300 | K33: =-K28*K23 -> -330 | ... AM33: =-AM28*AM23 -> -450 | AO33: =SUM(D33:O33) -> -3825 | AP33: =SUM(P33:AA33) -> -5400 | AQ33: =SUM(AB33:AM33) -> -5400
A34: чистый операционный доход | B34: тыс сом | D34: =SUM(D31:D33) -> -206.25 | E34: =SUM(E31:E33) -> -184.00781 | F34: =SUM(F31:F33) -> -162.20583 | G34: =SUM(G31:G33) -> -140.75472 | H34: =SUM(H31:H33) -> -119.62754 | I34: =SUM(I31:I33) -> -98.799279 | J34: =SUM(J31:J33) -> -64.496834 | K34: =SUM(K31:K33) -> -60.348378 | ... AM34: =SUM(AM31:AM33) -> 439.37396 | AO34: =SUM(D34:O34) -> -1192.0409 | AP34: =SUM(P34:AA34) -> 2222.687 | AQ34: =SUM(AB34:AM34) -> 4692.4527
A36: Депозиты RUB | B36: ЕИ | C36: Отв.исп.
A37: количество партнеров | B37: шт | D37: ='0'!D12 -> 15 | E37: ='0'!E12 -> 16 | F37: ='0'!F12 -> 17 | G37: ='0'!G12 -> 18 | H37: ='0'!H12 -> 19 | I37: ='0'!I12 -> 20 | J37: ='0'!J12 -> 20 | K37: ='0'!K12 -> 22 | ... AM37: ='0'!AM12 -> 30 | AO37: =O37 -> 30 | AP37: =AA37 -> 30 | AQ37: =AM37 -> 30
A38: среднее количество депозитов на 1 партнера | B38: шт | D38: 30 | E38: 30 | F38: 30 | G38: 30 | H38: 30 | I38: 30 | J38: 30 | K38: 30 | L38: 30 | M38: 30 | N38: 30 | O38: 30 | P38: 30 | Q38: 30 | R38: 30 | S38: 30 | T38: 30 | U38: 30 | V38: 30 | W38: 30 | X38: 30 | Y38: 30 | Z38: 30 | AA38: 30 | AB38: 30 | AC38: 30 | AD38: 30 | AE38: 30 | AF38: 30 | AG38: 30 | AH38: 30 | AI38: 30 | AJ38: 30 | AK38: 30 | AL38: 30 | AM38: 30 | AO38: =AVERAGE(D38:O38) -> 30 | AP38: =AVERAGE(P38:AA38) -> 30 | AQ38: =AVERAGE(AB38:AM38) -> 30
A39: количество новых депозитов | B39: шт | D39: =D37*D38 -> 450 | E39: =E37*E38 -> 480 | F39: =F37*F38 -> 510 | G39: =G37*G38 -> 540 | H39: =H37*H38 -> 570 | I39: =I37*I38 -> 600 | J39: =J37*J38 -> 600 | K39: =K37*K38 -> 660 | ... AM39: =AM37*AM38 -> 900 | AO39: =SUM(D39:O39) -> 7650 | AP39: =SUM(P39:AA39) -> 10800 | AQ39: =SUM(AB39:AM39) -> 10800
A40: ср. сумма депозита | B40: тыс руб | D40: 50 | E40: 50 | F40: 50 | G40: 50 | H40: 50 | I40: 50 | J40: 50 | K40: 50 | L40: 50 | M40: 50 | N40: 50 | O40: 50 | P40: 50 | Q40: 50 | R40: 50 | S40: 50 | T40: 50 | U40: 50 | V40: 50 | W40: 50 | X40: 50 | Y40: 50 | Z40: 50 | AA40: 50 | AB40: 50 | AC40: 50 | AD40: 50 | AE40: 50 | AF40: 50 | AG40: 50 | AH40: 50 | AI40: 50 | AJ40: 50 | AK40: 50 | AL40: 50 | AM40: 50 | AO40: =AVERAGE(D40:O40) -> 50 | AP40: =AVERAGE(P40:AA40) -> 50 | AQ40: =AVERAGE(AB40:AM40) -> 50
A41: привлечение депозитов | B41: тыс руб | D41: =D39*D40 -> 22500 | E41: =E39*E40 -> 24000 | F41: =F39*F40 -> 25500 | G41: =G39*G40 -> 27000 | H41: =H39*H40 -> 28500 | I41: =I39*I40 -> 30000 | J41: =J39*J40 -> 30000 | K41: =K39*K40 -> 33000 | ... AM41: =AM39*AM40 -> 45000 | AO41: =SUM(D41:O41) -> 382500 | AP41: =SUM(P41:AA41) -> 540000 | AQ41: =SUM(AB41:AM41) -> 540000
A42: капитализация % | B42: тыс руб | E42: =-D49/2 -> 65.625 | F42: =-E49/2 -> 195.97266 | G42: =-F49/2 -> 324.77959 | H42: =-G49/2 -> 452.35849 | I42: =-H49/2 -> 578.8036 | J42: =-I49/2 -> 704.20252 | K42: =-J49/2 -> 824.26108 | L42: =-K49/2 -> 943.78068 | ... AM42: =-AL49/2 -> 3089.8444 | AO42: =SUM(D42:O42) -> 7717.3897 | AP42: =SUM(P42:AA42) -> 25510.106 | AQ42: =SUM(AB42:AM42) -> 34878.041
A43: cр. срок портфеля | B43: мес | D43: 12 | E43: 12 | F43: 12 | G43: 12 | H43: 12 | I43: 12 | J43: 12 | K43: 12 | L43: 12 | M43: 12 | N43: 12 | O43: 12 | P43: 12 | Q43: 12 | R43: 12 | S43: 12 | T43: 12 | U43: 12 | V43: 12 | W43: 12 | X43: 12 | Y43: 12 | Z43: 12 | AA43: 12 | AB43: 12 | AC43: 12 | AD43: 12 | AE43: 12 | AF43: 12 | AG43: 12 | AH43: 12 | AI43: 12 | AJ43: 12 | AK43: 12 | AL43: 12 | AM43: 12 | AO43: =AVERAGE(D43:O43) -> 12 | AP43: =AVERAGE(P43:AA43) -> 12 | AQ43: =AVERAGE(AB43:AM43) -> 12
A44: возвраты | B44: тыс руб | D44: 0 | E44: =D45/E43 -> 1875 | F44: =E45/F43 -> 3724.2188 | G44: =F45/G43 -> 5555.1982 | H44: =G45/H43 -> 7369.33 | I44: =H45/I43 -> 9167.9157 | J44: =I45/J43 -> 10952.156 | K44: =J45/K43 -> 12598.16 | L44: =K45/L43 -> 14367.002 | ... AM44: =AL45/AM43 -> 44311.257 | AO44: =SUM(D44:O44) -> 120405.81 | AP44: =SUM(P44:AA44) -> 373118.01 | AQ44: =SUM(AB44:AM44) -> 501568.05
...

Sheet BaaS.3
A1: BaaS - Онлайн транзакционный бизнес
D3: 46023 | E3: 46054 | F3: 46082 | G3: 46113 | H3: 46143 | I3: 46174 | J3: 46204 | K3: 46235 | L3: 46266 | M3: 46296 | N3: 46327 | O3: 46357 | P3: 46388 | Q3: 46419 | R3: 46447 | S3: 46478 | T3: 46508 | U3: 46539 | V3: 46569 | W3: 46600 | X3: 46631 | Y3: 46661 | Z3: 46692 | AA3: 46722 | AB3: 46753 | AC3: 46784 | AD3: 46813 | AE3: 46844 | AF3: 46874 | AG3: 46905 | AH3: 46935 | AI3: 46966 | AJ3: 46997 | AK3: 47027 | AL3: 47058 | AM3: 47088 | AO3: =YEAR(O3) -> 2026 | AP3: =YEAR(AA3) -> 2027 | AQ3: =YEAR(AM3) -> 2028
D4: m1 | E4: m2 | F4: m3 | G4: m4 | H4: m5 | I4: m6 | J4: m7 | K4: m8 | L4: m9 | M4: m10 | N4: m11 | O4: m12 | P4: m13 | Q4: m14 | R4: m15 | S4: m16 | T4: m17 | U4: m18 | V4: m19 | W4: m20 | X4: m21 | Y4: m22 | Z4: m23 | AA4: m24 | AB4: m25 | AC4: m26 | AD4: m27 | AE4: m28 | AF4: m29 | AG4: m30 | AH4: m31 | AI4: m32 | AJ4: m33 | AK4: m34 | AL4: m35 | AM4: m36 | AO4: Y1 | AP4: Y2 | AQ4: Y3
D5: 1 | E5: =D5+1 -> 2 | F5: =E5+1 -> 3 | G5: =F5+1 -> 4 | H5: =G5+1 -> 5 | I5: =H5+1 -> 6 | J5: =I5+1 -> 7 | K5: =J5+1 -> 8 | L5: =K5+1 -> 9 | ... AM5: =AL5+1 -> 36
A7: DCB ID / DCB BIO
A8: количество партнеров | B8: шт | D8: ='0'!D13 -> 15 | E8: ='0'!E13 -> 16 | F8: ='0'!F13 -> 17 | G8: ='0'!G13 -> 18 | H8: ='0'!H13 -> 19 | I8: ='0'!I13 -> 20 | J8: ='0'!J13 -> 20 | K8: ='0'!K13 -> 22 | ... AM8: ='0'!AM13 -> 30 | AO8: =O8 -> 30 | AP8: =AA8 -> 30 | AQ8: =AM8 -> 30
A9: среднее кол-во клиентов на 1 партнера | B9: шт | D9: 100 | E9: 100 | F9: 100 | G9: 100 | H9: 100 | I9: 100 | J9: 100 | K9: 100 | L9: 100 | M9: 100 | N9: 100 | O9: 100 | P9: 100 | Q9: 100 | R9: 100 | S9: 100 | T9: 100 | U9: 100 | V9: 100 | W9: 100 | X9: 100 | Y9: 100 | Z9: 100 | AA9: 100 | AB9: 100 | AC9: 100 | AD9: 100 | AE9: 100 | AF9: 100 | AG9: 100 | AH9: 100 | AI9: 100 | AJ9: 100 | AK9: 100 | AL9: 100 | AM9: 100 | AO9: =AVERAGE(D9:O9) -> 100 | AP9: =AVERAGE(P9:AA9) -> 100 | AQ9: =AVERAGE(AB9:AM9) -> 100
A10: количество клиентов | B10: шт | D10: =D8*D9 -> 1500 | E10: =E8*E9 -> 1600 | F10: =F8*F9 -> 1700 | G10: =G8*G9 -> 1800 | H10: =H8*H9 -> 1900 | I10: =I8*I9 -> 2000 | J10: =J8*J9 -> 2000 | K10: =K8*K9 -> 2200 | ... AM10: =AM8*AM9 -> 3000 | AO10: =SUM(D10:O10) -> 25500 | AP10: =SUM(P10:AA10) -> 36000 | AQ10: =SUM(AB10:AM10) -> 36000
A11: ср.кол-во идентификаций в месяц 1 клиента | B11: шт | D11: 1 | E11: 1 | F11: 1 | G11: 1 | H11: 1 | I11: 1 | J11: 1 | K11: 1 | L11: 1 | M11: 1 | N11: 1 | O11: 1 | P11: 1 | Q11: 1 | R11: 1 | S11: 1 | T11: 1 | U11: 1 | V11: 1 | W11: 1 | X11: 1 | Y11: 1 | Z11: 1 | AA11: 1 | AB11: 1 | AC11: 1 | AD11: 1 | AE11: 1 | AF11: 1 | AG11: 1 | AH11: 1 | AI11: 1 | AJ11: 1 | AK11: 1 | AL11: 1 | AM11: 1 | AO11: =AVERAGE(D11:O11) -> 1 | AP11: =AVERAGE(P11:AA11) -> 1 | AQ11: =AVERAGE(AB11:AM11) -> 1
A12: общее кол-во идентификаций | B12: шт | D12: =D10*D11 -> 1500 | E12: =E10*E11 -> 1600 | F12: =F10*F11 -> 1700 | G12: =G10*G11 -> 1800 | H12: =H10*H11 -> 1900 | I12: =I10*I11 -> 2000 | J12: =J10*J11 -> 2000 | K12: =K10*K11 -> 2200 | ... AM12: =AM10*AM11 -> 3000 | AO12: =SUM(D12:O12) -> 25500 | AP12: =SUM(P12:AA12) -> 36000 | AQ12: =SUM(AB12:AM12) -> 36000
A13: ср.комиссия за идентификацию 1 клиента | B13: сом | D13: 50 | E13: 50 | F13: 50 | G13: 50 | H13: 50 | I13: 50 | J13: 50 | K13: 50 | L13: 50 | M13: 50 | N13: 50 | O13: 50 | P13: 50 | Q13: 50 | R13: 50 | S13: 50 | T13: 50 | U13: 50 | V13: 50 | W13: 50 | X13: 50 | Y13: 50 | Z13: 50 | AA13: 50 | AB13: 50 | AC13: 50 | AD13: 50 | AE13: 50 | AF13: 50 | AG13: 50 | AH13: 50 | AI13: 50 | AJ13: 50 | AK13: 50 | AL13: 50 | AM13: 50 | AO13: =AVERAGE(D13:O13) -> 50 | AP13: =AVERAGE(P13:AA13) -> 50 | AQ13: =AVERAGE(AB13:AM13) -> 50
A14: комиссионный доход | B14: тыс сом | D14: =D12*D13/1000*(1-2/102) -> 73.529412 | E14: =E12*E13/1000*(1-2/102) -> 78.431373 | F14: =F12*F13/1000*(1-2/102) -> 83.333333 | G14: =G12*G13/1000*(1-2/102) -> 88.235294 | H14: =H12*H13/1000*(1-2/102) -> 93.137255 | I14: =I12*I13/1000*(1-2/102) -> 98.039216 | J14: =J12*J13/1000*(1-2/102) -> 98.039216 | K14: =K12*K13/1000*(1-2/102) -> 107.84314 | ... AM14: =AM12*AM13/1000*(1-2/102) -> 147.05882 | AO14: =SUM(D14:O14) -> 1250 | AP14: =SUM(P14:AA14) -> 1764.7059 | AQ14: =SUM(AB14:AM14) -> 1764.7059
A15: себестоимость 1 идентификации (OzForenzics, 0,29usd за 1 запрос) | B15: сом | D15: =-0.29*'0'!D27 -> -24.65 | E15: =-0.29*'0'!E27 -> -24.65 | F15: =-0.29*'0'!F27 -> -24.65 | G15: =-0.29*'0'!G27 -> -24.65 | H15: =-0.29*'0'!H27 -> -24.65 | I15: =-0.29*'0'!I27 -> -24.65 | J15: =-0.29*'0'!J27 -> -24.65 | K15: =-0.29*'0'!K27 -> -24.65 | ... AM15: =-0.29*'0'!AM27 -> -24.65 | AO15: =SUM(D15:O15) -> -295.8 | AP15: =SUM(P15:AA15) -> -295.8 | AQ15: =SUM(AB15:AM15) -> -295.8
A16: операционные расходы (provider) | B16: тыс сом | D16: =D12*D15/1000 -> -36.975 | E16: =E12*E15/1000 -> -39.44 | F16: =F12*F15/1000 -> -41.905 | G16: =G12*G15/1000 -> -44.37 | H16: =H12*H15/1000 -> -46.835 | I16: =I12*I15/1000 -> -49.3 | J16: =J12*J15/1000 -> -49.3 | K16: =K12*K15/1000 -> -54.23 | ... AM16: =AM12*AM15/1000 -> -73.95 | AO16: =SUM(D16:O16) -> -628.575 | AP16: =SUM(P16:AA16) -> -887.4 | AQ16: =SUM(AB16:AM16) -> -887.4
A17: операционные расходы (банк) | B17: тыс сом | D17: =-('OPEX+CAPEX'!E50+'OPEX+CAPEX'!E52+'OPEX+CAPEX'!E53) -> -100 | E17: =-('OPEX+CAPEX'!F50+'OPEX+CAPEX'!F52+'OPEX+CAPEX'!F53) -> -142.5 | F17: =-('OPEX+CAPEX'!G50+'OPEX+CAPEX'!G52+'OPEX+CAPEX'!G53) -> -206.25 | G17: =-('OPEX+CAPEX'!H50+'OPEX+CAPEX'!H52+'OPEX+CAPEX'!H53) -> -270 | H17: =-('OPEX+CAPEX'!I50+'OPEX+CAPEX'!I52+'OPEX+CAPEX'!I53) -> -270 | I17: =-('OPEX+CAPEX'!J50+'OPEX+CAPEX'!J52+'OPEX+CAPEX'!J53) -> -270 | J17: =-('OPEX+CAPEX'!K50+'OPEX+CAPEX'!K52+'OPEX+CAPEX'!K53) -> -270 | K17: =-('OPEX+CAPEX'!L50+'OPEX+CAPEX'!L52+'OPEX+CAPEX'!L53) -> -270 | ... AM17: =-('OPEX+CAPEX'!AN50+'OPEX+CAPEX'!AN52+'OPEX+CAPEX'!AN53) -> -277.08333 | AO17: =SUM(D17:O17) -> -2878.75 | AP17: =SUM(P17:AA17) -> -3325 | AQ17: =SUM(AB17:AM17) -> -3325
A18: прибыль | B18: тыс сом | D18: =D14+D16+D17 -> -63.445588 | E18: =E14+E16+E17 -> -103.50863 | F18: =F14+F16+F17 -> -164.82167 | G18: =G14+G16+G17 -> -226.13471 | H18: =H14+H16+H17 -> -223.69775 | I18: =I14+I16+I17 -> -221.26078 | J18: =J14+J16+J17 -> -221.26078 | K18: =K14+K16+K17 -> -216.38686 | ... AM18: =AM14+AM16+AM17 -> -203.97451 | AO18: =SUM(D18:O18) -> -2257.325 | AP18: =SUM(P18:AA18) -> -2447.6941 | AQ18: =SUM(AB18:AM18) -> -2447.6941
A20: QR прием / оплата
A21: количество партнеров QR-приход | B21: шт | D21: ='0'!D14 -> 7 | E21: ='0'!E14 -> 7 | F21: ='0'!F14 -> 8 | G21: ='0'!G14 -> 8 | H21: ='0'!H14 -> 8 | I21: ='0'!I14 -> 9 | J21: ='0'!J14 -> 9 | K21: ='0'!K14 -> 9 | ... AM21: ='0'!AM14 -> 14 | AO21: =O21 -> 14 | AP21: =AA21 -> 14 | AQ21: =AM21 -> 14
A22: количество партнеров QR-оплата | B22: шт | D22: ='0'!D15 -> 5 | E22: ='0'!E15 -> 5 | F22: ='0'!F15 -> 5 | G22: ='0'!G15 -> 6 | H22: ='0'!H15 -> 6 | I22: ='0'!I15 -> 6 | J22: ='0'!J15 -> 7 | K22: ='0'!K15 -> 7 | ... AM22: ='0'!AM15 -> 9 | AO22: =O22 -> 9 | AP22: =AA22 -> 9 | AQ22: =AM22 -> 9
A23: среднемесячная сумма Предварительного возмещения на 1 партнера (на транзитных счета) | B23: тыс сом | D23: =(270000+50000)/2 -> 160000 | E23: =(270000+50000)/2 -> 160000 | F23: =(270000+50000)/2 -> 160000 | G23: =(270000+50000)/2 -> 160000 | H23: =(270000+50000)/2 -> 160000 | I23: =(270000+50000)/2 -> 160000 | J23: =(270000+50000)/2 -> 160000 | K23: =(270000+50000)/2 -> 160000 | ... AM23: =(270000+50000)/2 -> 160000 | AO23: =AVERAGE(D23:O23) -> 160000 | AP23: =AVERAGE(P23:AA23) -> 160000 | AQ23: =AVERAGE(AB23:AM23) -> 160000
A24: общая сумма Предварительного возмещения (для исходящих платежей Партнеров) | B24: тыс сом | D24: =D22*D23 -> 800000 | E24: =E22*E23 -> 800000 | F24: =F22*F23 -> 800000 | G24: =G22*G23 -> 960000 | H24: =H22*H23 -> 960000 | I24: =I22*I23 -> 960000 | J24: =J22*J23 -> 1120000 | K24: =K22*K23 -> 1120000 | ... AM24: =AM22*AM23 -> 1440000 | AO24: =AVERAGE(D24:O24) -> 1053333.3 | AP24: =AVERAGE(P24:AA24) -> 1440000 | AQ24: =AVERAGE(AB24:AM24) -> 1440000
A25: ср.сумма остатка на р/с 1 Партнера по входящим платежам | B25: тыс сом | D25: 10000 | E25: 10000 | F25: 10000 | G25: 10000 | H25: 10000 | I25: 10000 | J25: 10000 | K25: 10000 | L25: 10000 | M25: 10000 | N25: 10000 | O25: 10000 | P25: 10000 | Q25: 10000 | R25: 10000 | S25: 10000 | T25: 10000 | U25: 10000 | V25: 10000 | W25: 10000 | X25: 10000 | Y25: 10000 | Z25: 10000 | AA25: 10000 | AB25: 10000 | AC25: 10000 | AD25: 10000 | AE25: 10000 | AF25: 10000 | AG25: 10000 | AH25: 10000 | AI25: 10000 | AJ25: 10000 | AK25: 10000 | AL25: 10000 | AM25: 10000 | AO25: =AVERAGE(D25:O25) -> 10000 | AP25: =AVERAGE(P25:AA25) -> 10000 | AQ25: =AVERAGE(AB25:AM25) -> 10000
A26: общая сумма остатков на р/с Партнеров по входящим платежам | B26: тыс сом | D26: =D21*D25 -> 70000 | E26: =E21*E25 -> 70000 | F26: =F21*F25 -> 80000 | G26: =G21*G25 -> 80000 | H26: =H21*H25 -> 80000 | I26: =I21*I25 -> 90000 | J26: =J21*J25 -> 90000 | K26: =K21*K25 -> 90000 | ... AM26: =AM21*AM25 -> 140000 | AO26: =O26 -> 140000 | AP26: =AA26 -> 140000 | AQ26: =AM26 -> 140000
A27: ср. % ставка фондирования | B27: % | D27: 0.04 | E27: 0.04 | F27: 0.04 | G27: 0.04 | H27: 0.04 | I27: 0.04 | J27: 0.04 | K27: 0.04 | L27: 0.04 | M27: 0.04 | N27: 0.04 | O27: 0.04 | P27: 0.04 | Q27: 0.04 | R27: 0.04 | S27: 0.04 | T27: 0.04 | U27: 0.04 | V27: 0.04 | W27: 0.04 | X27: 0.04 | Y27: 0.04 | Z27: 0.04 | AA27: 0.04 | AB27: 0.04 | AC27: 0.04 | AD27: 0.04 | AE27: 0.04 | AF27: 0.04 | AG27: 0.04 | AH27: 0.04 | AI27: 0.04 | AJ27: 0.04 | AK27: 0.04 | AL27: 0.04 | AM27: 0.04 | AO27: =AVERAGE(D27:O27) -> 0.04 | AP27: =AVERAGE(P27:AA27) -> 0.04 | AQ27: =AVERAGE(AB27:AM27) -> 0.04
A28: трансфертный доход | B28: тыс сом | D28: =(C24+D24+C26+D26)/2*D27/12 -> 1450 | E28: =(D24+E24+D26+E26)/2*E27/12 -> 2900 | F28: =(E24+F24+E26+F26)/2*F27/12 -> 2916.6667 | G28: =(F24+G24+F26+G26)/2*G27/12 -> 3200 | H28: =(G24+H24+G26+H26)/2*H27/12 -> 3466.6667 | I28: =(H24+I24+H26+I26)/2*I27/12 -> 3483.3333 | J28: =(I24+J24+I26+J26)/2*J27/12 -> 3766.6667 | K28: =(J24+K24+J26+K26)/2*K27/12 -> 4033.3333 | ... AM28: =(AL24+AM24+AL26+AM26)/2*AM27/12 -> 5266.6667 | AO28: =SUM(D28:O28) -> 43200 | AP28: =SUM(P28:AA28) -> 63200 | AQ28: =SUM(AB28:AM28) -> 63200
A29: ср.сумма исходящих переводов на 1 Партнера | B29: тыс сом | D29: 150000 | E29: 150000 | F29: 150000 | G29: 150000 | H29: 150000 | I29: 150000 | J29: 150000 | K29: 150000 | L29: 150000 | M29: 150000 | N29: 150000 | O29: 150000 | P29: 150000 | Q29: 150000 | R29: 150000 | S29: 150000 | T29: 150000 | U29: 150000 | V29: 150000 | W29: 150000 | X29: 150000 | Y29: 150000 | Z29: 150000 | AA29: 150000 | AB29: 150000 | AC29: 150000 | AD29: 150000 | AE29: 150000 | AF29: 150000 | AG29: 150000 | AH29: 150000 | AI29: 150000 | AJ29: 150000 | AK29: 150000 | AL29: 150000 | AM29: 150000 | AO29: =AVERAGE(D29:O29) -> 150000 | AP29: =AVERAGE(P29:AA29) -> 150000 | AQ29: =AVERAGE(AB29:AM29) -> 150000
A30: ср.сумма входящих переводов на 1 Партнера | B30: тыс сом | D30: =1250000/4 -> 312500 | E30: =1250000/4 -> 312500 | F30: =1250000/4 -> 312500 | G30: =1250000/4 -> 312500 | H30: =1250000/4 -> 312500 | I30: =1250000/4 -> 312500 | J30: =1250000/4 -> 312500 | K30: =1250000/4 -> 312500 | ... AM30: =1250000/4 -> 312500 | AO30: =AVERAGE(D30:O30) -> 312500 | AP30: =AVERAGE(P30:AA30) -> 312500 | AQ30: =AVERAGE(AB30:AM30) -> 312500
A31: общая сумма исходящих переводов | B31: тыс сом | D31: =D29*D22 -> 750000 | E31: =E29*E22 -> 750000 | F31: =F29*F22 -> 750000 | G31: =G29*G22 -> 900000 | H31: =H29*H22 -> 900000 | I31: =I29*I22 -> 900000 | J31: =J29*J22 -> 1050000 | K31: =K29*K22 -> 1050000 | ... AM31: =AM29*AM22 -> 1350000 | AO31: =SUM(D31:O31) -> 11850000 | AP31: =SUM(P31:AA31) -> 16200000 | AQ31: =SUM(AB31:AM31) -> 16200000
A32: общая сумма входящих переводов | B32: тыс сом | D32: =D30*D21 -> 2187500 | E32: =E30*E21 -> 2187500 | F32: =F30*F21 -> 2500000 | G32: =G30*G21 -> 2500000 | H32: =H30*H21 -> 2500000 | I32: =I30*I21 -> 2812500 | J32: =J30*J21 -> 2812500 | K32: =K30*K21 -> 2812500 | ... AM32: =AM30*AM21 -> 4375000 | AO32: =SUM(D32:O32) -> 34687500 | AP32: =SUM(P32:AA32) -> 52500000 | AQ32: =SUM(AB32:AM32) -> 52500000
A33: ср.комиссия за исходящие платежи партнера | B33: % | D33: 0.005 | E33: 0.005 | F33: 0.005 | G33: 0.005 | H33: 0.005 | I33: 0.005 | J33: 0.005 | K33: 0.005 | L33: 0.005 | M33: 0.005 | N33: 0.005 | O33: 0.005 | P33: 0.005 | Q33: 0.005 | R33: 0.005 | S33: 0.005 | T33: 0.005 | U33: 0.005 | V33: 0.005 | W33: 0.005 | X33: 0.005 | Y33: 0.005 | Z33: 0.005 | AA33: 0.005 | AB33: 0.005 | AC33: 0.005 | AD33: 0.005 | AE33: 0.005 | AF33: 0.005 | AG33: 0.005 | AH33: 0.005 | AI33: 0.005 | AJ33: 0.005 | AK33: 0.005 | AL33: 0.005 | AM33: 0.005 | AO33: =AVERAGE(D33:O33) -> 0.005 | AP33: =AVERAGE(P33:AA33) -> 0.005 | AQ33: =AVERAGE(AB33:AM33) -> 0.005
A34: ср.комиссия за исходящие платежи (Interchange) | B34: % | D34: 0.002 | E34: 0.002 | F34: 0.002 | G34: 0.002 | H34: 0.002 | I34: 0.002 | J34: 0.002 | K34: 0.002 | L34: 0.002 | M34: 0.002 | N34: 0.002 | O34: 0.002 | P34: 0.002 | Q34: 0.002 | R34: 0.002 | S34: 0.002 | T34: 0.002 | U34: 0.002 | V34: 0.002 | W34: 0.002 | X34: 0.002 | Y34: 0.002 | Z34: 0.002 | AA34: 0.002 | AB34: 0.002 | AC34: 0.002 | AD34: 0.002 | AE34: 0.002 | AF34: 0.002 | AG34: 0.002 | AH34: 0.002 | AI34: 0.002 | AJ34: 0.002 | AK34: 0.002 | AL34: 0.002 | AM34: 0.002 | AO34: =AVERAGE(D34:O34) -> 0.002 | AP34: =AVERAGE(P34:AA34) -> 0.002 | AQ34: =AVERAGE(AB34:AM34) -> 0.002
A35: ср.комиссия за входящие платежи партнера | B35: % | D35: 0.005 | E35: 0.005 | F35: 0.005 | G35: 0.005 | H35: 0.005 | I35: 0.005 | J35: 0.005 | K35: 0.005 | L35: 0.005 | M35: 0.005 | N35: 0.005 | O35: 0.005 | P35: 0.005 | Q35: 0.005 | R35: 0.005 | S35: 0.005 | T35: 0.005 | U35: 0.005 | V35: 0.005 | W35: 0.005 | X35: 0.005 | Y35: 0.005 | Z35: 0.005 | AA35: 0.005 | AB35: 0.005 | AC35: 0.005 | AD35: 0.005 | AE35: 0.005 | AF35: 0.005 | AG35: 0.005 | AH35: 0.005 | AI35: 0.005 | AJ35: 0.005 | AK35: 0.005 | AL35: 0.005 | AM35: 0.005 | AO35: =AVERAGE(D35:O35) -> 0.005 | AP35: =AVERAGE(P35:AA35) -> 0.005 | AQ35: =AVERAGE(AB35:AM35) -> 0.005
A36: комиссионный доход | B36: тыс сом | D36: =(D31*D33+D32*D35+D31*D34)*(1-2/102) -> 15870.098 | E36: =(E31*E33+E32*E35+E31*E34)*(1-2/102) -> 15870.098 | F36: =(F31*F33+F32*F35+F31*F34)*(1-2/102) -> 17401.961 | G36: =(G31*G33+G32*G35+G31*G34)*(1-2/102) -> 18431.373 | H36: =(H31*H33+H32*H35+H31*H34)*(1-2/102) -> 18431.373 | I36: =(I31*I33+I32*I35+I31*I34)*(1-2/102) -> 19963.235 | J36: =(J31*J33+J32*J35+J31*J34)*(1-2/102) -> 20992.647 | K36: =(K31*K33+K32*K35+K31*K34)*(1-2/102) -> 20992.647 | ... AM36: =(AM31*AM33+AM32*AM35+AM31*AM34)*(1-2/102) -> 30710.784 | AO36: =SUM(D36:O36) -> 251360.29 | AP36: =SUM(P36:AA36) -> 368529.41 | AQ36: =SUM(AB36:AM36) -> 368529.41
A37: ср.комиссия возмещения Процессингу за входящие платежи | B37: % | D37: 0.001 | E37: 0.001 | F37: 0.001 | G37: 0.001 | H37: 0.001 | I37: 0.001 | J37: 0.001 | K37: 0.001 | L37: 0.001 | M37: 0.001 | N37: 0.001 | O37: 0.001 | P37: 0.001 | Q37: 0.001 | R37: 0.001 | S37: 0.001 | T37: 0.001 | U37: 0.001 | V37: 0.001 | W37: 0.001 | X37: 0.001 | Y37: 0.001 | Z37: 0.001 | AA37: 0.001 | AB37: 0.001 | AC37: 0.001 | AD37: 0.001 | AE37: 0.001 | AF37: 0.001 | AG37: 0.001 | AH37: 0.001 | AI37: 0.001 | AJ37: 0.001 | AK37: 0.001 | AL37: 0.001 | AM37: 0.001 | AO37: =AVERAGE(D37:O37) -> 0.001 | AP37: =AVERAGE(P37:AA37) -> 0.001 | AQ37: =AVERAGE(AB37:AM37) -> 0.001
A38: сумма возмещения Процессингу за входящие платежи | B38: тыс сом | D38: =-D32*D37 -> -2187.5 | E38: =-E32*E37 -> -2187.5 | F38: =-F32*F37 -> -2500 | G38: =-G32*G37 -> -2500 | H38: =-H32*H37 -> -2500 | I38: =-I32*I37 -> -2812.5 | J38: =-J32*J37 -> -2812.5 | K38: =-K32*K37 -> -2812.5 | ... AM38: =-AM32*AM37 -> -4375 | AO38: =SUM(D38:O38) -> -34687.5 | AP38: =SUM(P38:AA38) -> -52500 | AQ38: =SUM(AB38:AM38) -> -52500
A39: ср.комиссия за входящие платежи (Interchange) | B39: % | D39: 0.002 | E39: 0.002 | F39: 0.002 | G39: 0.002 | H39: 0.002 | I39: 0.002 | J39: 0.002 | K39: 0.002 | L39: 0.002 | M39: 0.002 | N39: 0.002 | O39: 0.002 | P39: 0.002 | Q39: 0.002 | R39: 0.002 | S39: 0.002 | T39: 0.002 | U39: 0.002 | V39: 0.002 | W39: 0.002 | X39: 0.002 | Y39: 0.002 | Z39: 0.002 | AA39: 0.002 | AB39: 0.002 | AC39: 0.002 | AD39: 0.002 | AE39: 0.002 | AF39: 0.002 | AG39: 0.002 | AH39: 0.002 | AI39: 0.002 | AJ39: 0.002 | AK39: 0.002 | AL39: 0.002 | AM39: 0.002 | AO39: =AVERAGE(D39:O39) -> 0.002 | AP39: =AVERAGE(P39:AA39) -> 0.002 | AQ39: =AVERAGE(AB39:AM39) -> 0.002
A40: сумма возмещения за входящие платежи (Interchange) | B40: тыс сом | D40: =-D32*D39 -> -4375 | E40: =-E32*E39 -> -4375 | F40: =-F32*F39 -> -5000 | G40: =-G32*G39 -> -5000 | H40: =-H32*H39 -> -5000 | I40: =-I32*I39 -> -5625 | J40: =-J32*J39 -> -5625 | K40: =-K32*K39 -> -5625 | ... AM40: =-AM32*AM39 -> -8750 | AO40: =SUM(D40:O40) -> -69375 | AP40: =SUM(P40:AA40) -> -105000 | AQ40: =SUM(AB40:AM40) -> -105000
