Workbook
Name __dol1: '[1]Д&Р'!$C$45
Name __END1: [2]Лист1!$A$293
Name __kurs_dol__: [3]Свод!$M$5
Name _dol1: '[1]Д&Р'!$C$45
Name _END1: [2]Лист1!$A$293
Name aned110: [4]неделя!$Q$81
Name aned111: [4]неделя!$Q$82
Name aned112: [4]неделя!$Q$83
Name aned113: [4]неделя!$Q$84
Name aned146: [4]неделя!$Q$93
Name aned158: [4]неделя!$Q$100
Name aned161: [4]неделя!$Q$169
Name aned162: [4]неделя!$Q$170
Name aned170: [4]неделя!$Q$178
Name aned184: [4]неделя!$Q$208
Name aned191: [4]неделя!$Q$220
Name aned194: [4]неделя!$Q$223
Name aned213: [4]неделя!$Q$229
Name aned224: [4]неделя!$Q$104
Name aned239: [4]неделя!$Q$109
Name aned34: [4]неделя!$Q$214
Name aned50: [4]неделя!$Q$38
Name aned60: [4]неделя!$Q$50
Name aned61: [4]неделя!$Q$51
Name aned62: [4]неделя!$Q$52
Name aned620: [4]неделя!$Q$416
Name aned624: [4]неделя!$Q$180
Name aned628: [4]неделя!$Q$184
Name aned629: [4]неделя!$Q$417
Name aned63: [4]неделя!$Q$53
Name aned632: [4]неделя!$Q$118
Name aned636: [4]неделя!$Q$121
Name aned637: [4]неделя!$Q$122
Name aned639: [4]неделя!$Q$124
Name aned64: [4]неделя!$Q$54
Name aned647: [4]неделя!$Q$185
Name aned65: [4]неделя!$Q$55
Name aned657: [4]неделя!$Q$187
Name aned662: [4]неделя!$Q$127
Name aned668: [4]неделя!$Q$132
Name aned680: [4]неделя!$Q$134
Name aned681: [4]неделя!$Q$135
Name aned682: [4]неделя!$Q$136
Name aned683: [4]неделя!$Q$137
Name aned716: [4]неделя!$Q$484
Name aned718: [4]неделя!$Q$486
Name aned719: [4]неделя!$Q$487
Name aned72: [4]неделя!$Q$62
Name aned728: [4]неделя!$Q$501
Name aned729: [4]неделя!$Q$502
Name aned731: [4]неделя!$Q$189
Name aned76: [4]неделя!$Q$66
Name aned77: [4]неделя!$Q$67
Name aned79: [4]неделя!$Q$69
Name aned812: [4]неделя!$Q$195
Name aned86: [4]неделя!$Q$70
Name aned87: [4]неделя!$Q$71
Name aned882: [4]неделя!$Q$561
Name aned900: [4]неделя!$Q$562
Name aned902: [4]неделя!$Q$547

Sheet Лист3
C1: 1 мес | D1: 2 мес | E1: 3 мес | F1: 4 мес | G1: 5 мес | H1: 6 мес | I1: 7 мес | J1: 8 мес | K1: 9 мес | L1: 10 мес | M1: 11 мес | N1: 12 мес | O1: 1 год | P1: 1 мес | Q1: 2 мес | R1: 3 мес | S1: 4 мес | T1: 5 мес | U1: 6 мес | V1: 7 мес | W1: 8 мес | X1: 9 мес | Y1: 10 мес | Z1: 11 мес | AA1: 12 мес | AB1: 2 год | AC1: 1 мес | AD1: 2 мес | AE1: 3 мес | AF1: 4 мес | AG1: 5 мес | AH1: 6 мес | AI1: 7 мес | AJ1: 8 мес | AK1: 9 мес | AL1: 10 мес | AM1: 11 мес | AN1: 12 мес | AO1: 3 год | AP1: 1 мес | AQ1: 2 мес | AR1: 3 мес | AS1: 4 мес | AT1: 5 мес | AU1: 6 мес | AV1: 7 мес | AW1: 8 мес | AX1: 9 мес | AY1: 10 мес | AZ1: 11 мес | BA1: 12 мес | BB1: 4 год | BC1: 1 мес | BD1: 2 мес | BE1: 3 мес | BF1: 4 мес | BG1: 5 мес | BH1: 6 мес | BI1: 7 мес | BJ1: 8 мес | BK1: 9 мес | BL1: 10 мес | BM1: 11 мес | BN1: 12 мес | BO1: 5 год
A3: Оформленные заявки | C3: =O3*C4 -> #REF! | D3: =O3*D4 -> #REF! | E3: =O3*E4 -> #REF! | F3: =O3*F4 -> #REF! | G3: =O3*G4 -> #REF! | H3: =O3*H4 -> #REF! | I3: =O3*I4 -> #REF! | J3: =O3*J4 -> #REF! | K3: =O3*K4 -> #REF! | L3: =O3*L4 -> #REF! | M3: =O3*M4 -> #REF! | N3: =O3*N4 -> #REF! | O3: =#REF! -> #REF! | P3: =AB3*P4 -> #REF! | Q3: =AB3*Q4 -> #REF! | R3: =AB3*R4 -> #REF! | S3: =AB3*S4 -> #REF! | T3: =AB3*T4 -> #REF! | U3: =AB3*U4 -> #REF! | V3: =AB3*V4 -> #REF! | W3: =AB3*W4 -> #REF! | X3: =AB3*X4 -> #REF! | Y3: =AB3*Y4 -> #REF! | Z3: =AB3*Z4 -> #REF! | AA3: =AB3*AA4 -> #REF! | AB3: =#REF! -> #REF! | AC3: =AO3*AC4 -> #REF! | AD3: =AO3*AD4 -> #REF! | AE3: =AO3*AE4 -> #REF! | AF3: =AO3*AF4 -> #REF! | AG3: =AO3*AG4 -> #REF! | AH3: =AO3*AH4 -> #REF! | AI3: =AO3*AI4 -> #REF! | AJ3: =AO3*AJ4 -> #REF! | AK3: =AO3*AK4 -> #REF! | AL3: =AO3*AL4 -> #REF! | AM3: =AO3*AM4 -> #REF! | AN3: =AO3*AN4 -> #REF! | AO3: =#REF! -> #REF! | AP3: =BB3*AP4 -> #REF! | AQ3: =BB3*AQ4 -> #REF! | AR3: =BB3*AR4 -> #REF! | AS3: =BB3*AS4 -> #REF! | AT3: =BB3*AT4 -> #REF! | AU3: =BB3*AU4 -> #REF! | AV3: =BB3*AV4 -> #REF! | AW3: =BB3*AW4 -> #REF! | AX3: =BB3*AX4 -> #REF! | AY3: =BB3*AY4 -> #REF! | AZ3: =BB3*AZ4 -> #REF! | BA3: =BB3*BA4 -> #REF! | BB3: =#REF! -> #REF! | BC3: =BO3*BC4 -> #REF! | BD3: =BO3*BD4 -> #REF! | BE3: =BO3*BE4 -> #REF! | BF3: =BO3*BF4 -> #REF! | BG3: =BO3*BG4 -> #REF! | BH3: =BO3*BH4 -> #REF! | BI3: =BO3*BI4 -> #REF! | BJ3: =BO3*BJ4 -> #REF! | BK3: =BO3*BK4 -> #REF! | BL3: =BO3*BL4 -> #REF! | BM3: =BO3*BM4 -> #REF! | BN3: =BO3*BN4 -> #REF! | BO3: =#REF! -> #REF!
A4: сезонность | C4: =100%/12 -> 0.083333333 | D4: =100%/12 -> 0.083333333 | E4: =100%/12 -> 0.083333333 | F4: =100%/12 -> 0.083333333 | G4: =100%/12 -> 0.083333333 | H4: =100%/12 -> 0.083333333 | I4: =100%/12 -> 0.083333333 | J4: =100%/12 -> 0.083333333 | ... M4: =100%/12 -> 0.083333333 | N4: =100%-SUM(C4:M4) -> 0.083333333 | O4: =SUM(C4:N4) -> 1 | P4: =100%/12 -> 0.083333333 | Q4: =100%/12 -> 0.083333333 | R4: =100%/12 -> 0.083333333 | S4: =100%/12 -> 0.083333333 | T4: =100%/12 -> 0.083333333 | U4: =100%/12 -> 0.083333333 | V4: =100%/12 -> 0.083333333 | W4: =100%/12 -> 0.083333333 | ... Z4: =100%/12 -> 0.083333333 | AA4: =100%-SUM(P4:Z4) -> 0.083333333 | AB4: =SUM(P4:AA4) -> 1 | AC4: =100%/12 -> 0.083333333 | AD4: =100%/12 -> 0.083333333 | AE4: =100%/12 -> 0.083333333 | AF4: =100%/12 -> 0.083333333 | AG4: =100%/12 -> 0.083333333 | AH4: =100%/12 -> 0.083333333 | AI4: =100%/12 -> 0.083333333 | AJ4: =100%/12 -> 0.083333333 | ... AM4: =100%/12 -> 0.083333333 | AN4: =100%-SUM(AC4:AM4) -> 0.083333333 | AO4: =SUM(AC4:AN4) -> 1 | AP4: =100%/12 -> 0.083333333 | AQ4: =100%/12 -> 0.083333333 | AR4: =100%/12 -> 0.083333333 | AS4: =100%/12 -> 0.083333333 | AT4: =100%/12 -> 0.083333333 | AU4: =100%/12 -> 0.083333333 | AV4: =100%/12 -> 0.083333333 | AW4: =100%/12 -> 0.083333333 | ... AZ4: =100%/12 -> 0.083333333 | BA4: =100%-SUM(AP4:AZ4) -> 0.083333333 | BB4: =SUM(AP4:BA4) -> 1 | BC4: =100%/12 -> 0.083333333 | BD4: =100%/12 -> 0.083333333 | BE4: =100%/12 -> 0.083333333 | BF4: =100%/12 -> 0.083333333 | BG4: =100%/12 -> 0.083333333 | BH4: =100%/12 -> 0.083333333 | BI4: =100%/12 -> 0.083333333 | BJ4: =100%/12 -> 0.083333333 | ... BM4: =100%/12 -> 0.083333333 | BN4: =100%-SUM(BC4:BM4) -> 0.083333333 | BO4: =SUM(BC4:BN4) -> 1
A5: AR, % | C5: =O5 -> #REF! | D5: =O5 -> #REF! | E5: =O5 -> #REF! | F5: =O5 -> #REF! | G5: =O5 -> #REF! | H5: =O5 -> #REF! | I5: =O5 -> #REF! | J5: =O5 -> #REF! | K5: =O5 -> #REF! | L5: =O5 -> #REF! | M5: =O5 -> #REF! | N5: =O5 -> #REF! | O5: =#REF! -> #REF! | P5: =AB5 -> #REF! | Q5: =AB5 -> #REF! | R5: =AB5 -> #REF! | S5: =AB5 -> #REF! | T5: =AB5 -> #REF! | U5: =AB5 -> #REF! | V5: =AB5 -> #REF! | W5: =AB5 -> #REF! | X5: =AB5 -> #REF! | Y5: =AB5 -> #REF! | Z5: =AB5 -> #REF! | AA5: =AB5 -> #REF! | AB5: =#REF! -> #REF! | AC5: =AO5 -> #REF! | AD5: =AO5 -> #REF! | AE5: =AO5 -> #REF! | AF5: =AO5 -> #REF! | AG5: =AO5 -> #REF! | AH5: =AO5 -> #REF! | AI5: =AO5 -> #REF! | AJ5: =AO5 -> #REF! | AK5: =AO5 -> #REF! | AL5: =AO5 -> #REF! | AM5: =AO5 -> #REF! | AN5: =AO5 -> #REF! | AO5: =#REF! -> #REF! | AP5: =BB5 -> #REF! | AQ5: =BB5 -> #REF! | AR5: =BB5 -> #REF! | AS5: =BB5 -> #REF! | AT5: =BB5 -> #REF! | AU5: =BB5 -> #REF! | AV5: =BB5 -> #REF! | AW5: =BB5 -> #REF! | AX5: =BB5 -> #REF! | AY5: =BB5 -> #REF! | AZ5: =BB5 -> #REF! | BA5: =BB5 -> #REF! | BB5: =#REF! -> #REF! | BC5: =BO5 -> #REF! | BD5: =BO5 -> #REF! | BE5: =BO5 -> #REF! | BF5: =BO5 -> #REF! | BG5: =BO5 -> #REF! | BH5: =BO5 -> #REF! | BI5: =BO5 -> #REF! | BJ5: =BO5 -> #REF! | BK5: =BO5 -> #REF! | BL5: =BO5 -> #REF! | BM5: =BO5 -> #REF! | BN5: =BO5 -> #REF! | BO5: =#REF! -> #REF!
A6: Кол-во одобренных клиентов | C6: =C3*C5 -> #REF! | D6: =D3*D5 -> #REF! | E6: =E3*E5 -> #REF! | F6: =F3*F5 -> #REF! | G6: =G3*G5 -> #REF! | H6: =H3*H5 -> #REF! | I6: =I3*I5 -> #REF! | J6: =J3*J5 -> #REF! | ... N6: =N3*N5 -> #REF! | O6: =SUM(C6:N6) -> #REF! | P6: =P3*P5 -> #REF! | Q6: =Q3*Q5 -> #REF! | R6: =R3*R5 -> #REF! | S6: =S3*S5 -> #REF! | T6: =T3*T5 -> #REF! | U6: =U3*U5 -> #REF! | V6: =V3*V5 -> #REF! | W6: =W3*W5 -> #REF! | ... AA6: =AA3*AA5 -> #REF! | AB6: =SUM(P6:AA6) -> #REF! | AC6: =AC3*AC5 -> #REF! | AD6: =AD3*AD5 -> #REF! | AE6: =AE3*AE5 -> #REF! | AF6: =AF3*AF5 -> #REF! | AG6: =AG3*AG5 -> #REF! | AH6: =AH3*AH5 -> #REF! | AI6: =AI3*AI5 -> #REF! | AJ6: =AJ3*AJ5 -> #REF! | ... AN6: =AN3*AN5 -> #REF! | AO6: =SUM(AC6:AN6) -> #REF! | AP6: =AP3*AP5 -> #REF! | AQ6: =AQ3*AQ5 -> #REF! | AR6: =AR3*AR5 -> #REF! | AS6: =AS3*AS5 -> #REF! | AT6: =AT3*AT5 -> #REF! | AU6: =AU3*AU5 -> #REF! | AV6: =AV3*AV5 -> #REF! | AW6: =AW3*AW5 -> #REF! | ... BA6: =BA3*BA5 -> #REF! | BB6: =SUM(AP6:BA6) -> #REF! | BC6: =BC3*BC5 -> #REF! | BD6: =BD3*BD5 -> #REF! | BE6: =BE3*BE5 -> #REF! | BF6: =BF3*BF5 -> #REF! | BG6: =BG3*BG5 -> #REF! | BH6: =BH3*BH5 -> #REF! | BI6: =BI3*BI5 -> #REF! | BJ6: =BJ3*BJ5 -> #REF! | ... BN6: =BN3*BN5 -> #REF! | BO6: =SUM(BC6:BN6) -> #REF!
A7: Take up, % | C7: =O7 -> #REF! | D7: =O7 -> #REF! | E7: =O7 -> #REF! | F7: =O7 -> #REF! | G7: =O7 -> #REF! | H7: =O7 -> #REF! | I7: =O7 -> #REF! | J7: =O7 -> #REF! | K7: =O7 -> #REF! | L7: =O7 -> #REF! | M7: =O7 -> #REF! | N7: =O7 -> #REF! | O7: =#REF! -> #REF! | P7: =AB7 -> #REF! | Q7: =AB7 -> #REF! | R7: =AB7 -> #REF! | S7: =AB7 -> #REF! | T7: =AB7 -> #REF! | U7: =AB7 -> #REF! | V7: =AB7 -> #REF! | W7: =AB7 -> #REF! | X7: =AB7 -> #REF! | Y7: =AB7 -> #REF! | Z7: =AB7 -> #REF! | AA7: =AB7 -> #REF! | AB7: =#REF! -> #REF! | AC7: =AO7 -> #REF! | AD7: =AO7 -> #REF! | AE7: =AO7 -> #REF! | AF7: =AO7 -> #REF! | AG7: =AO7 -> #REF! | AH7: =AO7 -> #REF! | AI7: =AO7 -> #REF! | AJ7: =AO7 -> #REF! | AK7: =AO7 -> #REF! | AL7: =AO7 -> #REF! | AM7: =AO7 -> #REF! | AN7: =AO7 -> #REF! | AO7: =#REF! -> #REF! | AP7: =BB7 -> #REF! | AQ7: =BB7 -> #REF! | AR7: =BB7 -> #REF! | AS7: =BB7 -> #REF! | AT7: =BB7 -> #REF! | AU7: =BB7 -> #REF! | AV7: =BB7 -> #REF! | AW7: =BB7 -> #REF! | AX7: =BB7 -> #REF! | AY7: =BB7 -> #REF! | AZ7: =BB7 -> #REF! | BA7: =BB7 -> #REF! | BB7: =#REF! -> #REF! | BC7: =BO7 -> #REF! | BD7: =BO7 -> #REF! | BE7: =BO7 -> #REF! | BF7: =BO7 -> #REF! | BG7: =BO7 -> #REF! | BH7: =BO7 -> #REF! | BI7: =BO7 -> #REF! | BJ7: =BO7 -> #REF! | BK7: =BO7 -> #REF! | BL7: =BO7 -> #REF! | BM7: =BO7 -> #REF! | BN7: =BO7 -> #REF! | BO7: =#REF! -> #REF!
A8: Кол-во клиентов, согласившихся на кредит | C8: =C6*C7 -> #REF! | D8: =D6*D7 -> #REF! | E8: =E6*E7 -> #REF! | F8: =F6*F7 -> #REF! | G8: =G6*G7 -> #REF! | H8: =H6*H7 -> #REF! | I8: =I6*I7 -> #REF! | J8: =J6*J7 -> #REF! | ... N8: =N6*N7 -> #REF! | O8: =SUM(C8:N8) -> #REF! | P8: =P6*P7 -> #REF! | Q8: =Q6*Q7 -> #REF! | R8: =R6*R7 -> #REF! | S8: =S6*S7 -> #REF! | T8: =T6*T7 -> #REF! | U8: =U6*U7 -> #REF! | V8: =V6*V7 -> #REF! | W8: =W6*W7 -> #REF! | ... AA8: =AA6*AA7 -> #REF! | AB8: =SUM(P8:AA8) -> #REF! | AC8: =AC6*AC7 -> #REF! | AD8: =AD6*AD7 -> #REF! | AE8: =AE6*AE7 -> #REF! | AF8: =AF6*AF7 -> #REF! | AG8: =AG6*AG7 -> #REF! | AH8: =AH6*AH7 -> #REF! | AI8: =AI6*AI7 -> #REF! | AJ8: =AJ6*AJ7 -> #REF! | ... AN8: =AN6*AN7 -> #REF! | AO8: =SUM(AC8:AN8) -> #REF! | AP8: =AP6*AP7 -> #REF! | AQ8: =AQ6*AQ7 -> #REF! | AR8: =AR6*AR7 -> #REF! | AS8: =AS6*AS7 -> #REF! | AT8: =AT6*AT7 -> #REF! | AU8: =AU6*AU7 -> #REF! | AV8: =AV6*AV7 -> #REF! | AW8: =AW6*AW7 -> #REF! | ... BA8: =BA6*BA7 -> #REF! | BB8: =SUM(AP8:BA8) -> #REF! | BC8: =BC6*BC7 -> #REF! | BD8: =BD6*BD7 -> #REF! | BE8: =BE6*BE7 -> #REF! | BF8: =BF6*BF7 -> #REF! | BG8: =BG6*BG7 -> #REF! | BH8: =BH6*BH7 -> #REF! | BI8: =BI6*BI7 -> #REF! | BJ8: =BJ6*BJ7 -> #REF! | ... BN8: =BN6*BN7 -> #REF! | BO8: =SUM(BC8:BN8) -> #REF!
A9: Средний чек займа, тенге | C9: =O9 -> #REF! | D9: =O9 -> #REF! | E9: =O9 -> #REF! | F9: =O9 -> #REF! | G9: =O9 -> #REF! | H9: =O9 -> #REF! | I9: =O9 -> #REF! | J9: =O9 -> #REF! | K9: =O9 -> #REF! | L9: =O9 -> #REF! | M9: =O9 -> #REF! | N9: =O9 -> #REF! | O9: =#REF! -> #REF! | P9: =AB9 -> #REF! | Q9: =AB9 -> #REF! | R9: =AB9 -> #REF! | S9: =AB9 -> #REF! | T9: =AB9 -> #REF! | U9: =AB9 -> #REF! | V9: =AB9 -> #REF! | W9: =AB9 -> #REF! | X9: =AB9 -> #REF! | Y9: =AB9 -> #REF! | Z9: =AB9 -> #REF! | AA9: =AB9 -> #REF! | AB9: =#REF! -> #REF! | AC9: =AO9 -> #REF! | AD9: =AO9 -> #REF! | AE9: =AO9 -> #REF! | AF9: =AO9 -> #REF! | AG9: =AO9 -> #REF! | AH9: =AO9 -> #REF! | AI9: =AO9 -> #REF! | AJ9: =AO9 -> #REF! | AK9: =AO9 -> #REF! | AL9: =AO9 -> #REF! | AM9: =AO9 -> #REF! | AN9: =AO9 -> #REF! | AO9: =#REF! -> #REF! | AP9: =BB9 -> #REF! | AQ9: =BB9 -> #REF! | AR9: =BB9 -> #REF! | AS9: =BB9 -> #REF! | AT9: =BB9 -> #REF! | AU9: =BB9 -> #REF! | AV9: =BB9 -> #REF! | AW9: =BB9 -> #REF! | AX9: =BB9 -> #REF! | AY9: =BB9 -> #REF! | AZ9: =BB9 -> #REF! | BA9: =BB9 -> #REF! | BB9: =#REF! -> #REF! | BC9: =BO9 -> #REF! | BD9: =BO9 -> #REF! | BE9: =BO9 -> #REF! | BF9: =BO9 -> #REF! | BG9: =BO9 -> #REF! | BH9: =BO9 -> #REF! | BI9: =BO9 -> #REF! | BJ9: =BO9 -> #REF! | BK9: =BO9 -> #REF! | BL9: =BO9 -> #REF! | BM9: =BO9 -> #REF! | BN9: =BO9 -> #REF! | BO9: =#REF! -> #REF!
A10: Выдачи, млн тенге | C10: =C8*C9/1000000 -> #REF! | D10: =D8*D9/1000000 -> #REF! | E10: =E8*E9/1000000 -> #REF! | F10: =F8*F9/1000000 -> #REF! | G10: =G8*G9/1000000 -> #REF! | H10: =H8*H9/1000000 -> #REF! | I10: =I8*I9/1000000 -> #REF! | J10: =J8*J9/1000000 -> #REF! | ... N10: =N8*N9/1000000 -> #REF! | O10: =SUM(C10:N10) -> #REF! | P10: =P8*P9/1000000 -> #REF! | Q10: =Q8*Q9/1000000 -> #REF! | R10: =R8*R9/1000000 -> #REF! | S10: =S8*S9/1000000 -> #REF! | T10: =T8*T9/1000000 -> #REF! | U10: =U8*U9/1000000 -> #REF! | V10: =V8*V9/1000000 -> #REF! | W10: =W8*W9/1000000 -> #REF! | ... AA10: =AA8*AA9/1000000 -> #REF! | AB10: =SUM(P10:AA10) -> #REF! | AC10: =AC8*AC9/1000000 -> #REF! | AD10: =AD8*AD9/1000000 -> #REF! | AE10: =AE8*AE9/1000000 -> #REF! | AF10: =AF8*AF9/1000000 -> #REF! | AG10: =AG8*AG9/1000000 -> #REF! | AH10: =AH8*AH9/1000000 -> #REF! | AI10: =AI8*AI9/1000000 -> #REF! | AJ10: =AJ8*AJ9/1000000 -> #REF! | ... AN10: =AN8*AN9/1000000 -> #REF! | AO10: =SUM(AC10:AN10) -> #REF! | AP10: =AP8*AP9/1000000 -> #REF! | AQ10: =AQ8*AQ9/1000000 -> #REF! | AR10: =AR8*AR9/1000000 -> #REF! | AS10: =AS8*AS9/1000000 -> #REF! | AT10: =AT8*AT9/1000000 -> #REF! | AU10: =AU8*AU9/1000000 -> #REF! | AV10: =AV8*AV9/1000000 -> #REF! | AW10: =AW8*AW9/1000000 -> #REF! | ... BA10: =BA8*BA9/1000000 -> #REF! | BB10: =SUM(AP10:BA10) -> #REF! | BC10: =BC8*BC9/1000000 -> #REF! | BD10: =BD8*BD9/1000000 -> #REF! | BE10: =BE8*BE9/1000000 -> #REF! | BF10: =BF8*BF9/1000000 -> #REF! | BG10: =BG8*BG9/1000000 -> #REF! | BH10: =BH8*BH9/1000000 -> #REF! | BI10: =BI8*BI9/1000000 -> #REF! | BJ10: =BJ8*BJ9/1000000 -> #REF! | ... BN10: =BN8*BN9/1000000 -> #REF! | BO10: =SUM(BC10:BN10) -> #REF!
A11: Коэффициент погашения | C11: =O11 -> -0.04 | D11: =O11 -> -0.04 | E11: =O11 -> -0.04 | F11: =O11 -> -0.04 | G11: =O11 -> -0.04 | H11: =O11 -> -0.04 | I11: =O11 -> -0.04 | J11: =O11 -> -0.04 | K11: =O11 -> -0.04 | L11: =O11 -> -0.04 | M11: =O11 -> -0.04 | N11: =O11 -> -0.04 | O11: -0.04 | P11: =AB11 -> -0.04 | Q11: =AB11 -> -0.04 | R11: =AB11 -> -0.04 | S11: =AB11 -> -0.04 | T11: =AB11 -> -0.04 | U11: =AB11 -> -0.04 | V11: =AB11 -> -0.04 | W11: =AB11 -> -0.04 | X11: =AB11 -> -0.04 | Y11: =AB11 -> -0.04 | Z11: =AB11 -> -0.04 | AA11: =AB11 -> -0.04 | AB11: -0.04 | AC11: =AO11 -> -0.04 | AD11: =AO11 -> -0.04 | AE11: =AO11 -> -0.04 | AF11: =AO11 -> -0.04 | AG11: =AO11 -> -0.04 | AH11: =AO11 -> -0.04 | AI11: =AO11 -> -0.04 | AJ11: =AO11 -> -0.04 | AK11: =AO11 -> -0.04 | AL11: =AO11 -> -0.04 | AM11: =AO11 -> -0.04 | AN11: =AO11 -> -0.04 | AO11: -0.04 | AP11: =BB11 -> -0.04 | AQ11: =BB11 -> -0.04 | AR11: =BB11 -> -0.04 | AS11: =BB11 -> -0.04 | AT11: =BB11 -> -0.04 | AU11: =BB11 -> -0.04 | AV11: =BB11 -> -0.04 | AW11: =BB11 -> -0.04 | AX11: =BB11 -> -0.04 | AY11: =BB11 -> -0.04 | AZ11: =BB11 -> -0.04 | BA11: =BB11 -> -0.04 | BB11: -0.04 | BC11: =BO11 -> -0.04 | BD11: =BO11 -> -0.04 | BE11: =BO11 -> -0.04 | BF11: =BO11 -> -0.04 | BG11: =BO11 -> -0.04 | BH11: =BO11 -> -0.04 | BI11: =BO11 -> -0.04 | BJ11: =BO11 -> -0.04 | BK11: =BO11 -> -0.04 | BL11: =BO11 -> -0.04 | BM11: =BO11 -> -0.04 | BN11: =BO11 -> -0.04 | BO11: -0.04
A12: Погашения | D12: =C14*D11 -> #REF! | E12: =D14*E11 -> #REF! | F12: =E14*F11 -> #REF! | G12: =F14*G11 -> #REF! | H12: =G14*H11 -> #REF! | I12: =H14*I11 -> #REF! | J12: =I14*J11 -> #REF! | K12: =J14*K11 -> #REF! | ... N12: =M14*N11 -> #REF! | O12: =SUM(C12:N12) -> #REF! | Q12: =P14*Q11 -> #REF! | R12: =Q14*R11 -> #REF! | S12: =R14*S11 -> #REF! | T12: =S14*T11 -> #REF! | U12: =T14*U11 -> #REF! | V12: =U14*V11 -> #REF! | W12: =V14*W11 -> #REF! | X12: =W14*X11 -> #REF! | ... AA12: =Z14*AA11 -> #REF! | AB12: =SUM(P12:AA12) -> #REF! | AD12: =AC14*AD11 -> #REF! | AE12: =AD14*AE11 -> #REF! | AF12: =AE14*AF11 -> #REF! | AG12: =AF14*AG11 -> #REF! | AH12: =AG14*AH11 -> #REF! | AI12: =AH14*AI11 -> #REF! | AJ12: =AI14*AJ11 -> #REF! | AK12: =AJ14*AK11 -> #REF! | ... AN12: =AM14*AN11 -> #REF! | AO12: =SUM(AC12:AN12) -> #REF! | AQ12: =AP14*AQ11 -> #REF! | AR12: =AQ14*AR11 -> #REF! | AS12: =AR14*AS11 -> #REF! | AT12: =AS14*AT11 -> #REF! | AU12: =AT14*AU11 -> #REF! | AV12: =AU14*AV11 -> #REF! | AW12: =AV14*AW11 -> #REF! | AX12: =AW14*AX11 -> #REF! | ... BA12: =AZ14*BA11 -> #REF! | BB12: =SUM(AP12:BA12) -> #REF! | BD12: =BC14*BD11 -> #REF! | BE12: =BD14*BE11 -> #REF! | BF12: =BE14*BF11 -> #REF! | BG12: =BF14*BG11 -> #REF! | BH12: =BG14*BH11 -> #REF! | BI12: =BH14*BI11 -> #REF! | BJ12: =BI14*BJ11 -> #REF! | BK12: =BJ14*BK11 -> #REF! | ... BN12: =BM14*BN11 -> #REF! | BO12: =SUM(BC12:BN12) -> #REF!
A13: Списания | O13: =N13 -> 0 | AB13: =AA13 -> 0 | AO13: =AN13 -> 0 | BB13: =BA13 -> 0 | BO13: =BN13 -> 0
A14: Кредитный порфтель | C14: =C10+C12+C13 -> #REF! | D14: =C14+D10+D12+D13 -> #REF! | E14: =D14+E10+E12+E13 -> #REF! | F14: =E14+F10+F12+F13 -> #REF! | G14: =F14+G10+G12+G13 -> #REF! | H14: =G14+H10+H12+H13 -> #REF! | I14: =H14+I10+I12+I13 -> #REF! | J14: =I14+J10+J12+J13 -> #REF! | K14: =J14+K10+K12+K13 -> #REF! | ... N14: =M14+N10+N12+N13 -> #REF! | O14: =N14 -> #REF! | P14: =P10+P12+P13 -> #REF! | Q14: =P14+Q10+Q12+Q13 -> #REF! | R14: =Q14+R10+R12+R13 -> #REF! | S14: =R14+S10+S12+S13 -> #REF! | T14: =S14+T10+T12+T13 -> #REF! | U14: =T14+U10+U12+U13 -> #REF! | V14: =U14+V10+V12+V13 -> #REF! | W14: =V14+W10+W12+W13 -> #REF! | X14: =W14+X10+X12+X13 -> #REF! | ... AA14: =Z14+AA10+AA12+AA13 -> #REF! | AB14: =AA14 -> #REF! | AC14: =AC10+AC12+AC13 -> #REF! | AD14: =AC14+AD10+AD12+AD13 -> #REF! | AE14: =AD14+AE10+AE12+AE13 -> #REF! | AF14: =AE14+AF10+AF12+AF13 -> #REF! | AG14: =AF14+AG10+AG12+AG13 -> #REF! | AH14: =AG14+AH10+AH12+AH13 -> #REF! | AI14: =AH14+AI10+AI12+AI13 -> #REF! | AJ14: =AI14+AJ10+AJ12+AJ13 -> #REF! | AK14: =AJ14+AK10+AK12+AK13 -> #REF! | ... AN14: =AM14+AN10+AN12+AN13 -> #REF! | AO14: =AN14 -> #REF! | AP14: =AP10+AP12+AP13 -> #REF! | AQ14: =AP14+AQ10+AQ12+AQ13 -> #REF! | AR14: =AQ14+AR10+AR12+AR13 -> #REF! | AS14: =AR14+AS10+AS12+AS13 -> #REF! | AT14: =AS14+AT10+AT12+AT13 -> #REF! | AU14: =AT14+AU10+AU12+AU13 -> #REF! | AV14: =AU14+AV10+AV12+AV13 -> #REF! | AW14: =AV14+AW10+AW12+AW13 -> #REF! | AX14: =AW14+AX10+AX12+AX13 -> #REF! | ... BA14: =AZ14+BA10+BA12+BA13 -> #REF! | BB14: =BA14 -> #REF! | BC14: =BC10+BC12+BC13 -> #REF! | BD14: =BC14+BD10+BD12+BD13 -> #REF! | BE14: =BD14+BE10+BE12+BE13 -> #REF! | BF14: =BE14+BF10+BF12+BF13 -> #REF! | BG14: =BF14+BG10+BG12+BG13 -> #REF! | BH14: =BG14+BH10+BH12+BH13 -> #REF! | BI14: =BH14+BI10+BI12+BI13 -> #REF! | BJ14: =BI14+BJ10+BJ12+BJ13 -> #REF! | BK14: =BJ14+BK10+BK12+BK13 -> #REF! | ... BN14: =BM14+BN10+BN12+BN13 -> #REF! | BO14: =BN14 -> #REF!
A15: Процентная ставка
A18: Уровень PD
A19: CoR
A20: Стоимость ресурсов

Sheet Лист4
C1: 1 мес | D1: 2 мес | E1: 3 мес | F1: 4 мес | G1: 5 мес | H1: 6 мес | I1: 7 мес | J1: 8 мес | K1: 9 мес | L1: 10 мес | M1: 11 мес | N1: 12 мес | O1: 1 год | P1: 1 мес | Q1: 2 мес | R1: 3 мес | S1: 4 мес | T1: 5 мес | U1: 6 мес | V1: 7 мес | W1: 8 мес | X1: 9 мес | Y1: 10 мес | Z1: 11 мес | AA1: 12 мес | AB1: 2 год | AC1: 1 мес | AD1: 2 мес | AE1: 3 мес | AF1: 4 мес | AG1: 5 мес | AH1: 6 мес | AI1: 7 мес | AJ1: 8 мес | AK1: 9 мес | AL1: 10 мес | AM1: 11 мес | AN1: 12 мес | AO1: 3 год | AP1: 1 мес | AQ1: 2 мес | AR1: 3 мес | AS1: 4 мес | AT1: 5 мес | AU1: 6 мес | AV1: 7 мес | AW1: 8 мес | AX1: 9 мес | AY1: 10 мес | AZ1: 11 мес | BA1: 12 мес | BB1: 4 год | BC1: 1 мес | BD1: 2 мес | BE1: 3 мес | BF1: 4 мес | BG1: 5 мес | BH1: 6 мес | BI1: 7 мес | BJ1: 8 мес | BK1: 9 мес | BL1: 10 мес | BM1: 11 мес | BN1: 12 мес | BO1: 5 год
A3: Кол-во клиентов, согласившихся на пакет | C3: =B3+C4 -> #REF! | D3: =C3+D4 -> #REF! | E3: =D3+E4 -> #REF! | F3: =E3+F4 -> #REF! | G3: =F3+G4 -> #REF! | H3: =G3+H4 -> #REF! | I3: =H3+I4 -> #REF! | J3: =I3+J4 -> #REF! | ... N3: =M3+N4 -> #REF! | O3: =#REF! -> #REF! | P3: =O3+P4 -> #REF! | Q3: =P3+Q4 -> #REF! | R3: =Q3+R4 -> #REF! | S3: =R3+S4 -> #REF! | T3: =S3+T4 -> #REF! | U3: =T3+U4 -> #REF! | V3: =U3+V4 -> #REF! | W3: =V3+W4 -> #REF! | ... AA3: =Z3+AA4 -> #REF! | AB3: =#REF! -> #REF! | AC3: =AB3+AC4 -> #REF! | AD3: =AC3+AD4 -> #REF! | AE3: =AD3+AE4 -> #REF! | AF3: =AE3+AF4 -> #REF! | AG3: =AF3+AG4 -> #REF! | AH3: =AG3+AH4 -> #REF! | AI3: =AH3+AI4 -> #REF! | AJ3: =AI3+AJ4 -> #REF! | ... AN3: =AM3+AN4 -> #REF! | AO3: =#REF! -> #REF! | AP3: =AO3+AP4 -> #REF! | AQ3: =AP3+AQ4 -> #REF! | AR3: =AQ3+AR4 -> #REF! | AS3: =AR3+AS4 -> #REF! | AT3: =AS3+AT4 -> #REF! | AU3: =AT3+AU4 -> #REF! | AV3: =AU3+AV4 -> #REF! | AW3: =AV3+AW4 -> #REF! | ... BA3: =AZ3+BA4 -> #REF! | BB3: =#REF! -> #REF! | BC3: =BB3+BC4 -> #REF! | BD3: =BC3+BD4 -> #REF! | BE3: =BD3+BE4 -> #REF! | BF3: =BE3+BF4 -> #REF! | BG3: =BF3+BG4 -> #REF! | BH3: =BG3+BH4 -> #REF! | BI3: =BH3+BI4 -> #REF! | BJ3: =BI3+BJ4 -> #REF! | ... BN3: =BM3+BN4 -> #REF! | BO3: =#REF! -> #REF!
A4: Прирост клиентов | C4: =O4*C5 -> #REF! | D4: =O4*D5 -> #REF! | E4: =O4*E5 -> #REF! | F4: =O4*F5 -> #REF! | G4: =O4*G5 -> #REF! | H4: =O4*H5 -> #REF! | I4: =O4*I5 -> #REF! | J4: =O4*J5 -> #REF! | K4: =O4*K5 -> #REF! | L4: =O4*L5 -> #REF! | M4: =O4*M5 -> #REF! | N4: =O4*N5 -> #REF! | O4: =O3-B3 -> #REF! | P4: =AB4*P5 -> #REF! | Q4: =AB4*Q5 -> #REF! | R4: =AB4*R5 -> #REF! | S4: =AB4*S5 -> #REF! | T4: =AB4*T5 -> #REF! | U4: =AB4*U5 -> #REF! | V4: =AB4*V5 -> #REF! | W4: =AB4*W5 -> #REF! | X4: =AB4*X5 -> #REF! | Y4: =AB4*Y5 -> #REF! | Z4: =AB4*Z5 -> #REF! | AA4: =AB4*AA5 -> #REF! | AB4: =AB3-O3 -> #REF! | AC4: =AO4*AC5 -> #REF! | AD4: =AO4*AD5 -> #REF! | AE4: =AO4*AE5 -> #REF! | AF4: =AO4*AF5 -> #REF! | AG4: =AO4*AG5 -> #REF! | AH4: =AO4*AH5 -> #REF! | AI4: =AO4*AI5 -> #REF! | AJ4: =AO4*AJ5 -> #REF! | AK4: =AO4*AK5 -> #REF! | AL4: =AO4*AL5 -> #REF! | AM4: =AO4*AM5 -> #REF! | AN4: =AO4*AN5 -> #REF! | AO4: =AO3-AB3 -> #REF! | AP4: =BB4*AP5 -> #REF! | AQ4: =BB4*AQ5 -> #REF! | AR4: =BB4*AR5 -> #REF! | AS4: =BB4*AS5 -> #REF! | AT4: =BB4*AT5 -> #REF! | AU4: =BB4*AU5 -> #REF! | AV4: =BB4*AV5 -> #REF! | AW4: =BB4*AW5 -> #REF! | AX4: =BB4*AX5 -> #REF! | AY4: =BB4*AY5 -> #REF! | AZ4: =BB4*AZ5 -> #REF! | BA4: =BB4*BA5 -> #REF! | BB4: =BB3-AO3 -> #REF! | BC4: =BO4*BC5 -> #REF! | BD4: =BO4*BD5 -> #REF! | BE4: =BO4*BE5 -> #REF! | BF4: =BO4*BF5 -> #REF! | BG4: =BO4*BG5 -> #REF! | BH4: =BO4*BH5 -> #REF! | BI4: =BO4*BI5 -> #REF! | BJ4: =BO4*BJ5 -> #REF! | BK4: =BO4*BK5 -> #REF! | BL4: =BO4*BL5 -> #REF! | BM4: =BO4*BM5 -> #REF! | BN4: =BO4*BN5 -> #REF! | BO4: =BO3-BB3 -> #REF!
A5: сезонность | C5: =100%/12 -> 0.083333333 | D5: =100%/12 -> 0.083333333 | E5: =100%/12 -> 0.083333333 | F5: =100%/12 -> 0.083333333 | G5: =100%/12 -> 0.083333333 | H5: =100%/12 -> 0.083333333 | I5: =100%/12 -> 0.083333333 | J5: =100%/12 -> 0.083333333 | ... M5: =100%/12 -> 0.083333333 | N5: =100%-SUM(C5:M5) -> 0.083333333 | O5: =SUM(C5:N5) -> 1 | P5: =100%/12 -> 0.083333333 | Q5: =100%/12 -> 0.083333333 | R5: =100%/12 -> 0.083333333 | S5: =100%/12 -> 0.083333333 | T5: =100%/12 -> 0.083333333 | U5: =100%/12 -> 0.083333333 | V5: =100%/12 -> 0.083333333 | W5: =100%/12 -> 0.083333333 | ... Z5: =100%/12 -> 0.083333333 | AA5: =100%-SUM(P5:Z5) -> 0.083333333 | AB5: =SUM(P5:AA5) -> 1 | AC5: =100%/12 -> 0.083333333 | AD5: =100%/12 -> 0.083333333 | AE5: =100%/12 -> 0.083333333 | AF5: =100%/12 -> 0.083333333 | AG5: =100%/12 -> 0.083333333 | AH5: =100%/12 -> 0.083333333 | AI5: =100%/12 -> 0.083333333 | AJ5: =100%/12 -> 0.083333333 | ... AM5: =100%/12 -> 0.083333333 | AN5: =100%-SUM(AC5:AM5) -> 0.083333333 | AO5: =SUM(AC5:AN5) -> 1 | AP5: =100%/12 -> 0.083333333 | AQ5: =100%/12 -> 0.083333333 | AR5: =100%/12 -> 0.083333333 | AS5: =100%/12 -> 0.083333333 | AT5: =100%/12 -> 0.083333333 | AU5: =100%/12 -> 0.083333333 | AV5: =100%/12 -> 0.083333333 | AW5: =100%/12 -> 0.083333333 | ... AZ5: =100%/12 -> 0.083333333 | BA5: =100%-SUM(AP5:AZ5) -> 0.083333333 | BB5: =SUM(AP5:BA5) -> 1 | BC5: =100%/12 -> 0.083333333 | BD5: =100%/12 -> 0.083333333 | BE5: =100%/12 -> 0.083333333 | BF5: =100%/12 -> 0.083333333 | BG5: =100%/12 -> 0.083333333 | BH5: =100%/12 -> 0.083333333 | BI5: =100%/12 -> 0.083333333 | BJ5: =100%/12 -> 0.083333333 | ... BM5: =100%/12 -> 0.083333333 | BN5: =100%-SUM(BC5:BM5) -> 0.083333333 | BO5: =SUM(BC5:BN5) -> 1
A6: Средний чек лимита для пакета, тенге | C6: =O6 -> #REF! | D6: =O6 -> #REF! | E6: =O6 -> #REF! | F6: =O6 -> #REF! | G6: =O6 -> #REF! | H6: =O6 -> #REF! | I6: =O6 -> #REF! | J6: =O6 -> #REF! | K6: =O6 -> #REF! | L6: =O6 -> #REF! | M6: =O6 -> #REF! | N6: =O6 -> #REF! | O6: =#REF! -> #REF! | P6: =AB6 -> #REF! | Q6: =AB6 -> #REF! | R6: =AB6 -> #REF! | S6: =AB6 -> #REF! | T6: =AB6 -> #REF! | U6: =AB6 -> #REF! | V6: =AB6 -> #REF! | W6: =AB6 -> #REF! | X6: =AB6 -> #REF! | Y6: =AB6 -> #REF! | Z6: =AB6 -> #REF! | AA6: =AB6 -> #REF! | AB6: =#REF! -> #REF! | AC6: =AO6 -> #REF! | AD6: =AO6 -> #REF! | AE6: =AO6 -> #REF! | AF6: =AO6 -> #REF! | AG6: =AO6 -> #REF! | AH6: =AO6 -> #REF! | AI6: =AO6 -> #REF! | AJ6: =AO6 -> #REF! | AK6: =AO6 -> #REF! | AL6: =AO6 -> #REF! | AM6: =AO6 -> #REF! | AN6: =AO6 -> #REF! | AO6: =#REF! -> #REF! | AP6: =BB6 -> #REF! | AQ6: =BB6 -> #REF! | AR6: =BB6 -> #REF! | AS6: =BB6 -> #REF! | AT6: =BB6 -> #REF! | AU6: =BB6 -> #REF! | AV6: =BB6 -> #REF! | AW6: =BB6 -> #REF! | AX6: =BB6 -> #REF! | AY6: =BB6 -> #REF! | AZ6: =BB6 -> #REF! | BA6: =BB6 -> #REF! | BB6: =#REF! -> #REF! | BC6: =BO6 -> #REF! | BD6: =BO6 -> #REF! | BE6: =BO6 -> #REF! | BF6: =BO6 -> #REF! | BG6: =BO6 -> #REF! | BH6: =BO6 -> #REF! | BI6: =BO6 -> #REF! | BJ6: =BO6 -> #REF! | BK6: =BO6 -> #REF! | BL6: =BO6 -> #REF! | BM6: =BO6 -> #REF! | BN6: =BO6 -> #REF! | BO6: =#REF! -> #REF!
A7: Сумма установленного кредитного лимита, млн.тенге | C7: =C3*C6/1000000 -> #REF! | D7: =D3*D6/1000000 -> #REF! | E7: =E3*E6/1000000 -> #REF! | F7: =F3*F6/1000000 -> #REF! | G7: =G3*G6/1000000 -> #REF! | H7: =H3*H6/1000000 -> #REF! | I7: =I3*I6/1000000 -> #REF! | J7: =J3*J6/1000000 -> #REF! | ... BO7: =BO3*BO6/1000000 -> #REF!
A8: % клиентов, которые пользуются пакетом | C8: =O8 -> #REF! | D8: =O8 -> #REF! | E8: =O8 -> #REF! | F8: =O8 -> #REF! | G8: =O8 -> #REF! | H8: =O8 -> #REF! | I8: =O8 -> #REF! | J8: =O8 -> #REF! | K8: =O8 -> #REF! | L8: =O8 -> #REF! | M8: =O8 -> #REF! | N8: =O8 -> #REF! | O8: =#REF! -> #REF! | P8: =AB8 -> #REF! | Q8: =AB8 -> #REF! | R8: =AB8 -> #REF! | S8: =AB8 -> #REF! | T8: =AB8 -> #REF! | U8: =AB8 -> #REF! | V8: =AB8 -> #REF! | W8: =AB8 -> #REF! | X8: =AB8 -> #REF! | Y8: =AB8 -> #REF! | Z8: =AB8 -> #REF! | AA8: =AB8 -> #REF! | AB8: =#REF! -> #REF! | AC8: =AO8 -> #REF! | AD8: =AO8 -> #REF! | AE8: =AO8 -> #REF! | AF8: =AO8 -> #REF! | AG8: =AO8 -> #REF! | AH8: =AO8 -> #REF! | AI8: =AO8 -> #REF! | AJ8: =AO8 -> #REF! | AK8: =AO8 -> #REF! | AL8: =AO8 -> #REF! | AM8: =AO8 -> #REF! | AN8: =AO8 -> #REF! | AO8: =#REF! -> #REF! | AP8: =BB8 -> #REF! | AQ8: =BB8 -> #REF! | AR8: =BB8 -> #REF! | AS8: =BB8 -> #REF! | AT8: =BB8 -> #REF! | AU8: =BB8 -> #REF! | AV8: =BB8 -> #REF! | AW8: =BB8 -> #REF! | AX8: =BB8 -> #REF! | AY8: =BB8 -> #REF! | AZ8: =BB8 -> #REF! | BA8: =BB8 -> #REF! | BB8: =#REF! -> #REF! | BC8: =BO8 -> #REF! | BD8: =BO8 -> #REF! | BE8: =BO8 -> #REF! | BF8: =BO8 -> #REF! | BG8: =BO8 -> #REF! | BH8: =BO8 -> #REF! | BI8: =BO8 -> #REF! | BJ8: =BO8 -> #REF! | BK8: =BO8 -> #REF! | BL8: =BO8 -> #REF! | BM8: =BO8 -> #REF! | BN8: =BO8 -> #REF! | BO8: =#REF! -> #REF!
A9: Кол-во клиентов, использующих пакет (с загрузкой лимита и оплачивающих пакет) | C9: =C3*C8 -> #REF! | D9: =D3*D8 -> #REF! | E9: =E3*E8 -> #REF! | F9: =F3*F8 -> #REF! | G9: =G3*G8 -> #REF! | H9: =H3*H8 -> #REF! | I9: =I3*I8 -> #REF! | J9: =J3*J8 -> #REF! | ... BO9: =BO3*BO8 -> #REF!
A10: % загрузки лимита у клиентов, которые используют пакет (важна в связи с резервами) | C10: =O10 -> #REF! | D10: =O10 -> #REF! | E10: =O10 -> #REF! | F10: =O10 -> #REF! | G10: =O10 -> #REF! | H10: =O10 -> #REF! | I10: =O10 -> #REF! | J10: =O10 -> #REF! | K10: =O10 -> #REF! | L10: =O10 -> #REF! | M10: =O10 -> #REF! | N10: =O10 -> #REF! | O10: =#REF! -> #REF! | P10: =AB10 -> #REF! | Q10: =AB10 -> #REF! | R10: =AB10 -> #REF! | S10: =AB10 -> #REF! | T10: =AB10 -> #REF! | U10: =AB10 -> #REF! | V10: =AB10 -> #REF! | W10: =AB10 -> #REF! | X10: =AB10 -> #REF! | Y10: =AB10 -> #REF! | Z10: =AB10 -> #REF! | AA10: =AB10 -> #REF! | AB10: =#REF! -> #REF! | AC10: =AO10 -> #REF! | AD10: =AO10 -> #REF! | AE10: =AO10 -> #REF! | AF10: =AO10 -> #REF! | AG10: =AO10 -> #REF! | AH10: =AO10 -> #REF! | AI10: =AO10 -> #REF! | AJ10: =AO10 -> #REF! | AK10: =AO10 -> #REF! | AL10: =AO10 -> #REF! | AM10: =AO10 -> #REF! | AN10: =AO10 -> #REF! | AO10: =#REF! -> #REF! | AP10: =BB10 -> #REF! | AQ10: =BB10 -> #REF! | AR10: =BB10 -> #REF! | AS10: =BB10 -> #REF! | AT10: =BB10 -> #REF! | AU10: =BB10 -> #REF! | AV10: =BB10 -> #REF! | AW10: =BB10 -> #REF! | AX10: =BB10 -> #REF! | AY10: =BB10 -> #REF! | AZ10: =BB10 -> #REF! | BA10: =BB10 -> #REF! | BB10: =#REF! -> #REF! | BC10: =BO10 -> #REF! | BD10: =BO10 -> #REF! | BE10: =BO10 -> #REF! | BF10: =BO10 -> #REF! | BG10: =BO10 -> #REF! | BH10: =BO10 -> #REF! | BI10: =BO10 -> #REF! | BJ10: =BO10 -> #REF! | BK10: =BO10 -> #REF! | BL10: =BO10 -> #REF! | BM10: =BO10 -> #REF! | BN10: =BO10 -> #REF! | BO10: =#REF! -> #REF!
A11: Сумма загруженного кредитного лимита, млн тенге (это кредитный портфель на дату - по годам не складывать) | C11: =C7*C10 -> #REF! | D11: =D7*D10 -> #REF! | E11: =E7*E10 -> #REF! | F11: =F7*F10 -> #REF! | G11: =G7*G10 -> #REF! | H11: =H7*H10 -> #REF! | I11: =I7*I10 -> #REF! | J11: =J7*J10 -> #REF! | ... BO11: =BO7*BO10 -> #REF!
A12: Средний чек загрузки лимита, тенге | C12: =C11*1000000/C9 -> #REF! | D12: =D11*1000000/D9 -> #REF! | E12: =E11*1000000/E9 -> #REF! | F12: =F11*1000000/F9 -> #REF! | G12: =G11*1000000/G9 -> #REF! | H12: =H11*1000000/H9 -> #REF! | I12: =I11*1000000/I9 -> #REF! | J12: =J11*1000000/J9 -> #REF! | ... BO12: =BO11*1000000/BO9 -> #REF!
A13: Обороты использования лимитов за период, млн тенге | C13: =C7*C8 -> #REF! | D13: =D7*D8 -> #REF! | E13: =E7*E8 -> #REF! | F13: =F7*F8 -> #REF! | G13: =G7*G8 -> #REF! | H13: =H7*H8 -> #REF! | I13: =I7*I8 -> #REF! | J13: =J7*J8 -> #REF! | ... N13: =N7*N8 -> #REF! | O13: =SUM(C13:N13) -> #REF! | P13: =P7*P8 -> #REF! | Q13: =Q7*Q8 -> #REF! | R13: =R7*R8 -> #REF! | S13: =S7*S8 -> #REF! | T13: =T7*T8 -> #REF! | U13: =U7*U8 -> #REF! | V13: =V7*V8 -> #REF! | W13: =W7*W8 -> #REF! | ... AA13: =AA7*AA8 -> #REF! | AB13: =SUM(P13:AA13) -> #REF! | AC13: =AC7*AC8 -> #REF! | AD13: =AD7*AD8 -> #REF! | AE13: =AE7*AE8 -> #REF! | AF13: =AF7*AF8 -> #REF! | AG13: =AG7*AG8 -> #REF! | AH13: =AH7*AH8 -> #REF! | AI13: =AI7*AI8 -> #REF! | AJ13: =AJ7*AJ8 -> #REF! | ... AN13: =AN7*AN8 -> #REF! | AO13: =SUM(AC13:AN13) -> #REF! | AP13: =AP7*AP8 -> #REF! | AQ13: =AQ7*AQ8 -> #REF! | AR13: =AR7*AR8 -> #REF! | AS13: =AS7*AS8 -> #REF! | AT13: =AT7*AT8 -> #REF! | AU13: =AU7*AU8 -> #REF! | AV13: =AV7*AV8 -> #REF! | AW13: =AW7*AW8 -> #REF! | ... BA13: =BA7*BA8 -> #REF! | BB13: =SUM(AP13:BA13) -> #REF! | BC13: =BC7*BC8 -> #REF! | BD13: =BD7*BD8 -> #REF! | BE13: =BE7*BE8 -> #REF! | BF13: =BF7*BF8 -> #REF! | BG13: =BG7*BG8 -> #REF! | BH13: =BH7*BH8 -> #REF! | BI13: =BI7*BI8 -> #REF! | BJ13: =BJ7*BJ8 -> #REF! | ... BN13: =BN7*BN8 -> #REF! | BO13: =SUM(BC13:BN13) -> #REF!
A14: Погашение лимита за период, млн тенге | C14: =C11-B11-C13 -> #REF! | D14: =D11-C11-D13 -> #REF! | E14: =E11-D11-E13 -> #REF! | F14: =F11-E11-F13 -> #REF! | G14: =G11-F11-G13 -> #REF! | H14: =H11-G11-H13 -> #REF! | I14: =I11-H11-I13 -> #REF! | J14: =J11-I11-J13 -> #REF! | ... N14: =N11-M11-N13 -> #REF! | O14: =SUM(C14:N14) -> #REF! | P14: =P11-O11-P13 -> #REF! | Q14: =Q11-P11-Q13 -> #REF! | R14: =R11-Q11-R13 -> #REF! | S14: =S11-R11-S13 -> #REF! | T14: =T11-S11-T13 -> #REF! | U14: =U11-T11-U13 -> #REF! | V14: =V11-U11-V13 -> #REF! | W14: =W11-V11-W13 -> #REF! | ... AA14: =AA11-Z11-AA13 -> #REF! | AB14: =SUM(P14:AA14) -> #REF! | AC14: =AC11-AB11-AC13 -> #REF! | AD14: =AD11-AC11-AD13 -> #REF! | AE14: =AE11-AD11-AE13 -> #REF! | AF14: =AF11-AE11-AF13 -> #REF! | AG14: =AG11-AF11-AG13 -> #REF! | AH14: =AH11-AG11-AH13 -> #REF! | AI14: =AI11-AH11-AI13 -> #REF! | AJ14: =AJ11-AI11-AJ13 -> #REF! | ... AN14: =AN11-AM11-AN13 -> #REF! | AO14: =SUM(AC14:AN14) -> #REF! | AP14: =AP11-AO11-AP13 -> #REF! | AQ14: =AQ11-AP11-AQ13 -> #REF! | AR14: =AR11-AQ11-AR13 -> #REF! | AS14: =AS11-AR11-AS13 -> #REF! | AT14: =AT11-AS11-AT13 -> #REF! | AU14: =AU11-AT11-AU13 -> #REF! | AV14: =AV11-AU11-AV13 -> #REF! | AW14: =AW11-AV11-AW13 -> #REF! | ... BA14: =BA11-AZ11-BA13 -> #REF! | BB14: =SUM(AP14:BA14) -> #REF! | BC14: =BC11-BB11-BC13 -> #REF! | BD14: =BD11-BC11-BD13 -> #REF! | BE14: =BE11-BD11-BE13 -> #REF! | BF14: =BF11-BE11-BF13 -> #REF! | BG14: =BG11-BF11-BG13 -> #REF! | BH14: =BH11-BG11-BH13 -> #REF! | BI14: =BI11-BH11-BI13 -> #REF! | BJ14: =BJ11-BI11-BJ13 -> #REF! | ... BN14: =BN11-BM11-BN13 -> #REF! | BO14: =SUM(BC14:BN14) -> #REF!

Sheet Лист2
D1: юр лицо | E1: механика
A2: 1 | B2: 1 | C2: Кошельки симпли обороты до 330 дол | D2: Симпли | F2: ограничение по обороту и типу транзакции
A3: от 1.3 млн | B3: 1.1 | C3: Доверительный платеж | D3: Симпли | E3: пределожение- ответ | F3: отсечения?
A4: от 5 млн | B4: 1.2 | C4: лимит кредитной транзакции 30 дол ( включая снятие нал) | D4: Симпли? Доссым?
A5: из 30 дол | B5: 1.2.1 | C5: БНПЛ 150 ( только рассрочка, любого мерчанта через QR Каспия) | D5: Досссым
B6: 2.2.1 | C6: БНПЛ 1000 (( только рассрочка, любого мерчанта через QR Каспия) | D6: Досссым
J8: Механика
A9: 2 | B9: 1 | C9: Кошельки симпли | D9: Симпли
B10: 2 | C10: кеш 2000 | D10: Доссым | I10: от 5000000 клиентов | J10: от Доверительный платежа и от Кошелька
I11: отсечение | J11: лимит кредитной транзакции 30 дол в месяц (с обязат закрытием в месяц)
I12: DPD 2-3% | J12: погашение нанолендинга | AA12: симпли
I13: сколько их? | J13: наличие семейного пакета Билайна с использованием более чем 2 мес | W13: симпли кошелек | AA13: передает в Доссым ежедневно через инструемнт факторинга и собранные деньги по пакетам и кредитную задолженность
I14: 0.7 | J14: по внутренним проверкам Билайна ( бесплатные), корпо пакеты, анлимитед, семейный, аванс платеж | T14: клиент
D15: из 5 000 000 | E15: из 5 000 000 | F15: из 5 000 000 | W15: кошелек и доверительный плтеж | AB15: камиссия и пакеты
D16: Пакет 1 | E16: Пакет 2 | F16: Пакет 3 | J16: установлен лимит 30 дол | AB16: фандиг
D17: 30 дол | E17: 30 дол | F17: 30 дол | I17: DPD на кеше 3% | W17: от лица Доссыма | AA17: досым | AB17: 10 % комисия
E18: БНПЛ 150 | F18: БНПЛ 1000 | J18: снятие кеша как опция через 90 дней ( только транзакции) | W18: кеш 30 и БНПЛ 150 или 1000
I19: 0.9 | J19: загрузка | AB19: оплата 450 дол
AB20: курсы 500 дол
D21: стоимость пакета | I21: от 5000000 клиентов | J21: от Доверительный платежа и от Кошелька | W21: курсы | AA21: чп иванов
D22: 1000 | E22: 2000 | F22: 3000 | J22: БНПЛ 150 и 1000 ( только рассрочка, любого мерчанта через QR Каспия)
I23: хочешь перейти на следующий стадию дай согласие
I24: 0.5 | J24: согласие клиента
I25: отсечение | J25: установленный лимит
I26: 0.03 | J26: просрочка на 30 дол
I27: 0.6 | J27: проверки в КБ +все необх запросы
C28: симпли кошелек | J28: устанановленный лимит на 6 мес | AD28: >
C30: кошелек и доверительный плтеж | I30: 37% осталось для двух продуктов
I32: 0.1 | J32: на 1000 долларов на 3 и 6мес
I33: для 20% | J33: увеличение лимита до 2000
I35: 0.27 | J35: на 150 долл на 3 и 6 мес
I36: для30% | J36: увеличение лимита до 1000 дол

Sheet Product
B2: курс | D2: 500 | E2: =D2 -> 500 | F2: =E2 -> 500 | G2: =F2 -> 500 | H2: =G2 -> 500 | I2: =H2 -> 500
D3: 2024 | E3: 2025 | F3: 2026 | G3: 2027 | H3: 2028 | I3: 2029
B4: Кол-во клиентов Билайн | D4: 5000000 | E4: =D4*117% -> 5850000 | F4: =E4*117% -> 6844500 | G4: =F4*117% -> 8008065 | H4: =G4*117% -> 9369436 | I4: =H4*117% -> 10962240
B5: доля клиентов со смартфонами (конверсия в кол-во клиентов Билайн), % | D5: 0.83 | E5: 0.83 | F5: 0.83 | G5: 0.83 | H5: 0.83 | I5: 0.83
B7: Кол-во эл кошельков Simply | D7: =D8+D12 -> 5153552 | E7: =E8+E12 -> 6009584.8 | F7: =F8+F12 -> 7008132.5 | G7: =G8+G12 -> 8172971.1 | H7: =H8+H12 -> 9531850.6 | I7: =I8+I12 -> 11117161
B8: Билайн | D8: =D4*D5 -> 4150000 | E8: =E4*E5 -> 4855500 | F8: =F4*F5 -> 5680935 | G8: =G4*G5 -> 6646693.9 | H8: =H4*H5 -> 7776631.9 | I8: =I4*I5 -> 9098659.3
B9: доля идентифицированных, % | D9: =D10/D8 -> 0.032315181 | E9: =E10/E8 -> 0.027619813 | F9: =F10/F8 -> 0.023606677 | G9: =G10/G8 -> 0.020176647 | H9: =H10/H8 -> 0.017244998 | I9: =I10/I8 -> 0.014739314
B10: идентифицированные | D10: 134108 | E10: 134108 | F10: 134108 | G10: 134108 | H10: 134108 | I10: 134108
B11: неидентифицированные | D11: =D8-D10 -> 4015892 | E11: =E8-E10 -> 4721392 | F11: =F8-F10 -> 5546827 | G11: =G8-G10 -> 6512585.9 | H11: =H8-H10 -> 7642523.9 | I11: =I8-I10 -> 8964551.3
B12: неБилайн | D12: 1003552 | E12: =D12*115% -> 1154084.8 | F12: =E12*115% -> 1327197.5 | G12: =F12*115% -> 1526277.1 | H12: =G12*115% -> 1755218.7 | I12: =H12*115% -> 2018501.5
B13: доля идентифицированных, % | D13: =D14/D12 -> 0.13363333 | E13: =E14/E12 -> 0.1162029 | F13: =F14/F12 -> 0.101046 | G13: =G14/G12 -> 0.087866087 | H13: =H14/H12 -> 0.076405293 | I13: =I14/I12 -> 0.066439385
B14: идентифицированные | D14: 134108 | E14: 134108 | F14: 134108 | G14: 134108 | H14: 134108 | I14: 134108
B15: неидентифицированные | D15: =D12-D14 -> 869444 | E15: =E12-E14 -> 1019976.8 | F15: =F12-F14 -> 1193089.5 | G15: =G12-G14 -> 1392169.1 | H15: =H12-H14 -> 1621110.7 | I15: =I12-I14 -> 1884393.5
B16: Доля активных кошельков Simply, % | D16: 0.5 | E16: 0.5 | F16: 0.5 | G16: 0.5 | H16: 0.5 | I16: 0.5
B17: Количество активных кошельков Simply | D17: =ROUND(D7*D16,0) -> 2576776 | E17: =ROUND(E7*E16,0) -> 3004792 | F17: =ROUND(F7*F16,0) -> 3504066 | G17: =ROUND(G7*G16,0) -> 4086486 | H17: =ROUND(H7*H16,0) -> 4765925 | I17: =ROUND(I7*I16,0) -> 5558580
B18: Current Accounts | C18: Forte
B19: Debit Card | C19: Forte | D19: Модель Simply
B20: Доля активных карт от количество активных кошельков Simply,% | D20: 0.1 | E20: 0.1 | F20: 0.1 | G20: 0.1 | H20: 0.1 | I20: 0.1
B21: Количество активных карт | D21: =D17*D20 -> 257677.6 | E21: =E17*E20 -> 300479.2 | F21: =F17*F20 -> 350406.6 | G21: =G17*G20 -> 408648.6 | H21: =H17*H20 -> 476592.5 | I21: =I17*I20 -> 555858
B22: Средний остаток на карте, KZT | D22: 5000 | E22: 5000 | F22: 5000 | G22: 5000 | H22: 5000 | I22: 5000
B23: Ср.остатки на картах, KZT | D23: =D22*D21 -> 1288388000 | E23: =E22*E21 -> 1502396000 | F23: =F22*F21 -> 1.752033e+09 | G23: =G22*G21 -> 2.043243e+09 | H23: =H22*H21 -> 2382962500 | I23: =I22*I21 -> 2779290000
B24: ср.ставка, % | D24: 0.05 | E24: 0.05 | F24: 0.05 | G24: 0.05 | H24: 0.05 | I24: 0.05
B25: трансф.ставка, % (дв) | D25: 0.1 | E25: 0.1 | F25: 0.1 | G25: 0.1 | H25: 0.1 | I25: 0.1
B26: комиссии:
B27: снятие наличных
B28: переводы (внутри KZ, заграничные)
B29: конверсионные
B30: добавить UE
B31: Nano-Lending | C31: Finco
B32: доля кошельков, участвующих в продукте, % | D32: 0.15844679 | E32: 0.15498951 | F32: 0.17129783 | G32: 0.18693162 | H32: 0.20801123 | I32: 0.23340524
B33: количество кошельков, участвующих в продукте, шт | D33: =ROUND(D17*D32,0) -> 408282 | E33: =ROUND(E17*E32,0) -> 465711 | F33: =ROUND(F17*F32,0) -> 600239 | G33: =ROUND(G17*G32,0) -> 763893 | H33: =ROUND(H17*H32,0) -> 991366 | I33: =ROUND(I17*I32,0) -> 1297402
B34: Кол-во платежей на 1 клиента | D34: 1.7964564 | E34: 1.6483669 | F34: 1.4518882 | G34: 1.2951236 | H34: 1.1476457 | I34: 1.0084752
B35: количество выдач | D35: =D17*D32*D34 -> 733460.63 | E35: =E17*E32*E34 -> 767663.01 | F35: =F17*F32*F34 -> 871479.76 | G35: =G17*G32*G34 -> 989336.42 | H35: =H17*H32*H34 -> 1137736.9 | I35: =I17*I32*I34 -> 1308397.4
B37: сред чек, долл | D37: 3 | E37: 3 | F37: 3 | G37: 3 | H37: 3 | I37: 3
B38: Сред чек, тенге | D38: =D37*D2 -> 1500 | E38: =E37*E2 -> 1500 | F38: =F37*F2 -> 1500 | G38: =G37*G2 -> 1500 | H38: =H37*H2 -> 1500 | I38: =I37*I2 -> 1500
B39: Сумма выдачи, тенге | E39: =E38*E35 -> 1.1514945e+09 | F39: =F38*F35 -> 1.3072196e+09 | G39: =G38*G35 -> 1.4840046e+09 | H39: =H38*H35 -> 1.7066053e+09 | I39: =I38*I35 -> 1.9625961e+09
B40: Сумма погашений (1 неделя)
B41: Cost of risk | D41: 0.02
B42: Резервы
B43: Комиссионный доход 1 долл за 1 неделю
...

Sheet Воронка (2)
D1: этим цветом выделены ячейки, которые требуют уточнений
B5: курс | D5: 500 | E5: =D5 -> 500 | F5: =E5 -> 500 | G5: =F5 -> 500 | H5: =G5 -> 500 | I5: =H5 -> 500 | K5: 2025-2029 г.
D6: 2024 | E6: 2025 | F6: 2026 | G6: 2027 | H6: 2028 | I6: 2029 | K6: тенге | L6: USD
B7: Кол-во клиентов Билайн | D7: 5000000 | E7: =D7*117% -> 5850000 | F7: =E7*117% -> 6844500 | G7: =F7*117% -> 8008065 | H7: =G7*117% -> 9369436 | I7: =H7*117% -> 10962240 | K7: уточнить данные по клеинтам Билайна
B8: Кол-во эл кошельков Simply | D8: 4100000 | E8: 5000000 | F8: 5560000 | G8: 6220000 | H8: 7000000 | I8: 8000000 | K8: настаивают , что это все клеиенты
B9: Билайн | D9: 4136295 | E9: =E7*E12 -> 4851165.1 | F9: =F7*F12 -> 5689552.2 | G9: =G7*G12 -> 6672792.2 | H9: =H7*H12 -> 7825905.8 | I9: =I7*I12 -> 9178234.2
B10: идентифицированные | D10: 134108
B11: неидентифицированные | D11: 869444
B12: конверсия в кол-во клиентов Билайн | D12: =D9/D7 -> 0.827259 | E12: =D12+0.2% -> 0.829259 | F12: =E12+0.2% -> 0.831259 | G12: =F12+0.2% -> 0.833259 | H12: =G12+0.2% -> 0.835259 | I12: =H12+0.2% -> 0.837259
B13: неБилайн | D13: 1003552 | E13: =D13*115% -> 1154084.8 | F13: =E13*115% -> 1327197.5 | G13: =F13*115% -> 1526277.1 | H13: =G13*115% -> 1755218.7 | I13: =H13*115% -> 2018501.5 | K13: не будет статитсти Билайна, Нужно выводить в отдельную ветку ( деделасть с Дианой воронку)
B14: идентифицированные | D14: 237217 | P14: ДОДЕЛАТЬ:
B15: неидентифицированные | D15: 3899077 | P15: 1. затраты на идентификацию и онбординг - Оксана
P16: 2. портфель _ Александр
A17: 1 | B17: Debit Card | P17: 3. затраты на коллекш - сколько и в какой момент списываем, стоимость возвращенного доллара ( уточнить у Оксана) софт и хард,
B18: Кол-во активных кошельков | D18: 956516 | E18: =E8*E19 -> 1000000 | F18: =F8*F19 -> 1112000 | G18: =G8*G19 -> 1244000 | H18: =H8*H19 -> 1400000 | I18: =I8*I19 -> 1600000 | P18: 4. резервы - Диана
B19: конверсия в кол-ве эл кошельков | D19: =D18/D8 -> 0.23329659 | E19: 0.2 | F19: 0.2 | G19: 0.2 | H19: 0.2 | I19: 0.2 | P19: 5. стоимость сервиса - предположить
B20: Кол-во активных карт | D20: 129307.44 | E20: 106852.5 | F20: 191162.5 | G20: 233951.02 | H20: 286317.02 | I20: 350404.28 | P20: 6. Пакеты подписки - Марина и Ко
B21: доля активных карт | D21: =D20/D18 -> 0.13518587 | E21: =E20/E18 -> 0.1068525 | F21: =F20/F18 -> 0.17190872 | G21: =G20/G18 -> 0.18806352 | H21: =H20/H18 -> 0.20451216 | I21: =I20/I18 -> 0.21900267
A23: 2 | B23: Nano-Lending
B24: Nano-Lending MAU | D24: 733460.63 | E24: 767663.01 | F24: 871479.76 | G24: 989336.42 | H24: 1137736.9 | I24: 1308397.4 | K24: проверить, это уникальный клиент или это выдача?
B25: конверсия в кол-ве эл кошельков | D25: =D24/D8 -> 0.17889284 | E25: =D25+1% -> 0.18889284 | F25: =E25+1% -> 0.19889284 | G25: =F25+1% -> 0.20889284 | H25: =G25+1% -> 0.21889284 | I25: =H25+1% -> 0.22889284
B26: Кол-во платежей на 1 клиента | D26: 1.7964564 | E26: 1.6483669 | F26: 1.4518882 | G26: 1.2951236 | H26: 1.1476457 | I26: 1.0084752
B27: Сред чек, тенге | D27: =D28*D5 -> 1500 | E27: =E28*E5 -> 1500 | F27: =F28*F5 -> 1500 | G27: =G28*G5 -> 1500 | H27: =H28*H5 -> 1500 | I27: =I28*I5 -> 1500
B28: сред чек, долл | D28: 3 | E28: 3 | F28: 3 | G28: 3 | H28: 3 | I28: 3
B29: Сумма выдачи, тенге | E29: =E27*E24 -> 1.1514945e+09 | F29: =F27*F24 -> 1.3072196e+09 | G29: =G27*G24 -> 1.4840046e+09 | H29: =H27*H24 -> 1.7066053e+09 | I29: =I27*I24 -> 1.9625961e+09 | K29: =E29+F29+G29+H29+I29 -> 7.6119202e+09 | L29: =E29/$E$5+F29/$F$5+G29/$G$5+H29/$H$5+I29/$I$5 -> 15223840
A31: 3 | B31: Микро Займ по подписке ( 30 дол c возможностью снятия кеша)
B32: % клиентов после внутренних проверок и отсечений внутри Билайна ( бесплатно) | E32: 0.7 | F32: 0.7 | G32: 0.7 | H32: 0.7 | I32: 0.7
B33: База после комплайнеса в банке | E33: =E8*E32 -> 3500000 | F33: =F8*F32 -> 3892000 | G33: =G8*G32 -> 4354000 | H33: =H8*H32 -> 4900000 | I33: =I8*I32 -> 5600000
B34: % клиентов,прошедших комплайнес в Банке | E34: 0.8 | F34: 0.8 | G34: 0.8 | H34: 0.8 | I34: 0.8
B35: База после внешних , платных проверок ( КБ, доходы, налоги, аресты) - действует 30 дней | E35: =E33*E34 -> 2800000 | F35: =F33*F34 -> 3113600 | G35: =G33*G34 -> 3483200 | H35: =H33*H34 -> 3920000 | I35: =I33*I34 -> 4480000
B36: % клиентов,после платных проверок | E36: 0.6 | F36: 0.6 | G36: 0.6 | H36: 0.6 | I36: 0.6
B37: Клиенты , которым сделаи оффер в приложении после всех проверок | E37: =E35*E36 -> 1680000 | F37: =F35*F36 -> 1868160 | G37: =G35*G36 -> 2089920 | H37: =H35*H36 -> 2352000 | I37: =I35*I36 -> 2688000
B38: % клиентов, которые откликнулись | E38: 0.3 | F38: 0.35 | G38: 0.4 | H38: 0.45 | I38: 0.5
B39: Клиенты с продуктом | E39: =E37*E38 -> 504000 | F39: =F37*F38 -> 653856 | G39: =G37*G38 -> 835968 | H39: =H37*H38 -> 1058400 | I39: =I37*I38 -> 1344000
B40: Take up, % | E40: 0.95 | F40: 0.95 | G40: 0.95 | H40: 0.95 | I40: 0.95
B41: Кол-во клиентов, согласившихся на пакет | E41: =E39*E40 -> 478800 | F41: =F39*F40 -> 621163.2 | G41: =G39*G40 -> 794169.6 | H41: =H39*H40 -> 1005480 | I41: =I39*I40 -> 1276800
B42: Средний чек лимита для пакета, тенге | E42: =E43*D5 -> 15000 | F42: =F43*E5 -> 15000 | G42: =G43*F5 -> 15000 | H42: =H43*G5 -> 15000 | I42: =I43*H5 -> 15000
B43: сред чек лимита на пакет, долл | E43: 30 | F43: 30 | G43: 30 | H43: 30 | I43: 30
B44: Сумма установленного кредитного лимита, тенге | E44: =E42*E41 -> 7182000000 | F44: =F42*F41 -> 9317448000 | G44: =G42*G41 -> 11912544000 | H44: =H42*H41 -> 15082200000 | I44: =I42*I41 -> 19152000000
B45: % клиентов, которые пользуются пакетом | E45: 0.8 | F45: 0.8 | G45: 0.8 | H45: 0.8 | I45: 0.8
...

Sheet Goals
A1: Goals
D3: 45657 | E3: 45747 | F3: 45838 | G3: 45930 | H3: 46022
D4: 2024 | E4: 2025 | F4: 2025 | G4: 2025 | H4: 2025 | I4: 2026 | J4: 2026 | K4: 2027 | L4: 2027 | M4: 2028 | N4: 2028 | O4: 2029 | P4: 2029 | R4: 2024 | S4: 2025 | T4: 2026 | U4: 2027 | V4: 2028 | W4: 2029
D5: Y0 | E5: Q1 | F5: Q2 | G5: Q3 | H5: Q4 | I5: H1 | J5: H2 | K5: H1 | L5: H2 | M5: H1 | N5: H2 | O5: H1 | P5: H2 | R5: Y0 | S5: Y1 | T5: Y2 | U5: Y3 | V5: Y4 | W5: Y5
D6: 0 | E6: 1 | F6: 2 | G6: 3 | H6: 4 | I6: 5 | J6: 6 | K6: 7 | L6: 8 | M6: 9 | N6: 10 | O6: 11 | P6: 12
A7: Параметры | B7: ЕИ | C7: Отв.исп.
A8: The clients of Beeline | B8: person | D8: ='Funnel QH'!D8 -> 5000000 | E8: ='Funnel QH'!E8 -> 5295890.4 | F8: ='Funnel QH'!F8 -> 5595068.5 | G8: ='Funnel QH'!G8 -> 5897534.2 | H8: ='Funnel QH'!H8 -> 6200000 | I8: ='Funnel QH'!I8 -> 6497500 | J8: ='Funnel QH'!J8 -> 6795000 | K8: ='Funnel QH'!K8 -> 7147500 | ... P8: ='Funnel QH'!P8 -> 9510000 | R8: =D8 -> 5000000 | S8: =H8 -> 6200000 | T8: =J8 -> 6795000 | U8: =L8 -> 7500000 | V8: =N8 -> 8365000 | W8: =P8 -> 9510000
A9: El. Wallet Simply | B9: unit | D9: ='Funnel QH'!D11 -> 4100000 | E9: ='Funnel QH'!E11 -> 4320359.5 | F9: ='Funnel QH'!F11 -> 4543167.5 | G9: ='Funnel QH'!G11 -> 4768423.9 | H9: ='Funnel QH'!H11 -> 5006080.3 | I9: ='Funnel QH'!I11 -> 5264475.3 | J9: ='Funnel QH'!J11 -> 5562450.4 | K9: ='Funnel QH'!K11 -> 5881699.8 | ... P9: ='Funnel QH'!P11 -> 8003045.6 | R9: =D9 -> 4100000 | S9: =H9 -> 5006080.3 | T9: =J9 -> 5562450.4 | U9: =L9 -> 6215949.1 | V9: =N9 -> 7002496.2 | W9: =P9 -> 8003045.6
A10: Client of ecosystem with el.wallet Simply | B10: person | D10: ='Funnel QH'!D24 -> 3280000 | E10: ='Funnel QH'!E24 -> 3456287.6 | F10: ='Funnel QH'!F24 -> 3634534 | G10: ='Funnel QH'!G24 -> 3814739.1 | H10: ='Funnel QH'!H24 -> 4004864.3 | I10: ='Funnel QH'!I24 -> 4211580.3 | J10: ='Funnel QH'!J24 -> 4449960.3 | K10: ='Funnel QH'!K24 -> 4705359.8 | ... P10: ='Funnel QH'!P24 -> 6402436.5 | R10: =D10 -> 3280000 | S10: =H10 -> 4004864.3 | T10: =J10 -> 4449960.3 | U10: =L10 -> 4972759.3 | V10: =N10 -> 5601997 | W10: =P10 -> 6402436.5
A11: Active clients with credit limit | B11: person | R11: =Funnel!D117 -> 0 | S11: =Funnel!E117 -> 55590.32 | T11: =Funnel!F117 -> 399794.5 | U11: =Funnel!G117 -> 851814.28 | V11: =Funnel!H117 -> 1224673.5 | W11: =Funnel!I117 -> 1507002.9
A12: Active clients with credit | B12: person | R12: =Funnel!D119 -> 0 | S12: =Funnel!E119 -> 62782.218 | T12: =Funnel!F119 -> 380630.58 | U12: =Funnel!G119 -> 786819.94 | V12: =Funnel!H119 -> 1127530.8 | W12: =Funnel!I119 -> 1374307.5
A13: Merchants (legal entities and individual entrepreneurs) | B13: unit | D13: ='Funnel QH'!D25 -> 0 | E13: ='Funnel QH'!E25 -> 0 | F13: ='Funnel QH'!F25 -> 0 | G13: ='Funnel QH'!G25 -> 0 | H13: ='Funnel QH'!H25 -> 0 | I13: ='Funnel QH'!I25 -> 0 | J13: ='Funnel QH'!J25 -> 30000 | K13: ='Funnel QH'!K25 -> 49833.333 | ... P13: ='Funnel QH'!P25 -> 149000 | R13: =D13 -> 0 | S13: =H13 -> 0 | T13: =J13 -> 30000 | U13: =L13 -> 69666.667 | V13: =N13 -> 109333.33 | W13: =P13 -> 149000
A14: Active merchants | B14: unit | D14: ='Merchants(corp)'!D164 -> 0 | E14: ='Merchants(corp)'!E164 -> 0 | F14: ='Merchants(corp)'!F164 -> 0 | G14: ='Merchants(corp)'!G164 -> 0 | H14: ='Merchants(corp)'!H164 -> 0 | I14: ='Merchants(corp)'!I164 -> 0 | J14: ='Merchants(corp)'!J164 -> 15000 | K14: ='Merchants(corp)'!K164 -> 26162.5 | ... P14: ='Merchants(corp)'!P164 -> 99837.125 | R14: =D14 -> 0 | S14: =H14 -> 0 | T14: =J14 -> 15000 | U14: =L14 -> 38403.75 | V14: =N14 -> 66447.675 | W14: =P14 -> 99837.125
A15: Дебетовые карты Simply | C15: Forte
A16: % от кол-ва клиентов экосистемы | B16: % | E16: =E17/E10 -> 0.02498924 | F16: =F17/F10 -> 0.025296228 | G16: =G17/G10 -> 0.026384504 | H16: =H17/H10 -> 0.027534017 | I16: =I17/I10 -> 0.038618521 | J16: =J17/J10 -> 0.048319532 | K16: =K17/K10 -> 0.051579308 | L16: =L17/L10 -> 0.054371907 | ... P16: =P17/P10 -> 0.051788416 | R16: =D16 -> 0 | S16: =H16 -> 0.027534017 | T16: =J16 -> 0.048319532 | U16: =L16 -> 0.054371907 | V16: =N16 -> 0.054521175 | W16: =P16 -> 0.051788416
A17: Количество карт на конец периода | B17: шт | C17: Finmodel SIMPLY | D17: 81000 | E17: 86370 | F17: 91940 | G17: 100650 | H17: 110270 | I17: =AVERAGE(J17,H17) -> 162645 | J17: 215020 | K17: =AVERAGE(L17,J17) -> 242699.2 | L17: 270378.41 | M17: =AVERAGE(N17,L17) -> 287902.93 | N17: 305427.46 | O17: =AVERAGE(P17,N17) -> 318499.75 | P17: 331572.05 | R17: =D17 -> 81000 | S17: =H17 -> 110270 | T17: =J17 -> 215020 | U17: =L17 -> 270378.41 | V17: =N17 -> 305427.46 | W17: =P17 -> 331572.05
A18: Остатки (на конец периода) | B18: 000 USD | C18: Факторный анализ для FPA | E18: =326966.90169915/500 -> 653.9338 | F18: =F17*$E18/$E17 -> 696.10598 | G18: =G17*$E18/$E17 -> 762.05207 | H18: =502521.813794505/500 -> 1005.0436 | I18: =I17*H18/H17 -> 1482.4097 | J18: =943978.77954158/500 -> 1887.9576 | K18: =K17*J18/J17 -> 2130.9915 | L18: =1213036.20494188/500 -> 2426.0724 | M18: =M17*L18/L17 -> 2583.3178 | N18: =1558781.68703578/500 -> 3117.5634 | O18: =O17*N18/N17 -> 3250.9951 | P18: =2003073.22892685/500 -> 4006.1465 | R18: =D18 -> 0 | S18: =H18 -> 1005.0436 | T18: =J18 -> 1887.9576 | U18: =L18 -> 2426.0724 | V18: =N18 -> 3117.5634 | W18: =P18 -> 4006.1465
A19: Комиссионные доходы | B19: 000 USD | C19: Факторный анализ для FPA | E19: =1472388.52797171/4/500 -> 736.19426 | F19: =1472388.52797171/4/500 -> 736.19426 | G19: =1472388.52797171/4/500 -> 736.19426 | H19: =1472388.52797171/4/500 -> 736.19426 | I19: =2810288.92365012/2/500 -> 2810.2889 | J19: =2810288.92365012/2/500 -> 2810.2889 | K19: =3595873.85026496/2/500 -> 3595.8739 | L19: =3595873.85026496/2/500 -> 3595.8739 | M19: =4604802.75037225/2/500 -> 4604.8028 | N19: =4604802.75037225/2/500 -> 4604.8028 | O19: =5900639.34576269/2/500 -> 5900.6393 | P19: =5900639.34576269/2/500 -> 5900.6393
A20: Операционные расходы | B20: 000 USD | C20: Факторный анализ для FPA | E20: =-1204077.19822955/4/500 -> -602.0386 | F20: =-1204077.19822955/4/500 -> -602.0386 | G20: =-1204077.19822955/4/500 -> -602.0386 | H20: =-1204077.19822955/4/500 -> -602.0386 | I20: =-1399194.37543398/2/500 -> -1399.1944 | J20: =-1399194.37543398/2/500 -> -1399.1944 | K20: =-1624610.29352731/2/500 -> -1624.6103 | L20: =-1624610.29352731/2/500 -> -1624.6103 | M20: =-1859998.82599472/2/500 -> -1859.9988 | N20: =-1859998.82599472/2/500 -> -1859.9988 | O20: =-2333382.96480478/2/500 -> -2333.383 | P20: =-2333382.96480478/2/500 -> -2333.383
A21: Среднемесячная прибыль на 1 карту | B21: USD | C21: PL продуктов 2024 Act | D21: 2.0747097 | E21: 2.0747097 | F21: 2.0747097 | G21: 2.0747097 | H21: 2.0747097 | I21: 2.0747097 | J21: 2.0747097 | K21: 2.0747097 | L21: 2.0747097 | M21: 2.0747097 | N21: 2.0747097 | O21: 2.0747097 | P21: 2.0747097 | R21: =D21 -> 2.0747097 | S21: =H21 -> 2.0747097 | T21: =J21 -> 2.0747097 | U21: =L21 -> 2.0747097 | V21: =N21 -> 2.0747097 | W21: =P21 -> 2.0747097
A22: Прибыль (до уплаты налогов) | B22: 000 USD | D22: =73000*D21/1000*12 -> 1817.4457 | E22: =(D17+E17)/2*E21*3/1000 -> 520.86625 | F22: =(E17+F17)/2*F21*3/1000 -> 554.91224 | G22: =(F17+G17)/2*G21*3/1000 -> 599.35252 | H22: =(G17+H17)/2*H21*3/1000 -> 656.39667 | I22: =(H17+I17)/2*I21*6/1000 -> 1698.6582 | J22: =(I17+J17)/2*J21*6/1000 -> 2350.6358 | K22: =(J17+K17)/2*K21*6/1000 -> 2848.9035 | L22: =(K17+L17)/2*L21*6/1000 -> 3193.4613 | M22: =(L17+M17)/2*M21*6/1000 -> 3474.8152 | N22: =(M17+N17)/2*N21*6/1000 -> 3692.965 | O22: =(N17+O17)/2*O21*6/1000 -> 3883.4036 | P22: =(O17+P17)/2*P21*6/1000 -> 4046.1309 | R22: =D22 -> 1817.4457 | S22: =E22+F22+G22+H22 -> 2331.5277 | T22: =I22+J22 -> 4049.294 | U22: =K22+L22 -> 6042.3648 | V22: =M22+N22 -> 7167.7802 | W22: =O22+P22 -> 7929.5345 | Y22: =W22/$W$124 -> 0.048852549
A24: Nano-Lending | C24: Finco
A25: % от кол-ва клиентов экосистемы | B25: % | E25: =E26/E10 -> 0.091528139 | F25: =F26/F10 -> 0.087039377 | G25: =G26/G10 -> 0.082927708 | H25: =H26/H10 -> 0.078990836 | I25: =I26/I10 -> 0.15021572 | J25: =J26/J10 -> 0.14216881 | K25: =K26/K10 -> 0.13615462 | L25: =L26/L10 -> 0.12883319 | ... P25: =P26/P10 -> 0.10304564 | R25: =D25 -> 0 | S25: =H25 -> 0.078990836 | T25: =J25 -> 0.14216881 | U25: =L25 -> 0.12883319 | V25: =N25 -> 0.11654048 | W25: =P25 -> 0.10304564
A26: Количество выданных займов | B26: шт | C26: Finmodel SIMPLY | D26: 1098025.1 | E26: =1265390.29514024/4 -> 316347.57 | F26: =1265390.29514024/4 -> 316347.57 | G26: =1265390.29514024/4 -> 316347.57 | H26: =1265390.29514024/4 -> 316347.57 | I26: =1265291.14780088/2 -> 632645.57 | J26: =1265291.14780088/2 -> 632645.57 | K26: 640656.46 | L26: 640656.46 | M26: 652859.44 | N26: 652859.44 | O26: 659743.15 | P26: 659743.15 | R26: =D26 -> 1098025.1 | S26: =E26+F26+G26+H26 -> 1265390.3 | T26: =I26+J26 -> 1265291.1 | U26: =K26+L26 -> 1281312.9 | V26: =M26+N26 -> 1305718.9 | W26: =O26+P26 -> 1319486.3
A27: Комиссионные доходы | B27: 000 USD | C27: Факторный анализ для FPA | E27: =2120216.51288896/500/4 -> 1060.1083 | F27: =2120216.51288896/500/4 -> 1060.1083 | G27: =2120216.51288896/500/4 -> 1060.1083 | H27: =2120216.51288896/500/4 -> 1060.1083 | I27: =2226052.90656702/500/2 -> 2226.0529 | J27: =2226052.90656702/500/2 -> 2226.0529 | K27: =2366952.37582407/500/2 -> 2366.9524 | L27: =2366952.37582407/500/2 -> 2366.9524 | M27: =2532639.04213175/500/2 -> 2532.639 | N27: =2532639.04213175/500/2 -> 2532.639 | O27: =2687310.16254222/500/2 -> 2687.3102 | P27: =2687310.16254222/500/2 -> 2687.3102 | S27: =E27+F27+G27+H27 -> 4240.433 | T27: =I27+J27 -> 4452.1058 | U27: =K27+L27 -> 4733.9048 | V27: =M27+N27 -> 5065.2781 | W27: =O27+P27 -> 5374.6203
A28: Операционные расходы | B28: 000 USD | C28: Факторный анализ для FPA | E28: =-754108.020657356/500/4 -> -377.05401 | F28: =-754108.020657356/500/4 -> -377.05401 | G28: =-754108.020657356/500/4 -> -377.05401 | H28: =-754108.020657356/500/4 -> -377.05401 | I28: =-664573.031479807/500/2 -> -664.57303 | J28: =-664573.031479807/500/2 -> -664.57303 | K28: =-645823.790682006/500/2 -> -645.82379 | L28: =-645823.790682006/500/2 -> -645.82379 | M28: =-650458.881388264/500/2 -> -650.45888 | N28: =-650458.881388264/500/2 -> -650.45888 | O28: =-711365.338718628/500/2 -> -711.36534 | P28: =-711365.338718628/500/2 -> -711.36534 | S28: =H28+J28+L28+N28 -> -2337.9097 | T28: =P28+#REF! -> #REF! | U28: =#REF!+#REF! -> #REF! | V28: =#REF!+#REF! -> #REF! | W28: =#REF!+#REF! -> #REF!
A29: Прибыль с 1 займа | B29: USD | C29: PL продуктов 2024 Act | D29: 3 | E29: 3 | F29: 3 | G29: 3 | H29: 3 | I29: 3 | J29: 3 | K29: 3 | L29: 3 | M29: 3 | N29: 3 | O29: 3 | P29: 3 | R29: =D29 -> 3 | S29: =H29 -> 3 | T29: =J29 -> 3 | U29: =L29 -> 3 | V29: =N29 -> 3 | W29: =P29 -> 3
A30: Прибыль (до уплаты налогов) | B30: 000 USD | D30: =D26*D29/1000 -> 3294.0752 | E30: =E26*E29/1000*3 -> 2847.1282 | F30: =F26*F29/1000*3 -> 2847.1282 | G30: =G26*G29/1000*3 -> 2847.1282 | H30: =H26*H29/1000*3 -> 2847.1282 | I30: =I26*I29/1000 -> 1897.9367 | J30: =J26*J29/1000 -> 1897.9367 | K30: =K26*K29/1000 -> 1921.9694 | L30: =L26*L29/1000 -> 1921.9694 | M30: =M26*M29/1000 -> 1958.5783 | N30: =N26*N29/1000 -> 1958.5783 | O30: =O26*O29/1000 -> 1979.2294 | P30: =P26*P29/1000 -> 1979.2294 | R30: =D30 -> 3294.0752 | S30: =E30+F30+G30+H30 -> 11388.513 | T30: =I30+J30 -> 3795.8734 | U30: =K30+L30 -> 3843.9388 | V30: =M30+N30 -> 3917.1567 | W30: =O30+P30 -> 3958.4589 | Y30: =W30/$W$124 -> 0.02438741
A32: Платные подписки на пакеты услуг | C32: Forte
A33: Прибыль (до уплаты налогов) | B33: 000 USD | G33: ='packages (indiv)'!BT$95 -> -719.73813 | H33: ='packages (indiv)'!BU$95 -> -872.68316 | I33: ='packages (indiv)'!BV$95 -> -3031.5865 | J33: ='packages (indiv)'!BW$95 -> -3852.4112 | K33: ='packages (indiv)'!BX$95 -> 1263.7236 | L33: ='packages (indiv)'!BY$95 -> 2599.2777 | M33: ='packages (indiv)'!BZ$95 -> 9636.2258 | N33: ='packages (indiv)'!CA$95 -> 11479.161 | ... Q33: ='packages (indiv)'!CD$95 -> 0 | T33: =I33+J33 -> -6883.9977 | U33: =K33+L33 -> 3863.0013 | V33: =M33+N33 -> 21115.387 | W33: =O33+P33 -> 39385.325 | Y33: =W33/$W$124 -> 0.24264647
A35: в т.ч. Дебетовые карты (план)
A36: Прибыль (до уплаты налогов) | E36: ='Debit card (indiv)'!BR$95 -> 0 | F36: ='Debit card (indiv)'!BS$95 -> 0 | G36: ='Debit card (indiv)'!BT$95 -> -92.821072 | H36: ='Debit card (indiv)'!BU$95 -> -241.53794 | I36: ='Debit card (indiv)'!BV$95 -> -690.44226 | J36: ='Debit card (indiv)'!BW$95 -> -1525.4348 | K36: ='Debit card (indiv)'!BX$95 -> -297.57002 | L36: ='Debit card (indiv)'!BY$95 -> -377.23838 | ... P36: ='Debit card (indiv)'!CC$95 -> 6979.3543 | S36: =E36+F36+G36+H36 -> -334.35901 | T36: =I36+J36 -> -2215.877 | U36: =K36+L36 -> -674.8084 | V36: =M36+N36 -> 5554.5244 | W36: =O36+P36 -> 13114.874 | Y36: =W36/$W$124 -> 0.080798568
A38: в т.ч. Микро Займ по подписке ( 30 дол c возможностью снятия кеша) | C38: Forte
A39: Прибыль (до уплаты налогов) | B39: 000 USD | E39: ='Micro_30 (indiv)'!BR$73 -> 0 | F39: ='Micro_30 (indiv)'!BS$73 -> 0 | G39: ='Micro_30 (indiv)'!BT$73 -> -12.008725 | H39: ='Micro_30 (indiv)'!BU$73 -> -37.942127 | I39: ='Micro_30 (indiv)'!BV$73 -> -221.19214 | J39: ='Micro_30 (indiv)'!BW$73 -> -523.8303 | K39: ='Micro_30 (indiv)'!BX$73 -> -788.11334 | L39: ='Micro_30 (indiv)'!BY$73 -> -1165.9014 | ... P39: ='Micro_30 (indiv)'!CC$73 -> -1933.8642 | S39: =E39+F39+G39+H39 -> -49.950852 | T39: =I39+J39 -> -745.02245 | U39: =K39+L39 -> -1954.0148 | V39: =M39+N39 -> -3018.5422 | W39: =O39+P39 -> -3645.8402 | Y39: =W39/$W$124 -> -0.022461418
A41: в т.ч. Карта рассрочки ( BNPL 150 дол) новая клиентская база из кошельков Simply - 4 мес | C41: Forte
