Workbook
Name __dol1: #REF!
Name __END1: #REF!
Name __kurs_dol__: #REF!
Name __stroka__: #REF!
Name _dol1: #REF!
Name _END1: #REF!
Name aned110: #REF!
Name aned111: #REF!
Name aned112: #REF!
Name aned113: #REF!
Name aned146: #REF!
Name aned158: #REF!
Name aned161: #REF!
Name aned162: #REF!
Name aned170: #REF!
Name aned184: #REF!
Name aned191: #REF!
Name aned194: #REF!
Name aned213: #REF!
Name aned224: #REF!
Name aned239: #REF!
Name aned34: #REF!
Name aned50: #REF!
Name aned60: #REF!
Name aned61: #REF!
Name aned62: #REF!
Name aned620: #REF!
Name aned624: #REF!
Name aned628: #REF!
Name aned629: #REF!
Name aned63: #REF!
Name aned632: #REF!
Name aned636: #REF!
Name aned637: #REF!
Name aned639: #REF!
Name aned64: #REF!
Name aned647: #REF!
Name aned65: #REF!
Name aned657: #REF!
Name aned662: #REF!
Name aned668: #REF!
Name aned680: #REF!
Name aned681: #REF!
Name aned682: #REF!
Name aned683: #REF!
Name aned716: #REF!
Name aned718: #REF!
Name aned719: #REF!
Name aned72: #REF!
Name aned728: #REF!
Name aned729: #REF!
Name aned731: #REF!
Name aned76: #REF!
Name aned77: #REF!
Name aned79: #REF!
Name aned812: #REF!
Name aned86: #REF!
Name aned87: #REF!
Name aned882: #REF!
Name aned900: #REF!

Sheet Продукты
B1: ЦФО – Владелец продукта | C1: Банковский продукт | D1: Банковский продукт (ФМ) | E1: Канал | F1: Бизнес линия | G1: Вид бизнеса | H1: Лист
C2: Потребительский кредит (ФЛ) | D2: Нецелевые кредиты (потребительские) (залоговые) | E2: Безбумажный офис | F2: Кредиты | G2: Розничный бизнес | H2: РБ.1
E3: DCB 360 | F3: Кредиты | G3: Розничный бизнес | H3: РБ.1
C4: Мобильный кредит | D4: Ипотека | E4: Безбумажный офис | F4: Кредиты | G4: Розничный бизнес | H4: РБ.1
C5: GREEN – ЭКОДОМ (ФЛ) | D5: Нецелевые кредиты (потребительские) (залоговые) | E5: Безбумажный офис | F5: Кредиты | G5: Розничный бизнес | H5: РБ.1
C6: DCB АВТО (ФЛ) | D6: Нецелевые кредиты (потребительские) (без залога) | E6: Безбумажный офис | F6: Кредиты | G6: Розничный бизнес | H6: РБ.1
E7: DCB 360 | F7: Кредиты | G7: Розничный бизнес | H7: РБ.1
C8: ЭКО-Агрокредит (ФЛ) | D8: Ипотека | E8: Безбумажный офис | F8: Кредиты | G8: Розничный бизнес | H8: РБ.1
C9: Универсальный депозит "Бай Бол" | E9: Безбумажный офис | F9: Счета и депозиты | G9: Розничный бизнес | H9: РБ.2
E10: DCB 360 | F10: Счета и депозиты | G10: Розничный бизнес | H10: РБ.2
C11: Депозит «Бай Бол +» | E11: Безбумажный офис | F11: Счета и депозиты | G11: Розничный бизнес | H11: РБ.2
E12: DCB 360 | F12: Счета и депозиты | G12: Розничный бизнес | H12: РБ.2
C13: Депозит «Зеленый» | E13: Безбумажный офис | F13: Счета и депозиты | G13: Розничный бизнес | H13: РБ.2
E14: DCB 360 | F14: Счета и депозиты | G14: Розничный бизнес | H14: РБ.2
C15: Счет до востребования | E15: Безбумажный офис | F15: Счета и депозиты | G15: Розничный бизнес | H15: РБ.2
E16: DCB 360 | F16: Счета и депозиты | G16: Розничный бизнес | H16: РБ.2
C17: Карта социальные выплаты | E17: Безбумажный офис | F17: Выпуск и обслуживание банковских карт | G17: Розничный бизнес | H17: РБ.3
C18: Карта Элкарт DCB | E18: Безбумажный офис | F18: Выпуск и обслуживание банковских карт | G18: Розничный бизнес | H18: РБ.3
E19: DCB 360 | F19: Выпуск и обслуживание банковских карт | G19: Розничный бизнес | H19: РБ.3
C20: Карта пенсионера | E20: Безбумажный офис | F20: Выпуск и обслуживание банковских карт | G20: Розничный бизнес | H20: РБ.3
C21: DCB Kids детская карта | E21: Безбумажный офис | F21: Выпуск и обслуживание банковских карт | G21: Розничный бизнес | H21: РБ.3
C22: Зарплатная карта | E22: Безбумажный офис | F22: Выпуск и обслуживание банковских карт | G22: Розничный бизнес | H22: РБ.3
C23: Открытие и обслуживание банковского счета | E23: Безбумажный офис | F23: РКО | G23: Розничный бизнес | H23: РБ.3
E24: DCB 360 | F24: РКО | G24: Розничный бизнес | H24: РБ.3
C25: Переводы и платежи | E25: Безбумажный офис | F25: РКО | G25: Розничный бизнес | H25: РБ.3
E26: DCB 360 | F26: РКО | G26: Розничный бизнес | H26: РБ.3
C27: Кассовые операции | E27: Безбумажный офис | F27: РКО | G27: Розничный бизнес | H27: РБ.3
C28: Валютные операции | E28: Безбумажный офис | F28: РКО | G28: Розничный бизнес | H28: РБ.3
E29: DCB 360 | F29: РКО | G29: Розничный бизнес | H29: РБ.3
C30: Бизнес-кредит (ИП, ЮЛ) | E30: Безбумажный офис | F30: Кредиты | G30: Малый и средний бизнес | H30: МСБ.1
C31: GREEN - ЭКОАВТО (ИП, ЮЛ) | E31: Безбумажный офис | F31: Кредиты | G31: Малый и средний бизнес | H31: МСБ.1
C32: ЭКО-Агрокредит (ИП, ЮЛ) | E32: Безбумажный офис | F32: Кредиты | G32: Малый и средний бизнес | H32: МСБ.1
C33: Гарантии | E33: Безбумажный офис | F33: Кредиты | G33: Малый и средний бизнес | H33: МСБ.1
C34: Депозит "Срочный" (ЮЛ, ИП) | E34: Безбумажный офис | F34: Депозиты | G34: Малый и средний бизнес | H34: МСБ.2
E35: DCB Бизнес | F35: Депозиты | G35: Малый и средний бизнес | H35: МСБ.2
C36: Депозит «Зеленый» (ЮЛ, ИП) | E36: Безбумажный офис | F36: Депозиты | G36: Малый и средний бизнес | H36: МСБ.2
E37: DCB Бизнес | F37: Депозиты | G37: Малый и средний бизнес | H37: МСБ.2
C38: Расчетный счет | E38: Безбумажный офис | F38: Депозиты | G38: Малый и средний бизнес | H38: МСБ.2
E39: DCB Бизнес | F39: Депозиты | G39: Малый и средний бизнес | H39: МСБ.2
C40: Карточные счета | E40: Безбумажный офис | F40: Депозиты | G40: Малый и средний бизнес | H40: МСБ.2
...

Sheet 0
A1: Параметры модели
D4: 46023 | E4: 46054 | F4: 46082 | G4: 46113 | H4: 46143 | I4: 46174 | J4: 46204 | K4: 46235 | L4: 46266 | M4: 46296 | N4: 46327 | O4: 46357 | P4: 46388 | Q4: 46419 | R4: 46447 | S4: 46478 | T4: 46508 | U4: 46539 | V4: 46569 | W4: 46600 | X4: 46631 | Y4: 46661 | Z4: 46692 | AA4: 46722 | AB4: 46753 | AC4: 46784 | AD4: 46813 | AE4: 46844 | AF4: 46874 | AG4: 46905 | AH4: 46935 | AI4: 46966 | AJ4: 46997 | AK4: 47027 | AL4: 47058 | AM4: 47088 | AO4: =YEAR(O4) -> 2026 | AP4: =YEAR(AA4) -> 2027 | AQ4: =YEAR(AM4) -> 2028
D5: m1 | E5: m2 | F5: m3 | G5: m4 | H5: m5 | I5: m6 | J5: m7 | K5: m8 | L5: m9 | M5: m10 | N5: m11 | O5: m12 | P5: m13 | Q5: m14 | R5: m15 | S5: m16 | T5: m17 | U5: m18 | V5: m19 | W5: m20 | X5: m21 | Y5: m22 | Z5: m23 | AA5: m24 | AB5: m25 | AC5: m26 | AD5: m27 | AE5: m28 | AF5: m29 | AG5: m30 | AH5: m31 | AI5: m32 | AJ5: m33 | AK5: m34 | AL5: m35 | AM5: m36 | AO5: Y1 | AP5: Y2 | AQ5: Y3
D6: 1 | E6: =D6+1 -> 2 | F6: =E6+1 -> 3 | G6: =F6+1 -> 4 | H6: =G6+1 -> 5 | I6: =H6+1 -> 6 | J6: =I6+1 -> 7 | K6: =J6+1 -> 8 | L6: =K6+1 -> 9 | ... AM6: =AL6+1 -> 36
A8: Показатель | B8: ЕИ | C8: Отв.исп.
A9: количество филиалов | D9: 10 | E9: 10 | F9: 10 | G9: 10 | H9: 10 | I9: 10 | J9: 10 | K9: 10 | L9: 10 | M9: 10 | N9: 10 | O9: 10 | P9: 10 | Q9: 10 | R9: 10 | S9: 10 | T9: 10 | U9: 10 | V9: 10 | W9: 10 | X9: 10 | Y9: 10 | Z9: 10 | AA9: 10 | AB9: 10 | AC9: 10 | AD9: 10 | AE9: 10 | AF9: 10 | AG9: 10 | AH9: 10 | AI9: 10 | AJ9: 10 | AK9: 10 | AL9: 10 | AM9: 10 | AO9: =O9 -> 10 | AP9: =AA9 -> 10 | AQ9: =AM9 -> 10
A10: количество клиентов, в т.ч.: | D10: =SUM(D11:D13) -> 0 | E10: =SUM(E11:E13) -> 0 | F10: =SUM(F11:F13) -> 0 | G10: =SUM(G11:G13) -> 0 | H10: =SUM(H11:H13) -> 0 | I10: =SUM(I11:I13) -> 0 | J10: =SUM(J11:J13) -> 0 | K10: =SUM(K11:K13) -> 0 | ... AM10: =SUM(AM11:AM13) -> 0
A11: ЮЛ
A12: ИП
A13: ФЛ
A14: количество кредитных специалистов | D14: 130 | E14: =D14*(1-5.5%) -> 122.85 | F14: =E14*(1-5.5%) -> 116.09325 | G14: =F14*(1-5.5%) -> 109.70812 | H14: =G14*(1-5.5%) -> 103.67417 | I14: =H14*(1-5.5%) -> 97.972095 | J14: =I14*(1-5.5%) -> 92.58363 | K14: =J14*(1-5.5%) -> 87.49153 | L14: =K14*(1-5.5%) -> 82.679496 | M14: 80 | N14: 80 | O14: 80 | P14: =O14 -> 80 | Q14: =P14 -> 80 | R14: =Q14 -> 80 | S14: =R14 -> 80 | T14: =S14 -> 80 | U14: =T14 -> 80 | V14: =U14 -> 80 | W14: =V14 -> 80 | ... AM14: =AL14 -> 80 | AO14: =O14 -> 80 | AP14: =AA14 -> 80 | AQ14: =AM14 -> 80
A15: курсы валют
A16: RUB | C16: 1.1233 | D16: 1.01 | E16: 1.01 | F16: 1.01 | G16: 1.01 | H16: 1.01 | I16: 1 | J16: 1 | K16: 1 | L16: 1 | M16: 1 | N16: 1 | O16: 1 | P16: 1 | Q16: 1 | R16: 0.97 | S16: 0.97 | T16: 0.97 | U16: 0.97 | V16: 0.97 | W16: 0.97 | X16: 0.97 | Y16: 0.97 | Z16: 0.97 | AA16: 0.97 | AB16: 0.97 | AC16: 0.97 | AD16: 0.97 | AE16: 0.97 | AF16: 0.97 | AG16: 0.97 | AH16: 0.97 | AI16: 0.97 | AJ16: 0.97 | AK16: 0.97 | AL16: 0.97 | AM16: 0.97
A17: USD | C17: 87.4177 | D17: 87.45 | E17: 87.45 | F17: 87.45 | G17: 87.45 | H17: 87.45 | I17: 87.45 | J17: 87.45 | K17: 87.45 | L17: 87.45 | M17: 87.45 | N17: 87.45 | O17: 87.45 | P17: 87.45 | Q17: 87.45 | R17: 87.45 | S17: 87.45 | T17: 87.45 | U17: 87.45 | V17: 87.45 | W17: 87.45 | X17: 87.45 | Y17: 87.45 | Z17: 87.45 | AA17: 87.45 | AB17: 87.45 | AC17: 87.45 | AD17: 87.45 | AE17: 87.45 | AF17: 87.45 | AG17: 87.45 | AH17: 87.45 | AI17: 87.45 | AJ17: 87.45 | AK17: 87.45 | AL17: 87.45 | AM17: 87.45
A18: EUR | C18: 102.86 | D18: 101 | E18: 101 | F18: 101 | G18: 101 | H18: 101 | I18: 101 | J18: 101 | K18: 101 | L18: 101 | M18: 101 | N18: 101 | O18: 101 | P18: 101 | Q18: 101 | R18: 101 | S18: 101 | T18: 101 | U18: 101 | V18: 101 | W18: 101 | X18: 101 | Y18: 101 | Z18: 101 | AA18: 101 | AB18: 101 | AC18: 101 | AD18: 101 | AE18: 101 | AF18: 101 | AG18: 101 | AH18: 101 | AI18: 101 | AJ18: 101 | AK18: 101 | AL18: 101 | AM18: 101
A19: KZT | C19: 0.1739 | D19: 0.17 | E19: 0.17 | F19: 0.17 | G19: 0.17 | H19: 0.17 | I19: 0.17 | J19: 0.17 | K19: 0.17 | L19: 0.17 | M19: 0.17 | N19: 0.17 | O19: 0.17 | P19: 0.17 | Q19: 0.17 | R19: 0.17 | S19: 0.17 | T19: 0.17 | U19: 0.17 | V19: 0.17 | W19: 0.17 | X19: 0.17 | Y19: 0.17 | Z19: 0.17 | AA19: 0.17 | AB19: 0.17 | AC19: 0.17 | AD19: 0.17 | AE19: 0.17 | AF19: 0.17 | AG19: 0.17 | AH19: 0.17 | AI19: 0.17 | AJ19: 0.17 | AK19: 0.17 | AL19: 0.17 | AM19: 0.17
A20: курсы валют
A21: RUB | D21: 1.01 | E21: 1.01 | F21: 1.01 | G21: 1.01 | H21: 1.01 | I21: 1 | J21: 1 | K21: 1 | L21: 1 | M21: 1 | N21: 1 | O21: 1 | P21: 1 | Q21: 1 | R21: 0.97 | S21: 0.97 | T21: 0.97 | U21: 0.97 | V21: 0.97 | W21: 0.97 | X21: 0.97 | Y21: 0.97 | Z21: 0.97 | AA21: 0.97 | AB21: 0.97 | AC21: 0.97 | AD21: 0.97 | AE21: 0.97 | AF21: 0.97 | AG21: 0.97 | AH21: 0.97 | AI21: 0.97 | AJ21: 0.97 | AK21: 0.97 | AL21: 0.97 | AM21: 0.97
A22: USD | D22: 87.45 | E22: 87.45 | F22: 87.45 | G22: 87.45 | H22: 87.45 | I22: 87.45 | J22: 87.45 | K22: 87.45 | L22: 87.45 | M22: 87.45 | N22: 87.45 | O22: 87.45 | P22: 87.45 | Q22: 87.45 | R22: 87.45 | S22: 87.45 | T22: 87.45 | U22: 87.45 | V22: 87.45 | W22: 87.45 | X22: 87.45 | Y22: 87.45 | Z22: 87.45 | AA22: 87.45 | AB22: 87.45 | AC22: 87.45 | AD22: 87.45 | AE22: 87.45 | AF22: 87.45 | AG22: 87.45 | AH22: 87.45 | AI22: 87.45 | AJ22: 87.45 | AK22: 87.45 | AL22: 87.45 | AM22: 87.45
A23: средний ФОТ специалистов
A24: кред.специалист (филиал) | B24: Фил | D24: 40000 | E24: 40000 | F24: 40000 | G24: 40000 | H24: 40000 | I24: 40000 | J24: 40000 | K24: 40000 | L24: 40000 | M24: 40000 | N24: 40000 | O24: 40000 | P24: 40000 | Q24: 40000 | R24: 40000 | S24: 40000 | T24: 40000 | U24: 40000 | V24: 40000 | W24: 40000 | X24: 40000 | Y24: 40000 | Z24: 40000 | AA24: 40000 | AB24: 40000 | AC24: 40000 | AD24: 40000 | AE24: 40000 | AF24: 40000 | AG24: 40000 | AH24: 40000 | AI24: 40000 | AJ24: 40000 | AK24: 40000 | AL24: 40000 | AM24: 40000
A25: нач.кред.отдела (филиал) | B25: Фил | D25: 60000 | E25: 60000 | F25: 60000 | G25: 60000 | H25: 60000 | I25: 60000 | J25: 60000 | K25: 60000 | L25: 60000 | M25: 60000 | N25: 60000 | O25: 60000 | P25: 60000 | Q25: 60000 | R25: 60000 | S25: 60000 | T25: 60000 | U25: 60000 | V25: 60000 | W25: 60000 | X25: 60000 | Y25: 60000 | Z25: 60000 | AA25: 60000 | AB25: 60000 | AC25: 60000 | AD25: 60000 | AE25: 60000 | AF25: 60000 | AG25: 60000 | AH25: 60000 | AI25: 60000 | AJ25: 60000 | AK25: 60000 | AL25: 60000 | AM25: 60000
A26: кред.администратор | B26: Фил | D26: 45000 | E26: 45000 | F26: 45000 | G26: 45000 | H26: 45000 | I26: 45000 | J26: 45000 | K26: 45000 | L26: 45000 | M26: 45000 | N26: 45000 | O26: 45000 | P26: 45000 | Q26: 45000 | R26: 45000 | S26: 45000 | T26: 45000 | U26: 45000 | V26: 45000 | W26: 45000 | X26: 45000 | Y26: 45000 | Z26: 45000 | AA26: 45000 | AB26: 45000 | AC26: 45000 | AD26: 45000 | AE26: 45000 | AF26: 45000 | AG26: 45000 | AH26: 45000 | AI26: 45000 | AJ26: 45000 | AK26: 45000 | AL26: 45000 | AM26: 45000
A27: бухгалтер | B27: Фил | D27: 45000 | E27: 45000 | F27: 45000 | G27: 45000 | H27: 45000 | I27: 45000 | J27: 45000 | K27: 45000 | L27: 45000 | M27: 45000 | N27: 45000 | O27: 45000 | P27: 45000 | Q27: 45000 | R27: 45000 | S27: 45000 | T27: 45000 | U27: 45000 | V27: 45000 | W27: 45000 | X27: 45000 | Y27: 45000 | Z27: 45000 | AA27: 45000 | AB27: 45000 | AC27: 45000 | AD27: 45000 | AE27: 45000 | AF27: 45000 | AG27: 45000 | AH27: 45000 | AI27: 45000 | AJ27: 45000 | AK27: 45000 | AL27: 45000 | AM27: 45000
A28: кассир | B28: Фил | D28: 45000 | E28: 45000 | F28: 45000 | G28: 45000 | H28: 45000 | I28: 45000 | J28: 45000 | K28: 45000 | L28: 45000 | M28: 45000 | N28: 45000 | O28: 45000 | P28: 45000 | Q28: 45000 | R28: 45000 | S28: 45000 | T28: 45000 | U28: 45000 | V28: 45000 | W28: 45000 | X28: 45000 | Y28: 45000 | Z28: 45000 | AA28: 45000 | AB28: 45000 | AC28: 45000 | AD28: 45000 | AE28: 45000 | AF28: 45000 | AG28: 45000 | AH28: 45000 | AI28: 45000 | AJ28: 45000 | AK28: 45000 | AL28: 45000 | AM28: 45000
A29: коллектор | B29: ГО | D29: 35000 | E29: 35000 | F29: 35000 | G29: 35000 | H29: 35000 | I29: 35000 | J29: 35000 | K29: 35000 | L29: 35000 | M29: 35000 | N29: 35000 | O29: 35000 | P29: 35000 | Q29: 35000 | R29: 35000 | S29: 35000 | T29: 35000 | U29: 35000 | V29: 35000 | W29: 35000 | X29: 35000 | Y29: 35000 | Z29: 35000 | AA29: 35000 | AB29: 35000 | AC29: 35000 | AD29: 35000 | AE29: 35000 | AF29: 35000 | AG29: 35000 | AH29: 35000 | AI29: 35000 | AJ29: 35000 | AK29: 35000 | AL29: 35000 | AM29: 35000
A30: операционист | B30: Фил | D30: 25000 | E30: 25000 | F30: 25000 | G30: 25000 | H30: 25000 | I30: 25000 | J30: 25000 | K30: 25000 | L30: 25000 | M30: 25000 | N30: 25000 | O30: 25000 | P30: 25000 | Q30: 25000 | R30: 25000 | S30: 25000 | T30: 25000 | U30: 25000 | V30: 25000 | W30: 25000 | X30: 25000 | Y30: 25000 | Z30: 25000 | AA30: 25000 | AB30: 25000 | AC30: 25000 | AD30: 25000 | AE30: 25000 | AF30: 25000 | AG30: 25000 | AH30: 25000 | AI30: 25000 | AJ30: 25000 | AK30: 25000 | AL30: 25000 | AM30: 25000
A31: верификатор | B31: Фил | D31: 45000 | E31: 45000 | F31: 45000 | G31: 45000 | H31: 45000 | I31: 45000 | J31: 45000 | K31: 45000 | L31: 45000 | M31: 45000 | N31: 45000 | O31: 45000 | P31: 45000 | Q31: 45000 | R31: 45000 | S31: 45000 | T31: 45000 | U31: 45000 | V31: 45000 | W31: 45000 | X31: 45000 | Y31: 45000 | Z31: 45000 | AA31: 45000 | AB31: 45000 | AC31: 45000 | AD31: 45000 | AE31: 45000 | AF31: 45000 | AG31: 45000 | AH31: 45000 | AI31: 45000 | AJ31: 45000 | AK31: 45000 | AL31: 45000 | AM31: 45000
A32: специалист отдела БК | B32: ГО | D32: 35000 | E32: 35000 | F32: 35000 | G32: 35000 | H32: 35000 | I32: 35000 | J32: 35000 | K32: 35000 | L32: 35000 | M32: 35000 | N32: 35000 | O32: 35000 | P32: 35000 | Q32: 35000 | R32: 35000 | S32: 35000 | T32: 35000 | U32: 35000 | V32: 35000 | W32: 35000 | X32: 35000 | Y32: 35000 | Z32: 35000 | AA32: 35000 | AB32: 35000 | AC32: 35000 | AD32: 35000 | AE32: 35000 | AF32: 35000 | AG32: 35000 | AH32: 35000 | AI32: 35000 | AJ32: 35000 | AK32: 35000 | AL32: 35000 | AM32: 35000
A33: курьер | B33: ГО | D33: 25000 | E33: 25000 | F33: 25000 | G33: 25000 | H33: 25000 | I33: 25000 | J33: 25000 | K33: 25000 | L33: 25000 | M33: 25000 | N33: 25000 | O33: 25000 | P33: 25000 | Q33: 25000 | R33: 25000 | S33: 25000 | T33: 25000 | U33: 25000 | V33: 25000 | W33: 25000 | X33: 25000 | Y33: 25000 | Z33: 25000 | AA33: 25000 | AB33: 25000 | AC33: 25000 | AD33: 25000 | AE33: 25000 | AF33: 25000 | AG33: 25000 | AH33: 25000 | AI33: 25000 | AJ33: 25000 | AK33: 25000 | AL33: 25000 | AM33: 25000
A34: комплайнс | B34: ГО | D34: 45000 | E34: 45000 | F34: 45000 | G34: 45000 | H34: 45000 | I34: 45000 | J34: 45000 | K34: 45000 | L34: 45000 | M34: 45000 | N34: 45000 | O34: 45000 | P34: 45000 | Q34: 45000 | R34: 45000 | S34: 45000 | T34: 45000 | U34: 45000 | V34: 45000 | W34: 45000 | X34: 45000 | Y34: 45000 | Z34: 45000 | AA34: 45000 | AB34: 45000 | AC34: 45000 | AD34: 45000 | AE34: 45000 | AF34: 45000 | AG34: 45000 | AH34: 45000 | AI34: 45000 | AJ34: 45000 | AK34: 45000 | AL34: 45000 | AM34: 45000
A35: бэк-офис | B35: ГО | D35: 45000 | E35: 45000 | F35: 45000 | G35: 45000 | H35: 45000 | I35: 45000 | J35: 45000 | K35: 45000 | L35: 45000 | M35: 45000 | N35: 45000 | O35: 45000 | P35: 45000 | Q35: 45000 | R35: 45000 | S35: 45000 | T35: 45000 | U35: 45000 | V35: 45000 | W35: 45000 | X35: 45000 | Y35: 45000 | Z35: 45000 | AA35: 45000 | AB35: 45000 | AC35: 45000 | AD35: 45000 | AE35: 45000 | AF35: 45000 | AG35: 45000 | AH35: 45000 | AI35: 45000 | AJ35: 45000 | AK35: 45000 | AL35: 45000 | AM35: 45000
... A43: юрист | B43: Фил | D43: 30000 | E43: 30000 | F43: 30000 | G43: 30000 | H43: 30000 | I43: 30000 | J43: 30000 | K43: 30000 | L43: 30000 | M43: 30000 | N43: 30000 | O43: 30000 | P43: 30000 | Q43: 30000 | R43: 30000 | S43: 30000 | T43: 30000 | U43: 30000 | V43: 30000 | W43: 30000 | X43: 30000 | Y43: 30000 | Z43: 30000 | AA43: 30000 | AB43: 30000 | AC43: 30000 | AD43: 30000 | AE43: 30000 | AF43: 30000 | AG43: 30000 | AH43: 30000 | AI43: 30000 | AJ43: 30000 | AK43: 30000 | AL43: 30000 | AM43: 30000

Sheet РБ>>>
F5: Розничный бизнес
F7: РБ.1 | G7: Кредиты
F8: РБ.2 | G8: Счета и депозиты
F9: РБ.3 | G9: Обслуживание клиентов

Sheet РБ.1
A1: Розничный бизнес - Кредиты
D3: 46023 | E3: 46054 | F3: 46082 | G3: 46113 | H3: 46143 | I3: 46174 | J3: 46204 | K3: 46235 | L3: 46266 | M3: 46296 | N3: 46327 | O3: 46357 | P3: 46388 | Q3: 46419 | R3: 46447 | S3: 46478 | T3: 46508 | U3: 46539 | V3: 46569 | W3: 46600 | X3: 46631 | Y3: 46661 | Z3: 46692 | AA3: 46722 | AB3: 46753 | AC3: 46784 | AD3: 46813 | AE3: 46844 | AF3: 46874 | AG3: 46905 | AH3: 46935 | AI3: 46966 | AJ3: 46997 | AK3: 47027 | AL3: 47058 | AM3: 47088 | AO3: =YEAR(O3) -> 2026 | AP3: =YEAR(AA3) -> 2027 | AQ3: =YEAR(AM3) -> 2028
D4: m1 | E4: m2 | F4: m3 | G4: m4 | H4: m5 | I4: m6 | J4: m7 | K4: m8 | L4: m9 | M4: m10 | N4: m11 | O4: m12 | P4: m13 | Q4: m14 | R4: m15 | S4: m16 | T4: m17 | U4: m18 | V4: m19 | W4: m20 | X4: m21 | Y4: m22 | Z4: m23 | AA4: m24 | AB4: m25 | AC4: m26 | AD4: m27 | AE4: m28 | AF4: m29 | AG4: m30 | AH4: m31 | AI4: m32 | AJ4: m33 | AK4: m34 | AL4: m35 | AM4: m36 | AO4: Y1 | AP4: Y2 | AQ4: Y3
D5: 1 | E5: =D5+1 -> 2 | F5: =E5+1 -> 3 | G5: =F5+1 -> 4 | H5: =G5+1 -> 5 | I5: =H5+1 -> 6 | J5: =I5+1 -> 7 | K5: =J5+1 -> 8 | L5: =K5+1 -> 9 | ... AM5: =AL5+1 -> 36
A7: сезонность | B7: % | D7: 0.4 | E7: 0.8 | F7: 1 | G7: 1 | H7: 0.4 | I7: 1 | J7: 1 | K7: 0.7 | L7: 1 | M7: 1 | N7: 0.9 | O7: 0.8 | P7: 0.4 | Q7: 0.8 | R7: 1 | S7: 1 | T7: 0.4 | U7: 1 | V7: 1 | W7: 0.7 | X7: 1 | Y7: 1 | Z7: 0.9 | AA7: 0.8 | AB7: 0.4 | AC7: 0.8 | AD7: 1 | AE7: 1 | AF7: 0.4 | AG7: 1 | AH7: 1 | AI7: 0.7 | AJ7: 1 | AK7: 1 | AL7: 0.9 | AM7: 0.8
A8: Итого
A9: количество заявок | B9: шт | D9: =D53+D165+D235+D289 -> 409.5 | E9: =E53+E165+E235+E289 -> 644.9625 | F9: =F53+F165+F235+F289 -> 761.86195 | G9: =G53+G165+G235+G289 -> 760.75725 | H9: =H53+H165+H235+H289 -> 287.43794 | I9: =I53+I165+I235+I289 -> 678.77207 | J9: =J53+J165+J235+J289 -> 641.15888 | K9: =K53+K165+K235+K289 -> 597.12969 | ... AM9: =AM53+AM165+AM235+AM289 -> 684 | AO9: =SUM(D9:O9) -> 7671.5831 | AP9: =SUM(P9:AA9) -> 8020 | AQ9: =SUM(AB9:AM9) -> 8490
A10: количество кредитных специалистов | B10: чел | D10: ='0'!D14 -> 130 | E10: ='0'!E14 -> 122.85 | F10: ='0'!F14 -> 116.09325 | G10: ='0'!G14 -> 109.70812 | H10: ='0'!H14 -> 103.67417 | I10: ='0'!I14 -> 97.972095 | J10: ='0'!J14 -> 92.58363 | K10: ='0'!K14 -> 87.49153 | ... AM10: ='0'!AM14 -> 80
A11: количество заявок на 1 специалиста | B11: шт | D11: =D9/D10 -> 3.15 | E11: =E9/E10 -> 5.25 | F11: =F9/F10 -> 6.5625 | G11: =G9/G10 -> 6.934375 | H11: =H9/H10 -> 2.7725125 | I11: =I9/I10 -> 6.9282184 | J11: =J9/J10 -> 6.9251863 | K11: =K9/K10 -> 6.825 | ... AM11: =AM9/AM10 -> 8.55
A12: выдачи | B12: тыс сом | D12: =D57+D117+D169+D239+D293 -> 54632.5 | E12: =E57+E117+E169+E239+E293 -> 63567.504 | F12: =F57+F117+F169+F239+F293 -> 75008.661 | G12: =G57+G117+G169+G239+G293 -> 91920.784 | H12: =H57+H117+H169+H239+H293 -> 34690.565 | I12: =I57+I117+I169+I239+I293 -> 81827.972 | J12: =J57+J117+J169+J239+J293 -> 77208.428 | K12: =K57+K117+K169+K239+K293 -> 107133.86 | ... AM12: =AM57+AM117+AM169+AM239+AM293 -> 147674.44 | AO12: =SUM(D12:O12) -> 1094810.7 | AP12: =SUM(P12:AA12) -> 1507165.2 | AQ12: =SUM(AB12:AM12) -> 1812602.9
A13: погашения | B13: тыс сом | D13: =D59+D84*'0'!D17+D119+D171+D241+D295 -> 392788.71 | E13: =E59+E84*'0'!E17+E119+E171+E241+E295 -> 391066.53 | F13: =F59+F84*'0'!F17+F119+F171+F241+F295 -> 389988.05 | G13: =G59+G84*'0'!G17+G119+G171+G241+G295 -> 389159.12 | H13: =H59+H84*'0'!H17+H119+H171+H241+H295 -> 388154.03 | I13: =I59+I84*'0'!I17+I119+I171+I241+I295 -> 383953.97 | J13: =J59+J84*'0'!J17+J119+J171+J241+J295 -> 373597.7 | K13: =K59+K84*'0'!K17+K119+K171+K241+K295 -> 363457.06 | ... AM13: =AM59+AM84*'0'!AM17+AM119+AM171+AM241+AM295 -> 241857.18 | AO13: =SUM(D13:O13) -> 4455010.3 | AP13: =SUM(P13:AA13) -> 3432754.3 | AQ13: =SUM(AB13:AM13) -> 2975417.2
A14: кредитный портфель | B14: тыс сом | C14: =C28+C172+C201+C220+C296 -> 5685987.9 | D14: =D28+D172+D201+D220+D296 -> 5527478.6 | E14: =E28+E172+E201+E220+E296 -> 5376030.3 | F14: =F28+F172+F201+F220+F296 -> 5233580.6 | G14: =G28+G172+G201+G220+G296 -> 5105421.4 | H14: =H28+H172+H201+H220+H296 -> 4917655.5 | I14: =I28+I172+I201+I220+I296 -> 4777913.1 | J14: =J28+J172+J201+J220+J296 -> 4640659.7 | ... AM14: =AM28+AM172+AM201+AM220+AM296 -> 3879261.2 | AO14: =O14 -> 4259504.8 | AP14: =AA14 -> 3851332.9 | AQ14: =AM14 -> 3879261.2
A15: просроченная задолженность | B15: тыс сом | D15: =D29+D174+D203+D221+D298 -> 48122.61 | E15: =E29+E174+E203+E221+E298 -> 46738.663 | F15: =F29+F174+F203+F221+F298 -> 45449.791 | G15: =G29+G174+G203+G221+G298 -> 44173.379 | H15: =H29+H174+H203+H221+H298 -> 42319.441 | I15: =I29+I174+I203+I221+I298 -> 40923.175 | J15: =J29+J174+J203+J221+J298 -> 39556.849 | K15: =K29+K174+K203+K221+K298 -> 38621.409 | ... AM15: =AM29+AM174+AM203+AM221+AM298 -> 34510.057 | AO15: =O15 -> 36103.132 | AP15: =AA15 -> 33100.204 | AQ15: =AM15 -> 34510.057
A16: РППУ на конец месяца | B16: тыс сом | D16: =D30+D179+D208+D222+D303 -> -180176.5 | E16: =E30+E179+E208+E222+E303 -> -173027.53 | F16: =F30+F179+F208+F222+F303 -> -166079.33 | G16: =G30+G179+G208+G222+G303 -> -159707.08 | H16: =H30+H179+H208+H222+H303 -> -152225.47 | I16: =I30+I179+I208+I222+I303 -> -145741.96 | J16: =J30+J179+J208+J222+J303 -> -139527.34 | K16: =K30+K179+K208+K222+K303 -> -135145.82 | ... AM16: =AM30+AM179+AM208+AM222+AM303 -> -119122.93 | AO16: =O16 -> -121758.11 | AP16: =AA16 -> -115906.67 | AQ16: =AM16 -> -119122.93
A17: % доход | B17: тыс сом | D17: =D31+D180+D209+D223+D304 -> 109670.06 | E17: =E31+E180+E209+E223+E304 -> 106890.47 | F17: =F31+F180+F209+F223+F304 -> 104308.46 | G17: =G31+G180+G209+G223+G304 -> 101934.03 | H17: =H31+H180+H209+H223+H304 -> 99047.58 | I17: =I31+I180+I209+I223+I304 -> 96034.878 | J17: =J31+J180+J209+J223+J304 -> 93544.204 | K17: =K31+K180+K209+K223+K304 -> 91426.291 | ... AM17: =AM31+AM180+AM209+AM223+AM304 -> 79677.03 | AO17: =SUM(D17:O17) -> 1156614.5 | AP17: =SUM(P17:AA17) -> 972895.92 | AQ17: =SUM(AB17:AM17) -> 939147.16
A18: трансфертный расход | B18: тыс сом | D18: =D32+D181+D210+D224+D305 -> -70017.426 | E18: =E32+E181+E210+E224+E305 -> -68081.506 | F18: =F32+F181+F210+F224+F305 -> -66245.952 | G18: =G32+G181+G210+G224+G305 -> -64555.929 | H18: =H32+H181+H210+H224+H305 -> -62582.654 | I18: =I32+I181+I210+I224+I305 -> -60536.958 | J18: =J32+J181+J210+J224+J305 -> -58806.942 | K18: =K32+K181+K210+K224+K305 -> -57322.979 | ... AM18: =AM32+AM181+AM210+AM224+AM305 -> -48492.879 | AO18: =SUM(D18:O18) -> -728436.13 | AP18: =SUM(P18:AA18) -> -594559.87 | AQ18: =SUM(AB18:AM18) -> -571188.68
A19: расходы на провизии | B19: тыс сом | D19: =D33+D182+D211+D225+D306 -> 15693.32 | E19: =E33+E182+E211+E225+E306 -> 7148.9765 | F19: =F33+F182+F211+F225+F306 -> 6948.1988 | G19: =G33+G182+G211+G225+G306 -> 6372.2512 | H19: =H33+H182+H211+H225+H306 -> 7481.6099 | I19: =I33+I182+I211+I225+I306 -> 6483.5012 | J19: =J33+J182+J211+J225+J306 -> 6214.6232 | K19: =K33+K182+K211+K225+K306 -> 4381.5239 | ... AM19: =AM33+AM182+AM211+AM225+AM306 -> -7.4729162 | AO19: =SUM(D19:O19) -> 74111.708 | AP19: =SUM(P19:AA19) -> 5851.4416 | AQ19: =SUM(AB19:AM19) -> -3216.2606
A20: комиссии | B20: тыс сом | D20: =D34+D183+D212+D226+D307 -> 0 | E20: =E34+E183+E212+E226+E307 -> 0 | F20: =F34+F183+F212+F226+F307 -> 0 | G20: =G34+G183+G212+G226+G307 -> 0 | H20: =H34+H183+H212+H226+H307 -> 0 | I20: =I34+I183+I212+I226+I307 -> 0 | J20: =J34+J183+J212+J226+J307 -> 0 | K20: =K34+K183+K212+K226+K307 -> 0 | ... AM20: =AM34+AM183+AM212+AM226+AM307 -> 0 | AO20: =SUM(D20:O20) -> 0 | AP20: =SUM(P20:AA20) -> 0 | AQ20: =SUM(AB20:AM20) -> 0
A21: операционные доходы | B21: тыс сом | D21: =D35+D184+D213+D227+D308 -> 55345.955 | E21: =E35+E184+E213+E227+E308 -> 45957.944 | F21: =F35+F184+F213+F227+F308 -> 45010.71 | G21: =G35+G184+G213+G227+G308 -> 43750.351 | H21: =H35+H184+H213+H227+H308 -> 43946.536 | I21: =I35+I184+I213+I227+I308 -> 41981.421 | J21: =J35+J184+J213+J227+J308 -> 40951.885 | K21: =K35+K184+K213+K227+K308 -> 38484.836 | ... AM21: =AM35+AM184+AM213+AM227+AM308 -> 31176.679 | AO21: =SUM(D21:O21) -> 502290.09 | AP21: =SUM(P21:AA21) -> 384187.49 | AQ21: =SUM(AB21:AM21) -> 364742.22
A22: операционные расходы | B22: тыс сом | D22: =D36+D185+D214+D228+D309 -> -803.65559 | E22: =E36+E185+E214+E228+E309 -> -999.82289 | F22: =F36+F185+F214+F228+F309 -> -1094.9488 | G22: =G36+G185+G214+G228+G309 -> -1089.4638 | H22: =H36+H185+H214+H228+H309 -> -678.92394 | I22: =I36+I185+I214+I228+I309 -> -999.89602 | J22: =J36+J185+J214+J228+J309 -> -962.0376 | K22: =K36+K185+K214+K228+K309 -> -835.15488 | ... AM22: =AM36+AM185+AM214+AM228+AM309 -> -886.25094 | AO22: =SUM(D22:O22) -> -11198.644 | AP22: =SUM(P22:AA22) -> -10487.985 | AQ22: =SUM(AB22:AM22) -> -10792.926
A23: прибыль | B23: тыс сом | D23: =D37+D186+D215+D229+D310 -> 54542.299 | E23: =E37+E186+E215+E229+E310 -> 44958.122 | F23: =F37+F186+F215+F229+F310 -> 43915.761 | G23: =G37+G186+G215+G229+G310 -> 42660.887 | H23: =H37+H186+H215+H229+H310 -> 43267.612 | I23: =I37+I186+I215+I229+I310 -> 40981.525 | J23: =J37+J186+J215+J229+J310 -> 39989.847 | K23: =K37+K186+K215+K229+K310 -> 37649.681 | ... AM23: =AM37+AM186+AM215+AM229+AM310 -> 30290.428 | AO23: =SUM(D23:O23) -> 491091.44 | AP23: =SUM(P23:AA23) -> 373699.5 | AQ23: =SUM(AB23:AM23) -> 353949.29
A25: Потребительский кредит
A26: Итого
A27: количество кредитов | B27: шт | D27: =D39+D101 -> 9409 | E27: =E39+E101 -> 9022 | F27: =F39+F101 -> 8634 | G27: =G39+G101 -> 8243 | H27: =H39+H101 -> 7839 | I27: =I39+I101 -> 7444 | J27: =J39+J101 -> 7068 | K27: =K39+K101 -> 4670 | ... AM27: =AM39+AM101 -> 3560 | AO27: =O27 -> 4211 | AP27: =AA27 -> 3671 | AQ27: =AM27 -> 3560
A28: кредитный портфель | B28: тыс сом | C28: =C40+C102 -> 3770987.9 | D28: =D40+D102 -> 3628621.3 | E28: =E40+E102 -> 3476492.3 | F28: =F40+F102 -> 3324180.2 | G28: =G40+G102 -> 3170250.9 | H28: =H40+H102 -> 3011065.7 | I28: =I40+I102 -> 2855528.7 | J28: =J40+J102 -> 2707894.6 | ... AM28: =AM40+AM102 -> 2203541.7 | AO28: =O28 -> 2360876.5 | AP28: =AA28 -> 2072616.9 | AQ28: =AM28 -> 2203541.7
A29: просроченная задолженность | B29: тыс сом | D29: =D41+D103 -> 39300.794 | E29: =E41+E103 -> 37651.021 | F29: =F41+F103 -> 35999.222 | G29: =G41+G103 -> 34329.826 | H29: =H41+H103 -> 32603.331 | I29: =I41+I103 -> 30916.409 | J29: =J41+J103 -> 29315.253 | K29: =K41+K103 -> 28387.433 | ... AM29: =AM41+AM103 -> 23876.997 | AO29: =O29 -> 25555.771 | AP29: =AA29 -> 22442.586 | AQ29: =AM29 -> 23876.997
A30: РППУ на конец месяца | B30: тыс сом | D30: =D42+D104 -> -142466.61 | E30: =E42+E104 -> -135803.5 | F30: =F42+F104 -> -129194.12 | G30: =G42+G104 -> -122583.2 | H30: =H42+H104 -> -115831.92 | I30: =I42+I104 -> -109283.75 | J30: =J42+J104 -> -103098.24 | K30: =K42+K104 -> -99186.686 | ... AM30: =AM42+AM104 -> -86497.895 | AO30: =O30 -> -86948.494 | AP30: =AA30 -> -81383.596 | AQ30: =AM30 -> -86497.895
A31: % доход | B31: тыс сом | D31: =D43+D105 -> 73965.676 | E31: =E43+E105 -> 71020.1 | F31: =F43+F105 -> 67974.983 | G31: =G43+G105 -> 64911.812 | H31: =H43+H105 -> 61779.82 | I31: =I43+I105 -> 58631.705 | J31: =J43+J105 -> 55599.16 | K31: =K43+K105 -> 53266.391 | ... AM31: =AM43+AM105 -> 44010.099 | AO31: =SUM(D31:O31) -> 706626.92 | AP31: =SUM(P31:AA31) -> 514499.52 | AQ31: =SUM(AB31:AM31) -> 503889.33
A32: трансфертный расход | B32: тыс сом | D32: =D44+D106 -> -46180.819 | E32: =E44+E106 -> -44341.536 | F32: =F44+F106 -> -42440.088 | G32: =G44+G106 -> -40527.361 | H32: =H44+H106 -> -38571.652 | I32: =I44+I106 -> -36605.87 | J32: =J44+J106 -> -34712.257 | K32: =K44+K106 -> -33255.644 | ... AM32: =AM44+AM106 -> -27478.931 | AO32: =SUM(D32:O32) -> -441173.76 | AP32: =SUM(P32:AA32) -> -321215.31 | AQ32: =SUM(AB32:AM32) -> -314607.52
A33: расходы на провизии | B33: тыс сом | D33: =D45+D107 -> 18800.208 | E33: =E45+E107 -> 6663.1133 | F33: =F45+F107 -> 6609.3772 | G33: =G45+G107 -> 6610.9187 | H33: =H45+H107 -> 6751.2799 | I33: =I45+I107 -> 6548.1791 | J33: =J45+J107 -> 6185.5042 | K33: =K45+K107 -> 3911.5553 | ... AM33: =AM45+AM107 -> -201.92895 | AO33: =SUM(D33:O33) -> 74318.328 | AP33: =SUM(P33:AA33) -> 5564.8975 | AQ33: =SUM(AB33:AM33) -> -5114.2988
A34: комиссии | B34: тыс сом | D34: =D46+D108 -> 0 | E34: =E46+E108 -> 0 | F34: =F46+F108 -> 0 | G34: =G46+G108 -> 0 | H34: =H46+H108 -> 0 | I34: =I46+I108 -> 0 | J34: =J46+J108 -> 0 | K34: =K46+K108 -> 0 | ... AM34: =AM46+AM108 -> 0 | AO34: =SUM(D34:O34) -> 0 | AP34: =SUM(P34:AA34) -> 0 | AQ34: =SUM(AB34:AM34) -> 0
A35: операционные доходы | B35: тыс сом | D35: =D47+D109 -> 46585.066 | E35: =E47+E109 -> 33341.677 | F35: =F47+F109 -> 32144.273 | G35: =G47+G109 -> 30995.37 | H35: =H47+H109 -> 29959.448 | I35: =I47+I109 -> 28574.014 | J35: =J47+J109 -> 27072.407 | K35: =K47+K109 -> 23922.302 | ... AM35: =AM47+AM109 -> 16329.239 | AO35: =SUM(D35:O35) -> 339771.5 | AP35: =SUM(P35:AA35) -> 198849.11 | AQ35: =SUM(AB35:AM35) -> 184167.51
A36: операционные расходы | B36: тыс сом | D36: =D48+D110 -> -347.31558 | E36: =E48+E110 -> -308.76901 | F36: =F48+F110 -> -300.67668 | G36: =G48+G110 -> -286.46425 | H36: =H48+H110 -> -257.53088 | I36: =I48+I110 -> -257.86527 | J36: =J48+J110 -> -244.47459 | K36: =K48+K110 -> -291.59112 | ... AM36: =AM48+AM110 -> -313.64971 | AO36: =SUM(D36:O36) -> -3531.0185 | AP36: =SUM(P36:AA36) -> -3509.5309 | AQ36: =SUM(AB36:AM36) -> -3784.4908
A37: прибыль | B37: тыс сом | D37: =D49+D111 -> 46237.75 | E37: =E49+E111 -> 33032.908 | F37: =F49+F111 -> 31843.596 | G37: =G49+G111 -> 30708.906 | H37: =H49+H111 -> 29701.918 | I37: =I49+I111 -> 28316.149 | J37: =J49+J111 -> 26827.932 | K37: =K49+K111 -> 23630.711 | ... AM37: =AM49+AM111 -> 16015.589 | AO37: =SUM(D37:O37) -> 336240.48 | AP37: =SUM(P37:AA37) -> 195339.58 | AQ37: =SUM(AB37:AM37) -> 180383.02
A38: Безбумажный офис
A39: количество кредитов | B39: шт | D39: =INT(D60/D56+D85/D81) -> 9409 | E39: =INT(E60/E56+E85/E81) -> 9022 | F39: =INT(F60/F56+F85/F81) -> 8634 | G39: =INT(G60/G56+G85/G81) -> 8243 | H39: =INT(H60/H56+H85/H81) -> 7839 | I39: =INT(I60/I56+I85/I81) -> 7444 | J39: =INT(J60/J56+J85/J81) -> 7068 | K39: =INT(K60/K56+K85/K81) -> 4670 | ... AM39: =INT(AM60/AM56+AM85/AM81) -> 3560 | AO39: =O39 -> 4211 | AP39: =AA39 -> 3671 | AQ39: =AM39 -> 3560
A40: кредитный портфель | B40: тыс сом | C40: =C60+C85*'0'!C17/1000 -> 3770987.9 | D40: =D60+D85*'0'!D17/1000 -> 3628621.3 | E40: =E60+E85*'0'!E17/1000 -> 3476492.3 | F40: =F60+F85*'0'!F17/1000 -> 3324180.2 | G40: =G60+G85*'0'!G17/1000 -> 3170250.9 | H40: =H60+H85*'0'!H17/1000 -> 3011065.7 | I40: =I60+I85*'0'!I17/1000 -> 2855528.7 | J40: =J60+J85*'0'!J17/1000 -> 2707894.6 | ... AM40: =AM60+AM85*'0'!AM17/1000 -> 2203541.7 | AO40: =O40 -> 2360876.5 | AP40: =AA40 -> 2072616.9 | AQ40: =AM40 -> 2203541.7
A41: просроченная задолженность | B41: тыс сом | D41: =D62+D87*'0'!D17/1000 -> 39300.794 | E41: =E62+E87*'0'!E17/1000 -> 37651.021 | F41: =F62+F87*'0'!F17/1000 -> 35999.222 | G41: =G62+G87*'0'!G17/1000 -> 34329.826 | H41: =H62+H87*'0'!H17/1000 -> 32603.331 | I41: =I62+I87*'0'!I17/1000 -> 30916.409 | J41: =J62+J87*'0'!J17/1000 -> 29315.253 | K41: =K62+K87*'0'!K17/1000 -> 28387.433 | ... AM41: =AM62+AM87*'0'!AM17/1000 -> 23876.997 | AO41: =O41 -> 25555.771 | AP41: =AA41 -> 22442.586 | AQ41: =AM41 -> 23876.997
A42: РППУ на конец месяца | B42: тыс сом | D42: =D67+D92*'0'!D$17/1000 -> -142466.61 | E42: =E67+E92*'0'!E$17/1000 -> -135803.5 | F42: =F67+F92*'0'!F$17/1000 -> -129194.12 | G42: =G67+G92*'0'!G$17/1000 -> -122583.2 | H42: =H67+H92*'0'!H$17/1000 -> -115831.92 | I42: =I67+I92*'0'!I$17/1000 -> -109283.75 | J42: =J67+J92*'0'!J$17/1000 -> -103098.24 | K42: =K67+K92*'0'!K$17/1000 -> -99186.686 | ... AM42: =AM67+AM92*'0'!AM$17/1000 -> -86497.895 | AO42: =O42 -> -86948.494 | AP42: =AA42 -> -81383.596 | AQ42: =AM42 -> -86497.895
A43: % доход | B43: тыс сом | D43: =D68+D93*'0'!D$17/1000 -> 73965.676 | E43: =E68+E93*'0'!E$17/1000 -> 71020.1 | F43: =F68+F93*'0'!F$17/1000 -> 67974.983 | G43: =G68+G93*'0'!G$17/1000 -> 64911.812 | H43: =H68+H93*'0'!H$17/1000 -> 61779.82 | I43: =I68+I93*'0'!I$17/1000 -> 58631.705 | J43: =J68+J93*'0'!J$17/1000 -> 55599.16 | K43: =K68+K93*'0'!K$17/1000 -> 53266.391 | ... AM43: =AM68+AM93*'0'!AM$17/1000 -> 44010.099 | AO43: =SUM(D43:O43) -> 706626.92 | AP43: =SUM(P43:AA43) -> 514499.52 | AQ43: =SUM(AB43:AM43) -> 503889.33
...

Sheet РБ.2
A1: Розничный бизнес - Счета и депозиты
D3: 46023 | E3: 46054 | F3: 46082 | G3: 46113 | H3: 46143 | I3: 46174 | J3: 46204 | K3: 46235 | L3: 46266 | M3: 46296 | N3: 46327 | O3: 46357 | P3: 46388 | Q3: 46419 | R3: 46447 | S3: 46478 | T3: 46508 | U3: 46539 | V3: 46569 | W3: 46600 | X3: 46631 | Y3: 46661 | Z3: 46692 | AA3: 46722 | AB3: 46753 | AC3: 46784 | AD3: 46813 | AE3: 46844 | AF3: 46874 | AG3: 46905 | AH3: 46935 | AI3: 46966 | AJ3: 46997 | AK3: 47027 | AL3: 47058 | AM3: 47088 | AO3: =YEAR(O3) -> 2026 | AP3: =YEAR(AA3) -> 2027 | AQ3: =YEAR(AM3) -> 2028
D4: m1 | E4: m2 | F4: m3 | G4: m4 | H4: m5 | I4: m6 | J4: m7 | K4: m8 | L4: m9 | M4: m10 | N4: m11 | O4: m12 | P4: m13 | Q4: m14 | R4: m15 | S4: m16 | T4: m17 | U4: m18 | V4: m19 | W4: m20 | X4: m21 | Y4: m22 | Z4: m23 | AA4: m24 | AB4: m25 | AC4: m26 | AD4: m27 | AE4: m28 | AF4: m29 | AG4: m30 | AH4: m31 | AI4: m32 | AJ4: m33 | AK4: m34 | AL4: m35 | AM4: m36 | AO4: Y1 | AP4: Y2 | AQ4: Y3
D5: 1 | E5: =D5+1 -> 2 | F5: =E5+1 -> 3 | G5: =F5+1 -> 4 | H5: =G5+1 -> 5 | I5: =H5+1 -> 6 | J5: =I5+1 -> 7 | K5: =J5+1 -> 8 | L5: =K5+1 -> 9 | ... AM5: =AL5+1 -> 36
A6: сезонность | B6: % | D6: 0.4 | E6: 0.8 | F6: 1 | G6: 1 | H6: 1 | I6: 1 | J6: 1 | K6: 0.7 | L6: 1 | M6: 1 | N6: 0.9 | O6: 0.8 | P6: 0.4 | Q6: 0.8 | R6: 1 | S6: 1 | T6: 1 | U6: 1 | V6: 1 | W6: 0.7 | X6: 1 | Y6: 1 | Z6: 0.9 | AA6: 0.8 | AB6: 0.4 | AC6: 0.8 | AD6: 1 | AE6: 1 | AF6: 1 | AG6: 1 | AH6: 1 | AI6: 0.7 | AJ6: 1 | AK6: 1 | AL6: 0.9 | AM6: 0.8
A7: Итого
A8: портфель | B8: тыс сом | C8: =C18+C160+C204+C246+C378 -> 7154435.2 | D8: =D18+D160+D204+D246+D378 -> 7432358 | E8: =E18+E160+E204+E246+E378 -> 7486074.6 | F8: =F18+F160+F204+F246+F378 -> 7551198.3 | G8: =G18+G160+G204+G246+G378 -> 7625873.6 | H8: =H18+H160+H204+H246+H378 -> 7710566.2 | I8: =I18+I160+I204+I246+I378 -> 7802758 | J8: =J18+J160+J204+J246+J378 -> 7906893.5 | ... AM8: =AM18+AM160+AM204+AM246+AM378 -> 16073930 | AO8: =O8 -> 8568555.8 | AP8: =AA8 -> 11071363 | AQ8: =AM8 -> 16073930
A9: % расход | B9: тыс сом | D9: =D19+D161+D205+D247+D379 -> -67435.52 | E9: =E19+E161+E205+E247+E379 -> -67604.099 | F9: =F19+F161+F205+F247+F379 -> -68153.559 | G9: =G19+G161+G205+G247+G379 -> -68795.023 | H9: =H19+H161+H205+H247+H379 -> -69529.765 | I9: =I19+I161+I205+I247+I379 -> -70341.068 | J9: =J19+J161+J205+J247+J379 -> -71262.826 | K9: =K19+K161+K205+K247+K379 -> -72275.84 | ... AM9: =AM19+AM161+AM205+AM247+AM379 -> -141740.01 | AO9: =SUM(D9:O9) -> -856526.77 | AP9: =SUM(P9:AA9) -> -1060691.3 | AQ9: =SUM(AB9:AM9) -> -1447193.9
A10: трансфертный доход | B10: тыс сом | D10: =D20+D162+D206+D248+D380 -> 81475.629 | E10: =E20+E162+E206+E248+E380 -> 82492.427 | F10: =F20+F162+F206+F248+F380 -> 83198.783 | G10: =G20+G162+G206+G248+G380 -> 84017.909 | H10: =H20+H162+H206+H248+H380 -> 84948.685 | I10: =I20+I162+I206+I248+I380 -> 85973.63 | J10: =J20+J162+J206+J248+J380 -> 87126.21 | K10: =K20+K162+K206+K248+K380 -> 88375.472 | ... AM10: =AM20+AM162+AM206+AM248+AM380 -> 176292.38 | AO10: =SUM(D10:O10) -> 1045965.4 | AP10: =SUM(P10:AA10) -> 1299529.3 | AQ10: =SUM(AB10:AM10) -> 1786557.9
A11: операционные доходы | B11: тыс сом | D11: =D21+D163+D207+D249+D381 -> 14040.109 | E11: =E21+E163+E207+E249+E381 -> 14888.328 | F11: =F21+F163+F207+F249+F381 -> 15045.224 | G11: =G21+G163+G207+G249+G381 -> 15222.886 | H11: =H21+H163+H207+H249+H381 -> 15418.92 | I11: =I21+I163+I207+I249+I381 -> 15632.562 | J11: =J21+J163+J207+J249+J381 -> 15863.385 | K11: =K21+K163+K207+K249+K381 -> 16099.632 | ... AM11: =AM21+AM163+AM207+AM249+AM381 -> 34552.368 | AO11: =SUM(D11:O11) -> 189438.62 | AP11: =SUM(P11:AA11) -> 238838.06 | AQ11: =SUM(AB11:AM11) -> 339363.99
A12: начисление расходов в ФЗД | B12: тыс сом | D12: =D22+D164+D208+D250+D382 -> -1215.5661 | E12: =E22+E164+E208+E250+E382 -> -1243.2027 | F12: =F22+F164+F208+F250+F382 -> -1253.1061 | G12: =G22+G164+G208+G250+G382 -> -1264.756 | H12: =H22+H164+H208+H250+H382 -> -1278.0366 | I12: =I22+I164+I208+I250+I382 -> -1292.777 | J12: =J22+J164+J208+J250+J382 -> -1309.1376 | K12: =K22+K164+K208+K250+K382 -> -1326.8376 | ... AM12: =AM22+AM164+AM208+AM250+AM382 -> -2632.9423 | AO12: =SUM(D12:O12) -> -15703.491 | AP12: =SUM(P12:AA12) -> -19357.025 | AQ12: =SUM(AB12:AM12) -> -26557.707
A13: операционные расходы | B13: тыс сом | D13: =D23+D165+D209+D251+D383 -> -1645.2759 | E13: =E23+E165+E209+E251+E383 -> -1622.242 | F13: =F23+F165+F209+F251+F383 -> -1639.4697 | G13: =G23+G165+G209+G251+G383 -> -1658.6417 | H13: =H23+H165+H209+H251+H383 -> -1679.8174 | I13: =I23+I165+I209+I251+I383 -> -1702.647 | J13: =J23+J165+J209+J251+J383 -> -1727.5056 | K13: =K23+K165+K209+K251+K383 -> -1754.0996 | ... AM13: =AM23+AM165+AM209+AM251+AM383 -> -3395.1994 | AO13: =SUM(D13:O13) -> -20760.379 | AP13: =SUM(P13:AA13) -> -25768.799 | AQ13: =SUM(AB13:AM13) -> -34732.723
A14: прибыль | B14: тыс сом | D14: =D24+D166+D210+D252+D384 -> 12154.963 | E14: =E24+E166+E210+E252+E384 -> 13021.748 | F14: =F24+F166+F210+F252+F384 -> 13155.649 | G14: =G24+G166+G210+G252+G384 -> 13308.486 | H14: =H24+H166+H210+H252+H384 -> 13477.819 | I14: =I24+I166+I210+I252+I384 -> 13663.254 | J14: =J24+J166+J210+J252+J384 -> 13863.933 | K14: =K24+K166+K210+K252+K384 -> 14068.49 | ... AM14: =AM24+AM166+AM210+AM252+AM384 -> 30783.902 | AO14: =SUM(D14:O14) -> 165456.05 | AP14: =SUM(P14:AA14) -> 209291.89 | AQ14: =SUM(AB14:AM14) -> 300436
A16: Универсальный депозит "Бай Бол"
A17: Итого
A18: портфель | B18: тыс сом | C18: =C26+C92 -> 4767893.2 | D18: =D26+D92 -> 4707639.8 | E18: =E26+E92 -> 4713311.7 | F18: =F26+F92 -> 4728678.6 | G18: =G26+G92 -> 4753302.3 | H18: =H26+H92 -> 4788626.7 | I18: =I26+I92 -> 4831453.5 | J18: =J26+J92 -> 4885880 | ... AM18: =AM26+AM92 -> 11047443 | AO18: =O18 -> 5313921.6 | AP18: =AA18 -> 7278477.1 | AQ18: =AM18 -> 11047443
A19: % расход | B19: тыс сом | D19: =D27+D93 -> -50644.593 | E19: =E27+E93 -> -50500.482 | F19: =F27+F93 -> -50646.215 | G19: =G27+G93 -> -50891.945 | H19: =H27+H93 -> -51239.932 | I19: =I27+I93 -> -51674.794 | J19: =J27+J93 -> -52226.572 | K19: =K27+K93 -> -52882.872 | ... AM19: =AM27+AM93 -> -115611.34 | AO19: =SUM(D19:O19) -> -630972.97 | AP19: =SUM(P19:AA19) -> -796275.44 | AQ19: =SUM(AB19:AM19) -> -1153524.9
A20: трансфертный доход | B20: тыс сом | D20: =D28+D94 -> 58141.36 | E20: =E28+E94 -> 58059.124 | F20: =F28+F94 -> 58256.004 | G20: =G28+G94 -> 58565.718 | H20: =H28+H94 -> 58993.718 | I20: =I28+I94 -> 59524.481 | J20: =J28+J94 -> 60185.464 | K20: =K28+K94 -> 60964.999 | ... AM20: =AM28+AM94 -> 134824.74 | AO20: =SUM(D20:O20) -> 726864.26 | AP20: =SUM(P20:AA20) -> 921530.97 | AQ20: =SUM(AB20:AM20) -> 1341523.7
A21: операционные доходы | B21: тыс сом | D21: =D29+D95 -> 7496.7671 | E21: =E29+E95 -> 7558.6425 | F21: =F29+F95 -> 7609.7893 | G21: =G29+G95 -> 7673.7731 | H21: =H29+H95 -> 7753.7854 | I21: =I29+I95 -> 7849.6876 | J21: =J29+J95 -> 7958.8921 | K21: =K29+K95 -> 8082.127 | ... AM21: =AM29+AM95 -> 19213.399 | AO21: =SUM(D21:O21) -> 95891.293 | AP21: =SUM(P21:AA21) -> 125255.52 | AQ21: =SUM(AB21:AM21) -> 187998.83
A22: начисление расходов в ФЗД | B22: тыс сом | D22: =-0.2%*(C18+D18)/2/12 -> -789.62775 | E22: =-0.2%*(D18+E18)/2/12 -> -785.07929 | F22: =-0.2%*(E18+F18)/2/12 -> -786.83253 | G22: =-0.2%*(F18+G18)/2/12 -> -790.16507 | H22: =-0.2%*(G18+H18)/2/12 -> -795.16075 | I22: =-0.2%*(H18+I18)/2/12 -> -801.67335 | J22: =-0.2%*(I18+J18)/2/12 -> -809.77779 | K22: =-0.2%*(J18+K18)/2/12 -> -819.65127 | ... AM22: =-0.2%*(AL18+AM18)/2/12 -> -1807.7453 | AO22: =SUM(D22:O22) -> -9790.073 | AP22: =SUM(P22:AA22) -> -12340.031 | AQ22: =SUM(AB22:AM22) -> -17968.873
A23: операционные расходы | B23: тыс сом | D23: =D22+D30+D96 -> -1135.88 | E23: =E22+E30+E96 -> -1137.7614 | F23: =F22+F30+F96 -> -1146.1962 | G23: =G22+G30+G96 -> -1156.3678 | H23: =H22+H30+H96 -> -1168.6156 | I23: =I22+I30+I96 -> -1182.5344 | J23: =J22+J30+J96 -> -1198.4538 | K23: =K22+K30+K96 -> -1216.4981 | ... AM23: =AM22+AM30+AM96 -> -2510.9399 | AO23: =SUM(D23:O23) -> -14435.887 | AP23: =SUM(P23:AA23) -> -18282.238 | AQ23: =SUM(AB23:AM23) -> -25519.796
A24: прибыль | B24: тыс сом | D24: =D21+D23 -> 6360.8871 | E24: =E21+E23 -> 6420.8811 | F24: =F21+F23 -> 6463.5931 | G24: =G21+G23 -> 6517.4053 | H24: =H21+H23 -> 6585.1698 | I24: =I21+I23 -> 6667.1532 | J24: =J21+J23 -> 6760.4384 | K24: =K21+K23 -> 6865.629 | ... AM24: =AM21+AM23 -> 16702.459 | AO24: =SUM(D24:O24) -> 81455.406 | AP24: =SUM(P24:AA24) -> 106973.29 | AQ24: =SUM(AB24:AM24) -> 162479.03
A25: Безбумажный офис
A26: портфель | B26: тыс сом | C26: =C40+C55*'0'!C$16+C70*'0'!C$19+C85*'0'!C$17 -> 4766780.9 | D26: =D40+D55*'0'!D$16+D70*'0'!D$19+D85*'0'!D$17 -> 4706310.3 | E26: =E40+E55*'0'!E$16+E70*'0'!E$19+E85*'0'!E$17 -> 4711666.5 | F26: =F40+F55*'0'!F$16+F70*'0'!F$19+F85*'0'!F$17 -> 4726522.3 | G26: =G40+G55*'0'!G$16+G70*'0'!G$19+G85*'0'!G$17 -> 4750475.2 | H26: =H40+H55*'0'!H$16+H70*'0'!H$19+H85*'0'!H$17 -> 4784861.5 | I26: =I40+I55*'0'!I$16+I70*'0'!I$19+I85*'0'!I$17 -> 4826406.7 | J26: =J40+J55*'0'!J$16+J70*'0'!J$19+J85*'0'!J$17 -> 4879030.4 | ... AM26: =AM40+AM55*'0'!AM$16+AM70*'0'!AM$19+AM85*'0'!AM$17 -> 11011974 | AO26: =O26 -> 5281028.4 | AP26: =AA26 -> 7250520.6 | AQ26: =AM26 -> 11011974
A27: % расход | B27: тыс сом | D27: =D43+D58*'0'!D$16+D73*'0'!D$19+D88*'0'!D$17 -> -50631.873 | E27: =E43+E58*'0'!E$16+E73*'0'!E$19+E88*'0'!E$17 -> -50484.862 | F27: =F43+F58*'0'!F$16+F73*'0'!F$19+F88*'0'!F$17 -> -50626.203 | G27: =G43+G58*'0'!G$16+G73*'0'!G$19+G88*'0'!G$17 -> -50865.653 | H27: =H43+H58*'0'!H$16+H73*'0'!H$19+H88*'0'!H$17 -> -51205.08 | I27: =I43+I58*'0'!I$16+I73*'0'!I$19+I88*'0'!I$17 -> -51628.145 | J27: =J43+J58*'0'!J$16+J73*'0'!J$19+J88*'0'!J$17 -> -52163.494 | K27: =K43+K58*'0'!K$16+K73*'0'!K$19+K88*'0'!K$17 -> -52796.941 | ... AM27: =AM43+AM58*'0'!AM$16+AM73*'0'!AM$19+AM88*'0'!AM$17 -> -115234.24 | AO27: =SUM(D27:O27) -> -629865.33 | AP27: =SUM(P27:AA27) -> -792532.93 | AQ27: =SUM(AB27:AM27) -> -1149531.9
A28: трансфертный доход | B28: тыс сом | D28: =D44+D59*'0'!D$16+D74*'0'!D$19+D89*'0'!D$17 -> 58126.526 | E28: =E44+E59*'0'!E$16+E74*'0'!E$19+E89*'0'!E$17 -> 58040.927 | F28: =F44+F59*'0'!F$16+F74*'0'!F$19+F89*'0'!F$17 -> 58232.708 | G28: =G44+G59*'0'!G$16+G74*'0'!G$19+G89*'0'!G$17 -> 58535.133 | H28: =H44+H59*'0'!H$16+H74*'0'!H$19+H89*'0'!H$17 -> 58953.201 | I28: =I44+I59*'0'!I$16+I74*'0'!I$19+I89*'0'!I$17 -> 59470.277 | J28: =J44+J59*'0'!J$16+J74*'0'!J$19+J89*'0'!J$17 -> 60112.2 | K28: =K44+K59*'0'!K$16+K74*'0'!K$19+K89*'0'!K$17 -> 60865.243 | ... AM28: =AM44+AM59*'0'!AM$16+AM74*'0'!AM$19+AM89*'0'!AM$17 -> 134389.08 | AO28: =SUM(D28:O28) -> 725579.14 | AP28: =SUM(P28:AA28) -> 917198 | AQ28: =SUM(AB28:AM28) -> 1336908.3
A29: операционные доходы | B29: тыс сом | D29: =D45+D60*'0'!D$16+D75*'0'!D$19+D90*'0'!D$17 -> 7494.6527 | E29: =E45+E60*'0'!E$16+E75*'0'!E$19+E90*'0'!E$17 -> 7556.065 | F29: =F45+F60*'0'!F$16+F75*'0'!F$19+F90*'0'!F$17 -> 7606.5054 | G29: =G45+G60*'0'!G$16+G75*'0'!G$19+G90*'0'!G$17 -> 7669.4799 | H29: =H45+H60*'0'!H$16+H75*'0'!H$19+H90*'0'!H$17 -> 7748.1207 | I29: =I45+I60*'0'!I$16+I75*'0'!I$19+I90*'0'!I$17 -> 7842.132 | J29: =J45+J60*'0'!J$16+J75*'0'!J$19+J90*'0'!J$17 -> 7948.7066 | K29: =K45+K60*'0'!K$16+K75*'0'!K$19+K90*'0'!K$17 -> 8068.3021 | ... AM29: =AM45+AM60*'0'!AM$16+AM75*'0'!AM$19+AM90*'0'!AM$17 -> 19154.834 | AO29: =SUM(D29:O29) -> 95713.806 | AP29: =SUM(P29:AA29) -> 124665.07 | AQ29: =SUM(AB29:AM29) -> 187376.43
A30: операционные расходы | B30: тыс сом | D30: =-'OPEX+CAPEX'!I190 -> -346.25223 | E30: =-'OPEX+CAPEX'!J190 -> -352.68214 | F30: =-'OPEX+CAPEX'!K190 -> -359.36367 | G30: =-'OPEX+CAPEX'!L190 -> -366.20273 | H30: =-'OPEX+CAPEX'!M190 -> -373.45483 | I30: =-'OPEX+CAPEX'!N190 -> -380.86103 | J30: =-'OPEX+CAPEX'!O190 -> -388.67599 | K30: =-'OPEX+CAPEX'!P190 -> -396.84681 | ... AM30: =-'OPEX+CAPEX'!AR190 -> -703.1946 | AO30: =SUM(D30:O30) -> -4645.8139 | AP30: =SUM(P30:AA30) -> -5942.2066 | AQ30: =SUM(AB30:AM30) -> -7550.9225
A31: KGS
A32: количество депозитов на конец периода | B32: шт | C32: 9000 | D32: =C32+D34 -> 9360 | E32: =D32+E34 -> 9734 | F32: =E32+F34 -> 10123 | G32: =F32+G34 -> 10527 | H32: =G32+H34 -> 10948 | I32: =H32+I34 -> 11385 | J32: =I32+J34 -> 11840 | K32: =J32+K34 -> 12313 | ... AM32: =AL32+AM34 -> 36899 | AO32: =AVERAGE(D32:O32) -> 11716.917 | AP32: =AVERAGE(P32:AA32) -> 18751.917 | AQ32: =AVERAGE(AB32:AM32) -> 30014.667
A33: индекс прироста депозитов | B33: % | D33: 0.04 | E33: 0.04 | F33: 0.04 | G33: 0.04 | H33: 0.04 | I33: 0.04 | J33: 0.04 | K33: 0.04 | L33: 0.04 | M33: 0.04 | N33: 0.04 | O33: 0.04 | P33: 0.04 | Q33: 0.04 | R33: 0.04 | S33: 0.04 | T33: 0.04 | U33: 0.04 | V33: 0.04 | W33: 0.04 | X33: 0.04 | Y33: 0.04 | Z33: 0.04 | AA33: 0.04 | AB33: 0.04 | AC33: 0.04 | AD33: 0.04 | AE33: 0.04 | AF33: 0.04 | AG33: 0.04 | AH33: 0.04 | AI33: 0.04 | AJ33: 0.04 | AK33: 0.04 | AL33: 0.04 | AM33: 0.04 | AO33: =O33 -> 0.04 | AP33: =AA33 -> 0.04 | AQ33: =AM33 -> 0.04
A34: количество новых депозитов | B34: шт | D34: =INT(C32*D33) -> 360 | E34: =INT(D32*E33) -> 374 | F34: =INT(E32*F33) -> 389 | G34: =INT(F32*G33) -> 404 | H34: =INT(G32*H33) -> 421 | I34: =INT(H32*I33) -> 437 | J34: =INT(I32*J33) -> 455 | K34: =INT(J32*K33) -> 473 | ... AM34: =INT(AL32*AM33) -> 1419 | AO34: =SUM(D34:O34) -> 5402 | AP34: =SUM(P34:AA34) -> 8649 | AQ34: =SUM(AB34:AM34) -> 13848
A35: ср. сумма нового депозита | B35: тыс сом | D35: 600 | E35: 600 | F35: 600 | G35: 600 | H35: 600 | I35: 600 | J35: 600 | K35: 600 | L35: 600 | M35: 600 | N35: 600 | O35: 600 | P35: 600 | Q35: 600 | R35: 600 | S35: 600 | T35: 600 | U35: 600 | V35: 600 | W35: 600 | X35: 600 | Y35: 600 | Z35: 600 | AA35: 600 | AB35: 600 | AC35: 600 | AD35: 600 | AE35: 600 | AF35: 600 | AG35: 600 | AH35: 600 | AI35: 600 | AJ35: 600 | AK35: 600 | AL35: 600 | AM35: 600 | AO35: =AVERAGE(D35:O35) -> 600 | AP35: =AVERAGE(P35:AA35) -> 600 | AQ35: =AVERAGE(AB35:AM35) -> 600
A36: привлечение депозитов | B36: тыс сом | D36: =D34*D35 -> 216000 | E36: =E34*E35 -> 224400 | F36: =F34*F35 -> 233400 | G36: =G34*G35 -> 242400 | H36: =H34*H35 -> 252600 | I36: =I34*I35 -> 262200 | J36: =J34*J35 -> 273000 | K36: =K34*K35 -> 283800 | ... AM36: =AM34*AM35 -> 851400 | AO36: =SUM(D36:O36) -> 3241200 | AP36: =SUM(P36:AA36) -> 5189400 | AQ36: =SUM(AB36:AM36) -> 8308800
A37: капитализация % | B37: тыс сом | E37: =-D43/2 -> 24139.375 | F37: =-E43/2 -> 24190.534 | G37: =-F43/2 -> 24351.776 | H37: =-G43/2 -> 24554.281 | I37: =-H43/2 -> 24799.645 | J37: =-I43/2 -> 25087.58 | K37: =-J43/2 -> 25417.812 | L37: =-K43/2 -> 25791.707 | ... AM37: =-AL43/2 -> 55528.386 | AO37: =SUM(D37:O37) -> 278389.48 | AP37: =SUM(P37:AA37) -> 382895.24 | AQ37: =SUM(AB37:AM37) -> 554416.99
A38: cр. срок портфеля | B38: мес | D38: 20 | E38: 20 | F38: 20 | G38: 20 | H38: 20 | I38: 20 | J38: 20 | K38: 20 | L38: 20 | M38: 20 | N38: 20 | O38: 20 | P38: 20 | Q38: 20 | R38: 20 | S38: 20 | T38: 20 | U38: 20 | V38: 20 | W38: 20 | X38: 20 | Y38: 20 | Z38: 20 | AA38: 20 | AB38: 20 | AC38: 20 | AD38: 20 | AE38: 20 | AF38: 20 | AG38: 20 | AH38: 20 | AI38: 20 | AJ38: 20 | AK38: 20 | AL38: 20 | AM38: 20 | AO38: =AVERAGE(D38:O38) -> 20 | AP38: =AVERAGE(P38:AA38) -> 20 | AQ38: =AVERAGE(AB38:AM38) -> 20
A39: возвраты | B39: тыс сом | D39: =C40/D38 -> 223000 | E39: =D40/E38 -> 222650 | F39: =E40/F38 -> 223944.47 | G39: =F40/G38 -> 225626.77 | H39: =G40/H38 -> 227683.02 | I39: =H40/I38 -> 230156.59 | J39: =I40/J38 -> 232998.74 | K39: =J40/K38 -> 236253.18 | ... AM39: =AL40/AM38 -> 521785.2 | AO39: =SUM(D39:O39) -> 2807899.4 | AP39: =SUM(P39:AA39) -> 3581295.2 | AQ39: =SUM(AB39:AM39) -> 5205060
A40: портфель | B40: тыс сом | C40: 4460000 | D40: =C40+D36-D39+D37 -> 4453000 | E40: =D40+E36-E39+E37 -> 4478889.4 | F40: =E40+F36-F39+F37 -> 4512535.4 | G40: =F40+G36-G39+G37 -> 4553660.4 | H40: =G40+H36-H39+H37 -> 4603131.7 | I40: =H40+I36-I39+I37 -> 4659974.8 | J40: =I40+J36-J39+J37 -> 4725063.6 | K40: =J40+K36-K39+K37 -> 4798028.2 | ... AM40: =AL40+AM36-AM39+AM37 -> 10820847 | AO40: =O40 -> 5171690.1 | AP40: =AA40 -> 7162690.1 | AQ40: =AM40 -> 10820847
A41: ср. % ставка портфеля | B41: % | D41: 0.13 | E41: 0.13 | F41: 0.13 | G41: 0.13 | H41: 0.13 | I41: 0.13 | J41: 0.13 | K41: 0.13 | L41: 0.13 | M41: 0.13 | N41: 0.13 | O41: 0.13 | P41: 0.13 | Q41: 0.13 | R41: 0.13 | S41: 0.13 | T41: 0.13 | U41: 0.13 | V41: 0.13 | W41: 0.13 | X41: 0.13 | Y41: 0.13 | Z41: 0.13 | AA41: 0.13 | AB41: 0.13 | AC41: 0.13 | AD41: 0.13 | AE41: 0.13 | AF41: 0.13 | AG41: 0.13 | AH41: 0.13 | AI41: 0.13 | AJ41: 0.13 | AK41: 0.13 | AL41: 0.13 | AM41: 0.13 | AO41: =AVERAGE(D41:O41) -> 0.13 | AP41: =AVERAGE(P41:AA41) -> 0.13 | AQ41: =AVERAGE(AB41:AM41) -> 0.13
A42: ср. % ставка фондирования | B42: % | D42: 0.15 | E42: 0.15 | F42: 0.15 | G42: 0.15 | H42: 0.15 | I42: 0.15 | J42: 0.15 | K42: 0.15 | L42: 0.15 | M42: 0.15 | N42: 0.15 | O42: 0.15 | P42: 0.15 | Q42: 0.15 | R42: 0.15 | S42: 0.15 | T42: 0.15 | U42: 0.15 | V42: 0.15 | W42: 0.15 | X42: 0.15 | Y42: 0.15 | Z42: 0.15 | AA42: 0.15 | AB42: 0.15 | AC42: 0.15 | AD42: 0.15 | AE42: 0.15 | AF42: 0.15 | AG42: 0.15 | AH42: 0.15 | AI42: 0.15 | AJ42: 0.15 | AK42: 0.15 | AL42: 0.15 | AM42: 0.15 | AO42: =AVERAGE(D42:O42) -> 0.15 | AP42: =AVERAGE(P42:AA42) -> 0.15 | AQ42: =AVERAGE(AB42:AM42) -> 0.15
...

Sheet РБ.3
A1: Розничный бизнес - обслуживание клиентов
D3: 46023 | E3: 46054 | F3: 46082 | G3: 46113 | H3: 46143 | I3: 46174 | J3: 46204 | K3: 46235 | L3: 46266 | M3: 46296 | N3: 46327 | O3: 46357 | P3: 46388 | Q3: 46419 | R3: 46447 | S3: 46478 | T3: 46508 | U3: 46539 | V3: 46569 | W3: 46600 | X3: 46631 | Y3: 46661 | Z3: 46692 | AA3: 46722 | AB3: 46753 | AC3: 46784 | AD3: 46813 | AE3: 46844 | AF3: 46874 | AG3: 46905 | AH3: 46935 | AI3: 46966 | AJ3: 46997 | AK3: 47027 | AL3: 47058 | AM3: 47088 | AO3: =YEAR(O3) -> 2026 | AP3: =YEAR(AA3) -> 2027 | AQ3: =YEAR(AM3) -> 2028
D4: m1 | E4: m2 | F4: m3 | G4: m4 | H4: m5 | I4: m6 | J4: m7 | K4: m8 | L4: m9 | M4: m10 | N4: m11 | O4: m12 | P4: m13 | Q4: m14 | R4: m15 | S4: m16 | T4: m17 | U4: m18 | V4: m19 | W4: m20 | X4: m21 | Y4: m22 | Z4: m23 | AA4: m24 | AB4: m25 | AC4: m26 | AD4: m27 | AE4: m28 | AF4: m29 | AG4: m30 | AH4: m31 | AI4: m32 | AJ4: m33 | AK4: m34 | AL4: m35 | AM4: m36 | AO4: Y1 | AP4: Y2 | AQ4: Y3
D5: 1 | E5: =D5+1 -> 2 | F5: =E5+1 -> 3 | G5: =F5+1 -> 4 | H5: =G5+1 -> 5 | I5: =H5+1 -> 6 | J5: =I5+1 -> 7 | K5: =J5+1 -> 8 | L5: =K5+1 -> 9 | ... AM5: =AL5+1 -> 36
A7: Выпуск и обслуживание банковских карт (ФЛ)
A8: количество новых карт, в т.ч. заказанных через: | B8: шт | D8: =SUM(D9:D10) -> 641 | E8: =SUM(E9:E10) -> 656 | F8: =SUM(F9:F10) -> 672 | G8: =SUM(G9:G10) -> 689 | H8: =SUM(H9:H10) -> 705 | I8: =SUM(I9:I10) -> 722 | J8: =SUM(J9:J10) -> 739 | K8: =SUM(K9:K10) -> 757 | ... AM8: =SUM(AM9:AM10) -> 1470 | AO8: =SUM(D8:O8) -> 8795 | AP8: =SUM(P8:AA8) -> 11687 | AQ8: =SUM(AB8:AM8) -> 15533
A9: Безбумажный офис | B9: шт | D9: =РБ.2!D398 -> 641 | E9: =РБ.2!E398 -> 656 | F9: =РБ.2!F398 -> 672 | G9: =РБ.2!G398 -> 689 | H9: =РБ.2!H398 -> 705 | I9: =РБ.2!I398 -> 722 | J9: =РБ.2!J398 -> 739 | K9: =РБ.2!K398 -> 757 | ... AM9: =РБ.2!AM398 -> 1470 | AO9: =SUM(D9:O9) -> 8795 | AP9: =SUM(P9:AA9) -> 11687 | AQ9: =SUM(AB9:AM9) -> 15533
A10: DCB 360 | B10: шт | D10: =РБ.2!D445 -> 0 | E10: =РБ.2!E445 -> 0 | F10: =РБ.2!F445 -> 0 | G10: =РБ.2!G445 -> 0 | H10: =РБ.2!H445 -> 0 | I10: =РБ.2!I445 -> 0 | J10: =РБ.2!J445 -> 0 | K10: =РБ.2!K445 -> 0 | ... AM10: =РБ.2!AM445 -> 0 | AO10: =SUM(D10:O10) -> 0 | AP10: =SUM(P10:AA10) -> 0 | AQ10: =SUM(AB10:AM10) -> 0
A11: количество карт на конец периода, в т.ч. заказанных через: | B11: шт | C11: =SUM(C12:C13) -> 26807 | D11: =SUM(D12:D13) -> 27448 | E11: =SUM(E12:E13) -> 28104 | F11: =SUM(F12:F13) -> 28776 | G11: =SUM(G12:G13) -> 29465 | H11: =SUM(H12:H13) -> 30170 | I11: =SUM(I12:I13) -> 30892 | J11: =SUM(J12:J13) -> 31631 | ... AM11: =SUM(AM12:AM13) -> 62822 | AO11: =O11 -> 35602 | AP11: =AA11 -> 47289 | AQ11: =AM11 -> 62822
A12: Безбумажный офис | B12: шт | C12: =РБ.2!C386 -> 26807 | D12: =РБ.2!D386 -> 27448 | E12: =РБ.2!E386 -> 28104 | F12: =РБ.2!F386 -> 28776 | G12: =РБ.2!G386 -> 29465 | H12: =РБ.2!H386 -> 30170 | I12: =РБ.2!I386 -> 30892 | J12: =РБ.2!J386 -> 31631 | ... AM12: =РБ.2!AM386 -> 62822 | AO12: =O12 -> 35602 | AP12: =AA12 -> 47289 | AQ12: =AM12 -> 62822
A13: DCB 360 | B13: шт | C13: =РБ.2!C433 -> 0 | D13: =РБ.2!D433 -> 0 | E13: =РБ.2!E433 -> 0 | F13: =РБ.2!F433 -> 0 | G13: =РБ.2!G433 -> 0 | H13: =РБ.2!H433 -> 0 | I13: =РБ.2!I433 -> 0 | J13: =РБ.2!J433 -> 0 | ... AM13: =РБ.2!AM433 -> 0 | AO13: =O13 -> 0 | AP13: =AA13 -> 0 | AQ13: =AM13 -> 0
A14: доля перевыпускаемых карт | B14: % | D14: 0.0147 | E14: 0.0147 | F14: 0.0147 | G14: 0.0147 | H14: 0.0147 | I14: 0.0147 | J14: 0.0147 | K14: 0.0147 | L14: 0.0147 | M14: 0.0147 | N14: 0.0147 | O14: 0.0147 | P14: 0.0147 | Q14: 0.0147 | R14: 0.0147 | S14: 0.0147 | T14: 0.0147 | U14: 0.0147 | V14: 0.0147 | W14: 0.0147 | X14: 0.0147 | Y14: 0.0147 | Z14: 0.0147 | AA14: 0.0147 | AB14: 0.0147 | AC14: 0.0147 | AD14: 0.0147 | AE14: 0.0147 | AF14: 0.0147 | AG14: 0.0147 | AH14: 0.0147 | AI14: 0.0147 | AJ14: 0.0147 | AK14: 0.0147 | AL14: 0.0147 | AM14: 0.0147
A15: количество перевыпускаемых карт | B15: шт | D15: =C11*D14 -> 394.0629 | E15: =D11*E14 -> 403.4856 | F15: =E11*F14 -> 413.1288 | G15: =F11*G14 -> 423.0072 | H15: =G11*H14 -> 433.1355 | I15: =H11*I14 -> 443.499 | J15: =I11*J14 -> 454.1124 | K15: =J11*K14 -> 464.9757 | ... AM15: =AL11*AM14 -> 901.8744 | AO15: =SUM(D15:O15) -> 5403.279 | AP15: =SUM(P15:AA15) -> 7176.4077 | AQ15: =SUM(AB15:AM15) -> 9533.244
A16: доля карт для оплаты годового обслуживания | B16: % | D16: =1/12 -> 0.083333333 | E16: =1/12 -> 0.083333333 | F16: =1/12 -> 0.083333333 | G16: =1/12 -> 0.083333333 | H16: =1/12 -> 0.083333333 | I16: =1/12 -> 0.083333333 | J16: =1/12 -> 0.083333333 | K16: =1/12 -> 0.083333333 | ... AM16: =1/12 -> 0.083333333
A17: ср.комиссия за выпуск (перевыпуск) 1 карты | B17: сом | D17: 200 | E17: 100 | F17: 100 | G17: 100 | H17: 100 | I17: 100 | J17: 100 | K17: 100 | L17: 100 | M17: 100 | N17: 100 | O17: 100 | P17: 100 | Q17: 100 | R17: 100 | S17: 100 | T17: 100 | U17: 100 | V17: 100 | W17: 100 | X17: 100 | Y17: 100 | Z17: 100 | AA17: 100 | AB17: 100 | AC17: 100 | AD17: 100 | AE17: 100 | AF17: 100 | AG17: 100 | AH17: 100 | AI17: 100 | AJ17: 100 | AK17: 100 | AL17: 100 | AM17: 100
A18: ср.комиссия за годовое обслуживание 1 карты | B18: сом | D18: 200 | E18: 450 | F18: 450 | G18: 450 | H18: 450 | I18: 450 | J18: 450 | K18: 450 | L18: 450 | M18: 450 | N18: 450 | O18: 450 | P18: 450 | Q18: 450 | R18: 450 | S18: 450 | T18: 450 | U18: 450 | V18: 450 | W18: 450 | X18: 450 | Y18: 450 | Z18: 450 | AA18: 450 | AB18: 450 | AC18: 450 | AD18: 450 | AE18: 450 | AF18: 450 | AG18: 450 | AH18: 450 | AI18: 450 | AJ18: 450 | AK18: 450 | AL18: 450 | AM18: 450
A19: комиссионный доход | B19: тыс.сом | D19: =D20+D21 -> 664.47925 | E19: =E20+E21 -> 1159.8486 | F19: =F20+F21 -> 1187.6129 | G19: =G20+G21 -> 1216.1382 | H19: =H20+H21 -> 1245.1886 | I19: =I20+I21 -> 1274.9999 | J19: =J20+J21 -> 1305.4737 | K19: =K20+K21 -> 1336.7476 | ... AM19: =AM20+AM21 -> 2593.0124 | AO19: =SUM(D19:O19) -> 15065.188 | AP19: =SUM(P19:AA19) -> 20631.766 | AQ19: =SUM(AB19:AM19) -> 27408.612
A20: комиссионный доход за выпуск (перевыпуск) | B20: тыс.сом | D20: =(D8+C11*D14)*D17/1000 -> 207.01258 | E20: =(E8+D11*E14)*E17/1000 -> 105.94856 | F20: =(F8+E11*F14)*F17/1000 -> 108.51288 | G20: =(G8+F11*G14)*G17/1000 -> 111.20072 | H20: =(H8+G11*H14)*H17/1000 -> 113.81355 | I20: =(I8+H11*I14)*I17/1000 -> 116.5499 | J20: =(J8+I11*J14)*J17/1000 -> 119.31124 | K20: =(K8+J11*K14)*K17/1000 -> 122.19757 | ... AM20: =(AM8+AL11*AM14)*AM17/1000 -> 237.18744 | AO20: =SUM(D20:O20) -> 1523.3342 | AP20: =SUM(P20:AA20) -> 1886.3408 | AQ20: =SUM(AB20:AM20) -> 2506.6244
A21: комиссионный доход за годовое обслуживание | B21: тыс.сом | D21: =D11*D16*D18/1000 -> 457.46667 | E21: =E11*E16*E18/1000 -> 1053.9 | F21: =F11*F16*F18/1000 -> 1079.1 | G21: =G11*G16*G18/1000 -> 1104.9375 | H21: =H11*H16*H18/1000 -> 1131.375 | I21: =I11*I16*I18/1000 -> 1158.45 | J21: =J11*J16*J18/1000 -> 1186.1625 | K21: =K11*K16*K18/1000 -> 1214.55 | ... AM21: =AM11*AM16*AM18/1000 -> 2355.825 | AO21: =SUM(D21:O21) -> 13541.854 | AP21: =SUM(P21:AA21) -> 18745.425 | AQ21: =SUM(AB21:AM21) -> 24901.987
A22: операционные расходы, в т.ч.: | B22: тыс.сом | D22: =-'OPEX+CAPEX'!I284 -> -297.80072 | E22: =-'OPEX+CAPEX'!J284 -> -303.57828 | F22: =-'OPEX+CAPEX'!K284 -> -309.58677 | G22: =-'OPEX+CAPEX'!L284 -> -315.83177 | H22: =-'OPEX+CAPEX'!M284 -> -322.02378 | I22: =-'OPEX+CAPEX'!N284 -> -328.4523 | J22: =-'OPEX+CAPEX'!O284 -> -334.97535 | K22: =-'OPEX+CAPEX'!P284 -> -341.74047 | ... AM22: =-'OPEX+CAPEX'!AR284 -> -612.20786 | AO22: =SUM(D22:O22) -> -3991.5063 | AP22: =SUM(P22:AA22) -> -5088.9366 | AQ22: =SUM(AB22:AM22) -> -6547.9266
A23: прибыль | B23: тыс.сом | D23: =D20+D21+D22 -> 366.67852 | E23: =E20+E21+E22 -> 856.27028 | F23: =F20+F21+F22 -> 878.02611 | G23: =G20+G21+G22 -> 900.30645 | H23: =H20+H21+H22 -> 923.16477 | I23: =I20+I21+I22 -> 946.5476 | J23: =J20+J21+J22 -> 970.49839 | K23: =K20+K21+K22 -> 995.0071 | ... AM23: =AM20+AM21+AM22 -> 1980.8046 | AO23: =SUM(D23:O23) -> 11073.682 | AP23: =SUM(P23:AA23) -> 15542.829 | AQ23: =SUM(AB23:AM23) -> 20860.685
A25: Открытие и обслуживание банковского счета (ФЛ)
A26: количество новых счетов, в т.ч. открытых через: | B26: шт | D26: =SUM(D27:D28) -> 344.8 | E26: =SUM(E27:E28) -> 744 | F26: =SUM(F27:F28) -> 948 | G26: =SUM(G27:G28) -> 974 | H26: =SUM(H27:H28) -> 1006 | I26: =SUM(I27:I28) -> 1042 | J26: =SUM(J27:J28) -> 1084 | K26: =SUM(K27:K28) -> 793.8 | ... AM26: =SUM(AM27:AM28) -> 5932 | AO26: =SUM(D26:O26) -> 11689 | AP26: =SUM(P26:AA26) -> 18893.6 | AQ26: =SUM(AB26:AM26) -> 48027.6
A27: Безбумажный офис | B27: шт | D27: =РБ.2!D262+РБ.2!D273+РБ.2!D284+РБ.2!D295+РБ.2!D306 -> 344.8 | E27: =РБ.2!E262+РБ.2!E273+РБ.2!E284+РБ.2!E295+РБ.2!E306 -> 692 | F27: =РБ.2!F262+РБ.2!F273+РБ.2!F284+РБ.2!F295+РБ.2!F306 -> 872 | G27: =РБ.2!G262+РБ.2!G273+РБ.2!G284+РБ.2!G295+РБ.2!G306 -> 881 | H27: =РБ.2!H262+РБ.2!H273+РБ.2!H284+РБ.2!H295+РБ.2!H306 -> 892 | I27: =РБ.2!I262+РБ.2!I273+РБ.2!I284+РБ.2!I295+РБ.2!I306 -> 901 | J27: =РБ.2!J262+РБ.2!J273+РБ.2!J284+РБ.2!J295+РБ.2!J306 -> 911 | K27: =РБ.2!K262+РБ.2!K273+РБ.2!K284+РБ.2!K295+РБ.2!K306 -> 644.7 | ... AM27: =РБ.2!AM262+РБ.2!AM273+РБ.2!AM284+РБ.2!AM295+РБ.2!AM306 -> 966.4 | AO27: =SUM(D27:O27) -> 9624.1 | AP27: =SUM(P27:AA27) -> 10802.6 | AQ27: =SUM(AB27:AM27) -> 12131
